Workbook
Name ColorTexto: _xludf.GET.CELL (BONO EXTRA !$Q$1)

Sheet A PAGAR FINAL
A1: N° | B1: RUT | C1: FECHA INGRESO MV | D1: FECHA TÉRMINO | E1: VIGENCIA | F1: TURNO | G1: NOMBRE | H1: CARGO | I1: HOJA DE DATOS | J1: OBSERVACION | K1: BONO PRODUCCIÓN JULIO A CARGAR EN AGOSTO 2026 | L1: BONO EXTRA JULIO A CARGAR EN AGOSTO 2026 | M1: BONO SOBRE 1000 M A CARGAR EN AGOSTO 2026 | O1: TOTAL A PAGAR VALIDACIONES | P1: HOJA
A2: 1 | B2: 12419789-9 | C2: 45964 | F2: 4X3 | G2: NUÑEZ GONZALEZ ROBERTO CARLOS | H2: ADMINISTRADOR DE CONTRATO | I2: SUP-PREV | K2: =VLOOKUP(B2,'SUP- PREV'!$B$16:$Q$39,16,FALSE) -> 355419 | O2: =K110+L110+M110 -> 18856252 | P2: A PAGAR FINAL
A3: 2 | B3: 15050618-2 | C3: 45967 | F3: 4X3 | G3: VIGORENA DUARTE KAREN ANDREA | H3: ADMINISTRATIVA/O DE FAENA | I3: NO OP | K3: =VLOOKUP(B3,'NO OP'!$B$16:$Q$68,16,FALSE) -> 268622 | O3: =O4-O2 -> 0 | P3: DIFERENCIA
A4: 3 | B4: 122192016 | C4: 46139 | F4: 4X3 | G4: ALFARO VEAS RODRIGO FERNANDO | H4: LIDER HSEC | I4: SUP-PREV | K4: =VLOOKUP(B4,'SUP- PREV'!$B$16:$Q$39,16,FALSE) -> 355419 | O4: =SUM(O5:O8)+O10+O11+O13 -> 18856252 | P4: VERIFICACIÓN HOJAS | Q4: VERIFICACION | R4: VERD O FALSO | S4: DIFERENCIA
A5: 4 | B5: 21336141-4 | C5: 46087 | F5: A | G5: ASTORGA PINTO BARBARA ANAIS | H5: ADMINISTRATIVA/O DE FAENA | I5: NO OP | J5: NO OP | K5: =VLOOKUP(B5,'NO OP'!$B$16:$Q$68,16,FALSE) -> 141380 | O5: ='NO OP'!Q69 -> 6234858 | P5: NO OP | Q5: =SUMIF(I2:I109,"NO OP",$K$2:$K$109) -> 6234858 | R5: =O5=Q5 -> TRUE | S5: =Q5-O5 -> 0
A6: 5 | B6: 17118820-2 | C6: 45691 | F6: A | G6: FERNANDEZ CASTILLO CLAUDIO ANDRES | H6: ADMINISTRATIVA/O DE FAENA | I6: NO OP | K6: =VLOOKUP(B6,'NO OP'!$B$16:$Q$68,16,FALSE) -> 268622 | O6: ='SUP- PREV'!Q40 -> 4704075 | P6: SUP-PREV | Q6: =SUMIF(I2:I109,"SUP-PREV",$K$2:$K$109) -> 4704075 | R6: =O6=Q6 -> TRUE | S6: =Q6-O6 -> 0
A7: 6 | B7: 21236457-6 | C7: 46063 | F7: A | G7: ANGEL MUNITA DIANA CATALINA | H7: AYUDANTE DE PERFORISTA | I7: AYUD. | K7: =VLOOKUP(B7,AYUD.!$B$4:$AB$54,27,FALSE) -> 201325 | L7: =VLOOKUP(B7,'BONO EXTRA'!$A$7:$AO$90,41,FALSE) -> 10025 | O7: =PERFOR.!AB30 -> 3158100 | P7: PERFORISTAS | Q7: =SUMIF($I$2:I108,"PERFOR.",$K$2:$K$108) -> 3158100 | R7: =O7=Q7 -> TRUE | S7: =Q7-O7 -> 0
A8: 7 | B8: 21637836-9 | C8: 45646 | F8: A | G8: AQUEA GONZALEZ MARIO ALBERTO | H8: AYUDANTE DE PERFORISTA | I8: AYUD. | K8: =VLOOKUP(B8,AYUD.!$B$4:$AB$54,27,FALSE) -> 126800 | L8: =VLOOKUP(B8,'BONO EXTRA'!$A$7:$AO$90,41,FALSE) -> 13000 | O8: =AYUD.!AB56 -> 4490725 | P8: AYUDANTES | Q8: =SUMIF($I$2:I108,"AYUD.",$K$2:$K$100) -> 4490725 | R8: =O8=Q8 -> TRUE | S8: =Q8-O8 -> 0
A9: 8 | B9: 17939732-3 | C9: 45666 | F9: A | G9: CASSRA ORELLANA DAVID JESUS | H9: AYUDANTE DE PERFORISTA | I9: AYUD. | J9: 3 al 6 vacaciones | K9: =VLOOKUP(B9,AYUD.!$B$4:$AB$54,27,FALSE) -> 168625 | L9: =VLOOKUP(B9,'BONO EXTRA'!$A$7:$AO$90,41,FALSE) -> 7000
A10: 9 | B10: 19454353-0 | C10: 45986 | F10: A | G10: CASTRO HOHMANN KASUKI | H10: AYUDANTE DE PERFORISTA | I10: AYUD. | K10: =VLOOKUP(B10,AYUD.!$B$4:$AB$54,27,FALSE) -> 149150 | L10: =VLOOKUP(B10,'BONO EXTRA'!$A$7:$AO$90,41,FALSE) -> 2712.5 | O10: =AYUD.!AC56 -> 166062.5 | P10: BONO EXTRA AYUD
A11: 10 | B11: 13425369-K | C11: 45951 | F11: A | G11: CONTRERAS FLORES RICHARD FERNANDO | H11: AYUDANTE DE PERFORISTA | I11: AYUD. | K11: =VLOOKUP(B11,AYUD.!$B$4:$AB$54,27,FALSE) -> 126800 | L11: =VLOOKUP(B11,'BONO EXTRA'!$A$7:$AO$90,41,FALSE) -> 13000 | O11: =PERFOR.!AC30 -> 102431.25 | P11: BONO EXTRA PERF
A12: 11 | B12: 19214178-8 | C12: 45925 | F12: A | G12: GAETE PAZ GERARDO ANTONIO | H12: AYUDANTE DE PERFORISTA | I12: AYUD. | K12: =VLOOKUP(B12,AYUD.!$B$4:$AB$54,27,FALSE) -> 250275 | L12: =VLOOKUP(B12,'BONO EXTRA'!$A$7:$AO$90,41,FALSE) -> 12025 | O12: ='BONO EXTRA'!AO86 -> 268493.75 | Q12: =PERFOR.!AC30+AYUD.!AC56 -> 268493.75 | R12: =Q12=O12 -> TRUE | S12: =O12-Q12 -> 0
A13: 12 | B13: 16892590-5 | C13: 45746 | F13: A | G13: GALLEGUILLOS DIAZ ERIC ALFONSO | H13: AYUDANTE DE PERFORISTA | I13: AYUD. | J13: 3 al 12 vacaciones | K13: =VLOOKUP(B13,AYUD.!$B$4:$AB$54,27,FALSE) -> 44000 | L13: =VLOOKUP(B13,'BONO EXTRA'!$A$7:$AO$90,41,FALSE) -> 0 | O13: =M110 -> 0 | P13: BONO SOBRE 1000 MTS
A14: 13 | B14: 17827549-6 | C14: 45726 | F14: A | G14: GONZALEZ ROMERO JUAN EDUARDO | H14: AYUDANTE DE PERFORISTA | I14: AYUD. | K14: =VLOOKUP(B14,AYUD.!$B$4:$AB$54,27,FALSE) -> 171200 | L14: =VLOOKUP(B14,'BONO EXTRA'!$A$7:$AO$90,41,FALSE) -> 7600
A15: 15 | B15: 25606451-0 | C15: 46146 | F15: A | G15: MUJICA MENDEZ ENDER ALEXANDER | H15: AYUDANTE DE PERFORISTA | I15: AYUD. | K15: =VLOOKUP(B15,AYUD.!$B$4:$AB$54,27,FALSE) -> 171200 | L15: =VLOOKUP(B15,'BONO EXTRA'!$A$7:$AO$90,41,FALSE) -> 13000
A16: 16 | B16: 20111998-7 | C16: 46130 | F16: A | G16: NOVOA TORO BORIS ALEXIS | H16: AYUDANTE DE PERFORISTA | I16: AYUD. | K16: =VLOOKUP(B16,AYUD.!$B$4:$AB$54,27,FALSE) -> 171200 | L16: =VLOOKUP(B16,'BONO EXTRA'!$A$7:$AO$90,41,FALSE) -> 7600
A17: 17 | B17: 21303273-9 | C17: 45754 | F17: A | G17: PEREZ LORCA VICTOR IGNACIO | H17: AYUDANTE DE PERFORISTA | I17: AYUD. | K17: =VLOOKUP(B17,AYUD.!$B$4:$AB$54,27,FALSE) -> 171200 | L17: =VLOOKUP(B17,'BONO EXTRA'!$A$7:$AO$90,41,FALSE) -> 7600
A18: 18 | B18: 18011716-4 | C18: 45646 | F18: A | G18: RAMIREZ RAMIREZ RICHARD FABIAN | H18: AYUDANTE DE PERFORISTA | I18: AYUD. | K18: =VLOOKUP(B18,AYUD.!$B$4:$AB$54,27,FALSE) -> 149150 | L18: =VLOOKUP(B18,'BONO EXTRA'!$A$7:$AO$90,41,FALSE) -> 2712.5
A19: 19 | B19: 14401561-4 | C19: 45666 | F19: A | G19: RODRIGUEZ OPAZO PAULO ANDRES | H19: AYUDANTE DE PERFORISTA | I19: AYUD. | K19: =VLOOKUP(B19,AYUD.!$B$4:$AB$54,27,FALSE) -> 149150 | L19: =VLOOKUP(B19,'BONO EXTRA'!$A$7:$AO$90,41,FALSE) -> 7850
A20: 20 | B20: 15521744-8 | C20: 45636 | F20: A | G20: ROJAS FERNANDEZ JILBERTO FRANCISCO | H20: AYUDANTE DE PERFORISTA | I20: AYUD. | K20: =VLOOKUP(B20,AYUD.!$B$4:$AB$54,27,FALSE) -> 236500 | L20: =VLOOKUP(B20,'BONO EXTRA'!$A$7:$AO$90,41,FALSE) -> 12025
A21: 21 | B21: 17295192-9 | C21: 45925 | F21: A | G21: SAN FRANCISCO ARDILES IVAN ALEJANDRO | H21: AYUDANTE DE PERFORISTA | I21: AYUD. | K21: =VLOOKUP(B21,AYUD.!$B$4:$AB$54,27,FALSE) -> 149150 | L21: =VLOOKUP(B21,'BONO EXTRA'!$A$7:$AO$90,41,FALSE) -> 7850
A22: 22 | B22: 19167554-1 | C22: 45627 | F22: A | G22: THOMPSON DIAZ FREDDY IGNACIO | H22: AYUDANTE DE PERFORISTA | I22: AYUD. | K22: =VLOOKUP(B22,AYUD.!$B$4:$AB$54,27,FALSE) -> 236500 | L22: =VLOOKUP(B22,'BONO EXTRA'!$A$7:$AO$90,41,FALSE) -> 12000
A23: 23 | B23: 13743972-7 | C23: 45627 | F23: A | G23: VEGA GONZALEZ PATRICIO COLLO | H23: AYUDANTE DE PERFORISTA | I23: NO OP | K23: =VLOOKUP(B23,'NO OP'!$B$16:$Q$68,16,FALSE) -> 141380
A24: 24 | B24: 17775054-9 | C24: 45966 | F24: A | G24: ZAPATA SEGUEL CARLOS ANDRES | H24: AYUDANTE DE PERFORISTA | I24: AYUD. | K24: =VLOOKUP(B24,AYUD.!$B$4:$AB$54,27,FALSE) -> 236500 | L24: =VLOOKUP(B24,'BONO EXTRA'!$A$7:$AO$90,41,FALSE) -> 12000
A25: 25 | B25: 15446035-7 | C25: 45627 | F25: A | G25: COFRE ROMERO VICTORIA DEL PILAR | H25: BODEGUERA/O | I25: NO OP | K25: =VLOOKUP(B25,'NO OP'!$B$16:$Q$68,16,FALSE) -> 183794
A26: 26 | B26: 15056140-K | C26: 45627 | F26: A | G26: ARDILES NUÑEZ JONATHAN ANDRES | H26: CHOFER | I26: NO OP | K26: =VLOOKUP(B26,'NO OP'!$B$16:$Q$68,16,FALSE) -> 268622
A27: 27 | B27: 16052742-0 | C27: 45733 | F27: A | G27: ARDILES NUÑEZ JOSE MIGUEL | H27: CHOFER | I27: NO OP | K27: =VLOOKUP(B27,'NO OP'!$B$16:$Q$68,16,FALSE) -> 268622
A28: 28 | B28: 17294428-0 | C28: 45804 | F28: A | G28: JIMENEZ VEGA LUIS RENATO DE JESUS | H28: CHOFER | I28: NO OP | K28: =VLOOKUP(B28,'NO OP'!$B$16:$Q$68,16,FALSE) -> 268622
A29: 29 | B29: 18633143-5 | C29: 46063 | F29: A | G29: MALDONADO MONDACA CRISTOFER JESUS | H29: CHOFER | I29: NO OP | K29: =VLOOKUP(B29,'NO OP'!$B$16:$Q$68,16,FALSE) -> 268622
A30: 30 | B30: 15831074-0 | C30: 46080 | F30: A | G30: NAETER QUIROZ ESTEFANIA CONSTANZA | H30: CHOFER | I30: NO OP | J30: 10-07 con traslado | K30: =VLOOKUP(B30,'NO OP'!$B$16:$Q$68,16,FALSE) -> 56552
A31: 31 | B31: 19460207-3 | C31: 45876 | F31: A | G31: POBLETE KUHNE PABLO LUCAS | H31: CHOFER | I31: NO OP | K31: =VLOOKUP(B31,'NO OP'!$B$16:$Q$68,16,FALSE) -> 141380
A32: 32 | B32: 13804452-1 | C32: 45646 | F32: A | G32: SANDOVAL SEPULVEDA GERSON ANDRES | H32: CHOFER | I32: NO OP | K32: =VLOOKUP(B32,'NO OP'!$B$16:$Q$68,16,FALSE) -> 268622
A33: 33 | B33: 15909798-6 | C33: 46148 | F33: A | G33: GALLEGUILLOS ARANCIBIA GABRIEL ALEJANDRO | H33: MECANICO | I33: NO OP | K33: =VLOOKUP(B33,'NO OP'!$B$16:$Q$68,16,FALSE) -> 268622
A34: 34 | B34: 19910908-1 | C34: 45826 | F34: A | G34: SANDERSON SALCEDO CRISTOBAL ALEXIC | H34: MECANICO | I34: NO OP | K34: =VLOOKUP(B34,'NO OP'!$B$16:$Q$68,16,FALSE) -> 268622
A35: 35 | B35: 17998731-7 | C35: 45946 | F35: A | G35: RIVERA HERRERA ANGELO PATRICIO | H35: MECANICO FLOTA | I35: NO OP | K35: =VLOOKUP(B35,'NO OP'!$B$16:$Q$68,16,FALSE) -> 268622
A36: 36 | B36: 17624527-1 | C36: 45666 | F36: A | G36: CASTRO AVALOS NELSON ANDRES | H36: PERFORISTA | I36: PERFOR. | K36: =VLOOKUP(B36,PERFOR.!$B$4:$AB$25,27,FALSE) -> 223725 | L36: =VLOOKUP(B36,'BONO EXTRA'!$A$7:$AO$84,41,FALSE) -> 11775
A37: 37 | B37: 17629034-K | C37: 45896 | F37: A | G37: CORTES GONZALEZ JUAN IGNACIO | H37: PERFORISTA | I37: PERFOR. | K37: =VLOOKUP(B37,PERFOR.!$B$4:$AB$25,27,FALSE) -> 100800 | L37: =VLOOKUP(B37,'BONO EXTRA'!$A$7:$AO$84,41,FALSE) -> 3000
A38: 38 | B38: 16280454-5 | C38: 45946 | F38: A | G38: ESCALONA VERA MANUEL ANTONIO | H38: PERFORISTA | I38: PERFOR. | K38: =VLOOKUP(B38,PERFOR.!$B$4:$AB$25,27,FALSE) -> 430912.5 | L38: =VLOOKUP(B38,'BONO EXTRA'!$A$7:$AO$84,41,FALSE) -> 10500
A39: 39 | B39: 17294242-3 | C39: 45646 | F39: A | G39: JERALDO CORTES DANIEL EDUARDO | H39: PERFORISTA | I39: PERFOR. | K39: =VLOOKUP(B39,PERFOR.!$B$4:$AB$25,27,FALSE) -> 348187.5 | L39: =VLOOKUP(B39,'BONO EXTRA'!$A$7:$AO$84,41,FALSE) -> 18037.5
A40: 40 | B40: 12115176-6 | C40: 45628 | F40: A | G40: LEIVA LEIVA FRANCISCO JAVIER | H40: PERFORISTA | I40: PERFOR. | K40: =VLOOKUP(B40,PERFOR.!$B$4:$AB$25,27,FALSE) -> 348187.5 | L40: =VLOOKUP(B40,'BONO EXTRA'!$A$7:$AO$84,41,FALSE) -> 18000
...

Sheet ASISTENCIA JULIO
B1: NOCHE | C1: NUEVOS INGRESOS | D1: HOTEL | F1: DESCANSO | G1: JULIO | AL1: JULIO | AP1: DICIEMBRE
A2: Lic | B2: DÍA | C2: PERMISO | D2: VACACIONES | F2: FALLA | G2: M | H2: M | I2: J | J2: V | K2: S | L2: D | M2: L | N2: M | O2: M | P2: J | Q2: V | R2: S | S2: D | T2: L | U2: M | V2: M | W2: J | X2: V | Y2: S | Z2: D | AA2: L | AB2: M | AC2: M | AD2: J | AE2: V | AF2: S | AG2: D | AH2: L | AI2: M | AJ2: M | AK2: J | AP2: HH
A3: NRO | B3: RUT | C3: NOMBRE | D3: TURNO | E3: GENERO | F3: CARGO | G3: 1 | H3: 2 | I3: 3 | J3: 4 | K3: 5 | L3: 6 | M3: 7 | N3: 8 | O3: 9 | P3: 10 | Q3: 11 | R3: 12 | S3: 13 | T3: 14 | U3: 15 | V3: 16 | W3: 17 | X3: 18 | Y3: 19 | Z3: 20 | AA3: 21 | AB3: 22 | AC3: 23 | AD3: 24 | AE3: 25 | AF3: 26 | AG3: 27 | AH3: 28 | AI3: 29 | AJ3: 30 | AK3: 31 | AL3: DÍA | AM3: Descanso | AN3: NOCHE | AO3: TOTAL | AP3: DIA
A4: 1 | B4: 12419789-9 | C4: NUÑEZ GONZALEZ ROBERTO CARLOS | D4: 4X3 | E4: M | F4: ADC | G4: D | H4: D | I4: DE | J4: DE | K4: DE | L4: D | M4: D | N4: D | O4: D | P4: DE | Q4: DE | R4: DE | S4: D | T4: D | U4: D | V4: DE | W4: DE | X4: DE | Y4: DE | Z4: D | AA4: D | AB4: D | AC4: D | AD4: DE | AE4: DE | AF4: DE | AG4: D | AH4: D | AI4: D | AJ4: D | AK4: DE | AL4: =COUNTIF(G4:AK4,"D") -> 17 | AM4: =COUNTIF(G4:AK4,"DE") -> 14 | AN4: =COUNTIF(G4:AK4,"N") -> 0 | AO4: =SUM(AL4:AN4) -> 31 | AP4: =COUNTIF(G4:AK4,"D")+COUNTIF(G4:AK4,"N") -> 17
A5: =A4+1 -> 2 | B5: 122192016 | C5: ALFARO VEAS RODRIGO FERNANDO | D5: 4X3 | E5: M | F5: LIDER HSEC | G5: D | H5: D | I5: DE | J5: DE | K5: DE | L5: D | M5: D | N5: D | O5: D | P5: DE | Q5: DE | R5: DE | S5: D | T5: D | U5: D | V5: DE | W5: DE | X5: DE | Y5: DE | Z5: D | AA5: D | AB5: D | AC5: D | AD5: DE | AE5: DE | AF5: DE | AG5: D | AH5: D | AI5: D | AJ5: D | AK5: DE | AL5: =COUNTIF(G5:AK5,"D") -> 17 | AM5: =COUNTIF(G5:AK5,"DE") -> 14 | AN5: =COUNTIF(G5:AK5,"N") -> 0 | AO5: =SUM(AL5:AN5) -> 31 | AP5: =COUNTIF(G5:AK5,"D")+COUNTIF(G5:AK5,"N") -> 17
A6: =A5+1 -> 3 | B6: 15050618-2 | C6: VIGORENA DUARTE KAREN ANDREA | D6: 4X3 | E6: F | F6: ADMINISTRATIVA/O DE FAENA | G6: DE | H6: DE | I6: D | J6: D | K6: D | L6: D | M6: D | N6: D | O6: D | P6: D | Q6: D | R6: D | S6: DE | T6: DE | U6: DE | V6: DE | W6: DE | X6: DE | Y6: DE | Z6: DE | AA6: DE | AB6: DE | AC6: D | AD6: D | AE6: D | AF6: D | AG6: D | AH6: D | AI6: D | AJ6: D | AK6: D | AL6: =COUNTIF(G6:AK6,"D") -> 19 | AM6: =COUNTIF(G6:AK6,"DE") -> 12 | AN6: =COUNTIF(G6:AK6,"N") -> 0 | AO6: =SUM(AL6:AN6) -> 31 | AP6: =COUNTIF(G6:AK6,"D")+COUNTIF(G6:AK6,"N") -> 19
A7: =A6+1 -> 4 | B7: 16442692-0 | C7: AGUIRRE CASTILLO ANITA FERNANDA | D7: A | E7: F | F7: PREVENCIONISTA | G7: DE | H7: DE | I7: D | J7: D | K7: D | L7: D | M7: D | N7: D | O7: D | P7: D | Q7: D | R7: D | S7: DE | T7: DE | U7: DE | V7: DE | W7: DE | X7: DE | Y7: DE | Z7: DE | AA7: DE | AB7: DE | AC7: D | AD7: D | AE7: D | AF7: D | AG7: D | AH7: D | AI7: D | AJ7: D | AK7: D | AL7: =COUNTIF(G7:AK7,"D") -> 19 | AM7: =COUNTIF(G7:AK7,"DE") -> 12 | AN7: =COUNTIF(G7:AK7,"N") -> 0 | AO7: =SUM(AL7:AN7) -> 31 | AP7: =COUNTIF(G7:AK7,"D")+COUNTIF(G7:AK7,"N") -> 19
A8: =A7+1 -> 5 | B8: 21236457-6 | C8: ANGEL MUNITA DIANA CATALINA | D8: A | E8: F | F8: AYUDANTE DE PERFORISTA | G8: DE | H8: DE | I8: N | J8: N | K8: N | L8: N | M8: N | N8: N | O8: N | P8: N | Q8: N | R8: N | S8: DE | T8: DE | U8: DE | V8: DE | W8: DE | X8: DE | Y8: DE | Z8: DE | AA8: DE | AB8: DE | AC8: D | AD8: D | AE8: D | AF8: D | AG8: D | AH8: D | AI8: D | AJ8: D | AK8: D | AL8: =COUNTIF(G8:AK8,"D") -> 9 | AM8: =COUNTIF(G8:AK8,"DE") -> 12 | AN8: =COUNTIF(G8:AK8,"N") -> 10 | AO8: =SUM(AL8:AN8) -> 31 | AP8: =COUNTIF(G8:AK8,"D")+COUNTIF(G8:AK8,"N") -> 19
A9: =A8+1 -> 6 | B9: 21637836-9 | C9: AQUEA GONZALEZ MARIO ALBERTO | D9: A | E9: M | F9: AYUDANTE DE PERFORISTA(RIGGER) | G9: DE | H9: DE | I9: N | J9: N | K9: N | L9: N | M9: N | N9: N | O9: N | P9: N | Q9: N | R9: N | S9: DE | T9: DE | U9: DE | V9: DE | W9: DE | X9: DE | Y9: DE | Z9: DE | AA9: DE | AB9: DE | AC9: L | AD9: L | AE9: L | AF9: L | AG9: L | AH9: L | AI9: L | AJ9: L | AK9: L | AL9: =COUNTIF(G9:AK9,"D") -> 0 | AM9: =COUNTIF(G9:AK9,"DE") -> 12 | AN9: =COUNTIF(G9:AK9,"N") -> 10 | AO9: =SUM(AL9:AN9) -> 22 | AP9: =COUNTIF(G9:AK9,"D")+COUNTIF(G9:AK9,"N") -> 10
A10: =A9+1 -> 7 | B10: 15056140-K | C10: ARDILES NUÑEZ JONATHAN ANDRES | D10: A | E10: M | F10: CHOFER | G10: DE | H10: DE | I10: N | J10: N | K10: N | L10: N | M10: N | N10: N | O10: N | P10: N | Q10: N | R10: N | S10: DE | T10: DE | U10: DE | V10: DE | W10: DE | X10: DE | Y10: DE | Z10: DE | AA10: DE | AB10: DE | AC10: D | AD10: D | AE10: D | AF10: D | AG10: D | AH10: D | AI10: D | AJ10: D | AK10: D | AL10: =COUNTIF(G10:AK10,"D") -> 9 | AM10: =COUNTIF(G10:AK10,"DE") -> 12 | AN10: =COUNTIF(G10:AK10,"N") -> 10 | AO10: =SUM(AL10:AN10) -> 31 | AP10: =COUNTIF(G10:AK10,"D")+COUNTIF(G10:AK10,"N") -> 19
A11: =A10+1 -> 8 | B11: 16052742-0 | C11: ARDILES NUÑEZ JOSE MIGUEL | D11: A | E11: M | F11: CHOFER | G11: DE | H11: DE | I11: D | J11: D | K11: D | L11: D | M11: D | N11: D | O11: D | P11: D | Q11: D | R11: D | S11: DE | T11: DE | U11: DE | V11: DE | W11: DE | X11: DE | Y11: DE | Z11: DE | AA11: DE | AB11: DE | AC11: N | AD11: N | AE11: N | AF11: N | AG11: N | AH11: N | AI11: N | AJ11: N | AK11: N | AL11: =COUNTIF(G11:AK11,"D") -> 10 | AM11: =COUNTIF(G11:AK11,"DE") -> 12 | AN11: =COUNTIF(G11:AK11,"N") -> 9 | AO11: =SUM(AL11:AN11) -> 31 | AP11: =COUNTIF(G11:AK11,"D")+COUNTIF(G11:AK11,"N") -> 19
A12: =A11+1 -> 9 | B12: 21336141-4 | C12: ASTORGA PINTO BARBARA ANAIS | D12: A | E12: M | F12: ADMINISTRATIVA/O DE FAENA | G12: DE | H12: DE | I12: D | J12: D | K12: D | L12: D | M12: D | N12: D | O12: D | P12: D | Q12: D | R12: D | S12: DE | T12: DE | U12: DE | V12: DE | W12: DE | X12: DE | Y12: DE | Z12: DE | AA12: DE | AB12: DE | AC12: T | AD12: T | AE12: T | AF12: T | AG12: T | AH12: T | AI12: T | AJ12: T | AK12: T | AL12: =COUNTIF(G12:AK12,"D") -> 10 | AM12: =COUNTIF(G12:AK12,"DE") -> 12 | AN12: =COUNTIF(G12:AK12,"N") -> 0 | AO12: =SUM(AL12:AN12) -> 22 | AP12: =COUNTIF(G12:AK12,"D")+COUNTIF(G12:AK12,"N") -> 10
A13: =A12+1 -> 10 | B13: 17979787-9 | C13: BRICEÑO HONORES JOHN ALEXIS | D13: A | E13: M | F13: PREVENCIONISTA | G13: L | H13: L | I13: L | J13: L | K13: L | L13: L | M13: L | N13: L | O13: L | P13: L | Q13: L | R13: L | S13: L | T13: L | U13: L | V13: L | W13: L | X13: L | Y13: L | Z13: L | AA13: DE | AB13: DE | AC13: T | AD13: T | AE13: T | AF13: T | AG13: T | AH13: T | AI13: T | AJ13: T | AK13: T | AL13: =COUNTIF(G13:AK13,"D") -> 0 | AM13: =COUNTIF(G13:AK13,"DE") -> 2 | AN13: =COUNTIF(G13:AK13,"N") -> 0 | AO13: =SUM(AL13:AN13) -> 2 | AP13: =COUNTIF(G13:AK13,"D")+COUNTIF(G13:AK13,"N") -> 0
A14: =A13+1 -> 11 | B14: 17939732-3 | C14: CASSRA ORELLANA DAVID JESUS | D14: A | E14: M | F14: AYUDANTE DE PERFORISTA(RIGGER) | G14: DE | H14: DE | I14: V | J14: V | K14: V | L14: V | M14: D | N14: D | O14: D | P14: D | Q14: D | R14: D | S14: DE | T14: DE | U14: DE | V14: DE | W14: DE | X14: DE | Y14: DE | Z14: DE | AA14: DE | AB14: DE | AC14: N | AD14: N | AE14: N | AF14: N | AG14: N | AH14: N | AI14: N | AJ14: N | AK14: N | AL14: =COUNTIF(G14:AK14,"D") -> 6 | AM14: =COUNTIF(G14:AK14,"DE") -> 12 | AN14: =COUNTIF(G14:AK14,"N") -> 9 | AO14: =SUM(AL14:AN14) -> 27 | AP14: =COUNTIF(G14:AK14,"D")+COUNTIF(G14:AK14,"N") -> 15
A15: =A14+1 -> 12 | B15: 16581787-7 | C15: CASTILLO VALDIVIA FELIX JOEL | D15: A | E15: M | F15: SOLDADOR | G15: DE | H15: DE | I15: D | J15: D | K15: D | L15: D | M15: D | N15: D | O15: D | P15: D | Q15: D | R15: D | S15: DE | T15: DE | U15: DE | V15: DE | W15: DE | X15: DE | Y15: DE | Z15: DE | AA15: DE | AB15: DE | AC15: D | AD15: D | AE15: D | AF15: D | AG15: D | AH15: D | AI15: D | AJ15: D | AK15: D | AL15: =COUNTIF(G15:AK15,"D") -> 19 | AM15: =COUNTIF(G15:AK15,"DE") -> 12 | AN15: =COUNTIF(G15:AK15,"N") -> 0 | AO15: =SUM(AL15:AN15) -> 31 | AP15: =COUNTIF(G15:AK15,"D")+COUNTIF(G15:AK15,"N") -> 19
A16: =A15+1 -> 13 | B16: 17624527-1 | C16: CASTRO AVALOS NELSON ANDRES | D16: A | E16: M | F16: PERFORISTA | G16: DE | H16: DE | I16: N | J16: N | K16: N | L16: N | M16: N | N16: N | O16: N | P16: N | Q16: N | R16: N | S16: DE | T16: DE | U16: DE | V16: DE | W16: DE | X16: DE | Y16: DE | Z16: DE | AA16: DE | AB16: DE | AC16: D | AD16: D | AE16: D | AF16: D | AG16: D | AH16: D | AI16: D | AJ16: D | AK16: D | AL16: =COUNTIF(G16:AK16,"D") -> 9 | AM16: =COUNTIF(G16:AK16,"DE") -> 12 | AN16: =COUNTIF(G16:AK16,"N") -> 10 | AO16: =SUM(AL16:AN16) -> 31 | AP16: =COUNTIF(G16:AK16,"D")+COUNTIF(G16:AK16,"N") -> 19
A17: =A16+1 -> 14 | B17: 19454353-0 | C17: CASTRO HOHMANN KAZUKI | D17: A | E17: M | F17: AYUDANTE DE PERFORISTA | G17: DE | H17: DE | I17: D | J17: D | K17: D | L17: D | M17: D | N17: D | O17: D | P17: D | Q17: D | R17: D | S17: DE | T17: DE | U17: DE | V17: DE | W17: DE | X17: DE | Y17: DE | Z17: DE | AA17: DE | AB17: DE | AC17: N | AD17: N | AE17: N | AF17: N | AG17: N | AH17: N | AI17: N | AJ17: N | AK17: N | AL17: =COUNTIF(G17:AK17,"D") -> 10 | AM17: =COUNTIF(G17:AK17,"DE") -> 12 | AN17: =COUNTIF(G17:AK17,"N") -> 9 | AO17: =SUM(AL17:AN17) -> 31 | AP17: =COUNTIF(G17:AK17,"D")+COUNTIF(G17:AK17,"N") -> 19
A18: =A17+1 -> 15 | B18: 15446035-7 | C18: COFRE ROMERO VICTORIA DEL PILAR | D18: A | E18: F | F18: BODEGUERA/O | G18: DE | H18: DE | I18: D | J18: D | K18: D | L18: D | M18: L | N18: L | O18: L | P18: L | Q18: L | R18: L | S18: DE | T18: DE | U18: DE | V18: DE | W18: DE | X18: DE | Y18: DE | Z18: DE | AA18: DE | AB18: DE | AC18: D | AD18: D | AE18: D | AF18: D | AG18: D | AH18: D | AI18: D | AJ18: D | AK18: D | AL18: =COUNTIF(G18:AK18,"D") -> 13 | AM18: =COUNTIF(G18:AK18,"DE") -> 12 | AN18: =COUNTIF(G18:AK18,"N") -> 0 | AO18: =SUM(AL18:AN18) -> 25 | AP18: =COUNTIF(G18:AK18,"D")+COUNTIF(G18:AK18,"N") -> 13
A19: =A18+1 -> 16 | B19: 13425369-K | C19: CONTRERAS FLORES RICHARD FERNANDO | D19: A | E19: M | F19: AYUDANTE DE PERFORISTA | G19: DE | H19: DE | I19: N | J19: N | K19: N | L19: N | M19: N | N19: N | O19: N | P19: N | Q19: N | R19: N | S19: DE | T19: DE | U19: DE | V19: DE | W19: DE | X19: DE | Y19: DE | Z19: DE | AA19: DE | AB19: DE | AL19: =COUNTIF(G19:AK19,"D") -> 0 | AM19: =COUNTIF(G19:AK19,"DE") -> 12 | AN19: =COUNTIF(G19:AK19,"N") -> 10 | AO19: =SUM(AL19:AN19) -> 22 | AP19: =COUNTIF(G19:AK19,"D")+COUNTIF(G19:AK19,"N") -> 10
A20: =A19+1 -> 17 | B20: 17629034-K | C20: CORTES GONZALEZ JUAN IGNACIO | D20: A | E20: M | F20: PERFORISTA | G20: DE | H20: DE | I20: DE | J20: DE | K20: DE | L20: DE | M20: DE | N20: N | O20: N | P20: N | Q20: N | R20: N | S20: DE | T20: DE | U20: DE | V20: DE | W20: DE | X20: DE | Y20: DE | Z20: DE | AA20: DE | AB20: DE | AC20: D | AD20: D | AE20: D | AF20: D | AG20: D | AH20: D | AI20: D | AJ20: D | AK20: D | AL20: =COUNTIF(G20:AK20,"D") -> 9 | AM20: =COUNTIF(G20:AK20,"DE") -> 17 | AN20: =COUNTIF(G20:AK20,"N") -> 5 | AO20: =SUM(AL20:AN20) -> 31 | AP20: =COUNTIF(G20:AK20,"D")+COUNTIF(G20:AK20,"N") -> 14
A21: =A20+1 -> 18 | B21: 16280454-5 | C21: ESCALONA VERA MANUEL ANTONIO | D21: A | E21: M | F21: PERFORISTA | G21: DE | H21: DE | I21: D | J21: D | K21: D | L21: D | M21: D | N21: D | O21: D | P21: D | Q21: D | R21: D | S21: DE | T21: DE | U21: DE | V21: DE | W21: DE | X21: DE | Y21: DE | Z21: DE | AA21: DE | AB21: DE | AC21: N | AD21: N | AE21: N | AF21: N | AG21: N | AH21: N | AI21: N | AJ21: N | AK21: N | AL21: =COUNTIF(G21:AK21,"D") -> 10 | AM21: =COUNTIF(G21:AK21,"DE") -> 12 | AN21: =COUNTIF(G21:AK21,"N") -> 9 | AO21: =SUM(AL21:AN21) -> 31 | AP21: =COUNTIF(G21:AK21,"D")+COUNTIF(G21:AK21,"N") -> 19
A22: =A21+1 -> 19 | B22: 17118820-2 | C22: FERNANDEZ CASTILLO CLAUDIO ANDRES | D22: A | E22: M | F22: ADMINISTRATIVA/O DE FAENA | G22: DE | H22: DE | I22: D | J22: D | K22: D | L22: D | M22: D | N22: D | O22: D | P22: D | Q22: D | R22: D | S22: DE | T22: DE | U22: DE | V22: DE | W22: DE | X22: DE | Y22: DE | Z22: DE | AA22: DE | AB22: DE | AC22: D | AD22: D | AE22: D | AF22: D | AG22: D | AH22: D | AI22: D | AJ22: D | AK22: D | AL22: =COUNTIF(G22:AK22,"D") -> 19 | AM22: =COUNTIF(G22:AK22,"DE") -> 12 | AN22: =COUNTIF(G22:AK22,"N") -> 0 | AO22: =SUM(AL22:AN22) -> 31 | AP22: =COUNTIF(G22:AK22,"D")+COUNTIF(G22:AK22,"N") -> 19
A23: =A22+1 -> 20 | B23: 19214178-8 | C23: GAETE PAZ GERARDO ANTONIO | D23: A | E23: M | F23: AYUDANTE DE PERFORISTA | G23: DE | H23: DE | I23: N | J23: N | K23: N | L23: N | M23: N | N23: N | O23: N | P23: N | Q23: N | R23: N | S23: DE | T23: DE | U23: DE | V23: DE | W23: DE | X23: DE | Y23: DE | Z23: DE | AA23: DE | AB23: DE | AC23: D | AD23: D | AE23: D | AF23: D | AG23: D | AH23: D | AI23: D | AJ23: D | AK23: D | AL23: =COUNTIF(G23:AK23,"D") -> 9 | AM23: =COUNTIF(G23:AK23,"DE") -> 12 | AN23: =COUNTIF(G23:AK23,"N") -> 10 | AO23: =SUM(AL23:AN23) -> 31 | AP23: =COUNTIF(G23:AK23,"D")+COUNTIF(G23:AK23,"N") -> 19
A24: =A23+1 -> 21 | B24: 15909798-6 | C24: GALLEGUILLOS ARANCIBIA GABRIEL ALEJANDRO | D24: A | E24: M | F24: MECANICO | G24: DE | H24: DE | I24: D | J24: D | K24: D | L24: D | M24: D | N24: D | O24: D | P24: D | Q24: D | R24: D | S24: DE | T24: DE | U24: DE | V24: DE | W24: DE | X24: DE | Y24: DE | Z24: DE | AA24: DE | AB24: DE | AC24: N | AD24: N | AE24: N | AF24: N | AG24: N | AH24: N | AI24: N | AJ24: N | AK24: N | AL24: =COUNTIF(G24:AK24,"D") -> 10 | AM24: =COUNTIF(G24:AK24,"DE") -> 12 | AN24: =COUNTIF(G24:AK24,"N") -> 9 | AO24: =SUM(AL24:AN24) -> 31 | AP24: =COUNTIF(G24:AK24,"D")+COUNTIF(G24:AK24,"N") -> 19
A25: =A24+1 -> 22 | B25: 16892590-5 | C25: GALLEGUILLOS DIAZ ERIC ALFONSO | D25: A | E25: M | F25: AYUDANTE DE PERFORISTA | G25: DE | H25: DE | I25: V | J25: V | K25: V | L25: V | M25: V | N25: V | O25: V | P25: V | Q25: V | R25: V | S25: DE | T25: DE | U25: DE | V25: DE | W25: DE | X25: DE | Y25: DE | Z25: DE | AA25: DE | AB25: DE | AC25: N | AD25: N | AE25: N | AF25: N | AG25: N | AH25: N | AI25: N | AJ25: N | AK25: N | AL25: =COUNTIF(G25:AK25,"D") -> 0 | AM25: =COUNTIF(G25:AK25,"DE") -> 12 | AN25: =COUNTIF(G25:AK25,"N") -> 9 | AO25: =SUM(AL25:AN25) -> 21 | AP25: =COUNTIF(G25:AK25,"D")+COUNTIF(G25:AK25,"N") -> 9
A26: =A25+1 -> 23 | B26: 17827549-6 | C26: GONZALEZ ROMERO JUAN EDUARDO | D26: A | E26: M | F26: AYUDANTE DE PERFORISTA | G26: DE | H26: DE | I26: D | J26: D | K26: D | L26: D | M26: D | N26: D | O26: D | P26: D | Q26: D | R26: D | S26: DE | T26: DE | U26: DE | V26: DE | W26: DE | X26: DE | Y26: DE | Z26: DE | AA26: DE | AB26: DE | AC26: N | AD26: N | AE26: N | AF26: N | AG26: N | AH26: N | AI26: N | AJ26: N | AK26: N | AL26: =COUNTIF(G26:AK26,"D") -> 10 | AM26: =COUNTIF(G26:AK26,"DE") -> 12 | AN26: =COUNTIF(G26:AK26,"N") -> 9 | AO26: =SUM(AL26:AN26) -> 31 | AP26: =COUNTIF(G26:AK26,"D")+COUNTIF(G26:AK26,"N") -> 19
A27: =A26+1 -> 24 | B27: 17294242-3 | C27: JERALDO CORTES DANIEL EDUARDO | D27: A | E27: M | F27: PERFORISTA | G27: DE | H27: DE | I27: N | J27: N | K27: N | L27: N | M27: N | N27: N | O27: N | P27: N | Q27: N | R27: N | S27: DE | T27: DE | U27: DE | V27: DE | W27: DE | X27: DE | Y27: DE | Z27: DE | AA27: DE | AB27: DE | AC27: D | AD27: D | AE27: D | AF27: D | AG27: D | AH27: D | AI27: D | AJ27: D | AK27: D | AL27: =COUNTIF(G27:AK27,"D") -> 9 | AM27: =COUNTIF(G27:AK27,"DE") -> 12 | AN27: =COUNTIF(G27:AK27,"N") -> 10 | AO27: =SUM(AL27:AN27) -> 31 | AP27: =COUNTIF(G27:AK27,"D")+COUNTIF(G27:AK27,"N") -> 19
A28: =A27+1 -> 25 | B28: 17294428-0 | C28: JIMENEZ VEGA LUIS RENATO DE JESUS | D28: A | E28: M | F28: CHOFER | G28: DE | H28: DE | I28: D | J28: D | K28: D | L28: D | M28: D | N28: D | O28: D | P28: D | Q28: D | R28: D | S28: DE | T28: DE | U28: DE | V28: DE | W28: DE | X28: DE | Y28: DE | Z28: DE | AA28: DE | AB28: DE | AC28: N | AD28: N | AE28: N | AF28: N | AG28: N | AH28: N | AI28: N | AJ28: N | AK28: N | AL28: =COUNTIF(G28:AK28,"D") -> 10 | AM28: =COUNTIF(G28:AK28,"DE") -> 12 | AN28: =COUNTIF(G28:AK28,"N") -> 9 | AO28: =SUM(AL28:AN28) -> 31 | AP28: =COUNTIF(G28:AK28,"D")+COUNTIF(G28:AK28,"N") -> 19
A29: =A28+1 -> 26 | B29: 12115176-6 | C29: LEIVA LEIVA FRANCISCO JAVIER | D29: A | E29: M | F29: PERFORISTA | G29: DE | H29: DE | I29: D | J29: D | K29: D | L29: D | M29: D | N29: D | O29: D | P29: D | Q29: D | R29: D | S29: DE | T29: DE | U29: DE | V29: DE | W29: DE | X29: DE | Y29: DE | Z29: DE | AA29: DE | AB29: DE | AC29: N | AD29: N | AE29: N | AF29: N | AG29: N | AH29: N | AI29: N | AJ29: N | AK29: N | AL29: =COUNTIF(G29:AK29,"D") -> 10 | AM29: =COUNTIF(G29:AK29,"DE") -> 12 | AN29: =COUNTIF(G29:AK29,"N") -> 9 | AO29: =SUM(AL29:AN29) -> 31 | AP29: =COUNTIF(G29:AK29,"D")+COUNTIF(G29:AK29,"N") -> 19
A30: =A29+1 -> 27 | B30: 18688482-5 | C30: LORCA SANCHEZ LUIS DAVID | D30: A | E30: M | F30: PREVENCIONISTA | G30: DE | H30: DE | I30: LS | J30: LS | K30: LS | L30: D | M30: D | N30: D | O30: DE | P30: DE | Q30: DE | R30: DE | S30: DE | T30: DE | U30: D | V30: D | W30: D | X30: D | Y30: D | Z30: D | AA30: D | AB30: D | AC30: DE | AD30: DE | AE30: DE | AF30: DE | AG30: DE | AH30: DE | AI30: DE | AJ30: DE | AK30: DE | AL30: =COUNTIF(G30:AK30,"D") -> 11 | AM30: =COUNTIF(G30:AK30,"DE") -> 17 | AN30: =COUNTIF(G30:AK30,"N") -> 0 | AO30: =SUM(AL30:AN30) -> 28 | AP30: =COUNTIF(G30:AK30,"D")+COUNTIF(G30:AK30,"N") -> 11
A31: =A30+1 -> 28 | B31: 18633143-5 | C31: MALDONADO MONDACA CRISTOFER JESUS | D31: A | E31: M | F31: CHOFER | G31: DE | H31: DE | I31: N | J31: N | K31: N | L31: N | M31: N | N31: N | O31: N | P31: N | Q31: N | R31: N | S31: DE | T31: DE | U31: DE | V31: DE | W31: DE | X31: DE | Y31: DE | Z31: DE | AA31: DE | AB31: DE | AC31: D | AD31: D | AE31: D | AF31: D | AG31: D | AH31: D | AI31: D | AJ31: D | AK31: D | AL31: =COUNTIF(G31:AK31,"D") -> 9 | AM31: =COUNTIF(G31:AK31,"DE") -> 12 | AN31: =COUNTIF(G31:AK31,"N") -> 10 | AO31: =SUM(AL31:AN31) -> 31 | AP31: =COUNTIF(G31:AK31,"D")+COUNTIF(G31:AK31,"N") -> 19
... A49: =A48+1 -> 46 | B49: 14903561-3 | C49: VALENCIA CAMPOS ANDRES ALEJANDRO | D49: A | E49: M | F49: SUPERVISOR DE OPERACIONES | G49: DE | H49: DE | I49: N | J49: N | K49: N | L49: N | M49: N | N49: N | O49: N | P49: N | Q49: N | R49: N | S49: DE | T49: DE | U49: DE | V49: DE | W49: DE | X49: DE | Y49: DE | Z49: DE | AA49: DE | AB49: DE | AC49: D | AD49: D | AE49: D | AF49: D | AG49: D | AH49: D | AI49: D | AJ49: D | AK49: D | AL49: =COUNTIF(G49:AK49,"D") -> 9 | AM49: =COUNTIF(G49:AK49,"DE") -> 12 | AN49: =COUNTIF(G49:AK49,"N") -> 10 | AO49: =SUM(AL49:AN49) -> 31 | AP49: =COUNTIF(G49:AK49,"D")+COUNTIF(G49:AK49,"N") -> 19
A50: =A49+1 -> 47 | B50: 13743972-7 | C50: VEGA GONZALEZ PATRICIO COLLO | D50: A | E50: M | F50: AYUDANTE DE PERFORISTA(RIGGER) | G50: DE | H50: DE | I50: N | J50: N | K50: N | L50: N | M50: N | N50: N | O50: N | P50: N | Q50: N | R50: N | S50: DE | T50: DE | U50: DE | V50: DE | W50: DE | X50: DE | Y50: DE | Z50: DE | AA50: DE | AB50: DE | AL50: =COUNTIF(G50:AK50,"D") -> 0 | AM50: =COUNTIF(G50:AK50,"DE") -> 12 | AN50: =COUNTIF(G50:AK50,"N") -> 10 | AO50: =SUM(AL50:AN50) -> 22 | AP50: =COUNTIF(G50:AK50,"D")+COUNTIF(G50:AK50,"N") -> 10
A51: =A50+1 -> 48 | B51: 17775054-9 | C51: ZAPATA SEGUEL CARLOS ANDRES | D51: A | E51: M | F51: AYUDANTE DE PERFORISTA | G51: DE | H51: DE | I51: D | J51: D | K51: D | L51: D | M51: D | N51: D | O51: D | P51: D | Q51: D | R51: D | S51: DE | T51: DE | U51: DE | V51: DE | W51: DE | X51: DE | Y51: DE | Z51: DE | AA51: DE | AB51: DE | AC51: N | AD51: N | AE51: N | AF51: N | AG51: N | AH51: N | AI51: N | AJ51: N | AK51: N | AL51: =COUNTIF(G51:AK51,"D") -> 10 | AM51: =COUNTIF(G51:AK51,"DE") -> 12 | AN51: =COUNTIF(G51:AK51,"N") -> 9 | AO51: =SUM(AL51:AN51) -> 31 | AP51: =COUNTIF(G51:AK51,"D")+COUNTIF(G51:AK51,"N") -> 19
A52: =A51+1 -> 49 | B52: 17293946-5 | C52: GONZALEZ JERALDO HAMIR ALONSO | D52: B | E52: M | F52: PERFORISTA (INSTRUCTOR) | G52: D | H52: D | I52: D | J52: D | K52: D | L52: D | M52: D | N52: DE | O52: DE | P52: DE | Q52: DE | R52: DE | S52: DE | T52: DE | U52: L | V52: L | W52: L | X52: L | Y52: L | Z52: L | AA52: L | AB52: L | AC52: L | AD52: L | AE52: L | AF52: L | AG52: L | AH52: L | AI52: L | AJ52: L | AK52: L | AL52: =COUNTIF(G52:AK52,"D") -> 7 | AM52: =COUNTIF(G52:AK52,"DE") -> 7 | AN52: =COUNTIF(G52:AK52,"N") -> 0 | AO52: =SUM(AL52:AN52) -> 14 | AP52: =COUNTIF(G52:AK52,"D")+COUNTIF(G52:AK52,"N") -> 7
A53: =A52+1 -> 50 | B53: 13011075-4 | C53: BORQUEZ CARVAJAL IBAR ALEXIS | D53: AB | E53: M | F53: JEFE DE FAENA | G53: DE | H53: DE | I53: DE | J53: DE | K53: DE | L53: DE | M53: DE | N53: D | O53: D | P53: D | Q53: D | R53: D | S53: D | T53: D | U53: D | V53: D | W53: D | X53: DE | Y53: DE | Z53: DE | AA53: DE | AB53: DE | AC53: DE | AD53: DE | AE53: DE | AF53: DE | AG53: DE | AH53: D | AI53: D | AJ53: D | AK53: D | AL53: =COUNTIF(G53:AK53,"D") -> 14 | AM53: =COUNTIF(G53:AK53,"DE") -> 17 | AN53: =COUNTIF(G53:AK53,"N") -> 0 | AO53: =SUM(AL53:AN53) -> 31 | AP53: =COUNTIF(G53:AK53,"D")+COUNTIF(G53:AK53,"N") -> 14
A54: =A53+1 -> 51 | B54: 17169171-0 | C54: LOPEZ OLAVE LUIS GERARDO | D54: AB | E54: M | F54: MECANICO | G54: DE | H54: DE | I54: DE | J54: DE | K54: DE | L54: DE | M54: DE | N54: D | O54: D | P54: D | Q54: D | R54: D | S54: D | T54: D | U54: D | V54: D | W54: D | X54: DE | Y54: DE | Z54: DE | AA54: DE | AB54: DE | AC54: DE | AD54: DE | AE54: DE | AF54: DE | AG54: DE | AH54: D | AI54: D | AJ54: D | AK54: D | AL54: =COUNTIF(G54:AK54,"D") -> 14 | AM54: =COUNTIF(G54:AK54,"DE") -> 17 | AN54: =COUNTIF(G54:AK54,"N") -> 0 | AO54: =SUM(AL54:AN54) -> 31 | AP54: =COUNTIF(G54:AK54,"D")+COUNTIF(G54:AK54,"N") -> 14
A55: =A54+1 -> 52 | B55: 19948246-7 | C55: RAMIREZ BARRAZA MARCELO GIOVANNI | D55: AB | E55: M | F55: MECANICO | G55: D | H55: D | I55: D | J55: D | K55: D | L55: D | M55: D | N55: DE | O55: DE | P55: DE | Q55: DE | R55: DE | S55: DE | T55: DE | U55: DE | V55: DE | W55: DE | X55: D | Y55: D | Z55: D | AA55: D | AB55: D | AC55: D | AD55: D | AE55: D | AF55: D | AG55: D | AH55: DE | AI55: DE | AJ55: DE | AK55: DE | AL55: =COUNTIF(G55:AK55,"D") -> 17 | AM55: =COUNTIF(G55:AK55,"DE") -> 14 | AN55: =COUNTIF(G55:AK55,"N") -> 0 | AO55: =SUM(AL55:AN55) -> 31 | AP55: =COUNTIF(G55:AK55,"D")+COUNTIF(G55:AK55,"N") -> 17
A56: =A55+1 -> 53 | B56: 16463792-1 | C56: ROJAS MARTINEZ FRANCISCO JAVIER | D56: AB | E56: M | F56: JEFE DE FAENA | G56: D | H56: D | I56: D | J56: D | K56: D | L56: D | M56: D | N56: DE | O56: DE | P56: DE | Q56: DE | R56: DE | S56: DE | T56: DE | U56: DE | V56: DE | W56: DE | X56: D | Y56: D | Z56: D | AA56: D | AB56: D | AC56: D | AD56: D | AE56: D | AF56: D | AG56: D | AH56: DE | AI56: DE | AJ56: DE | AK56: DE | AL56: =COUNTIF(G56:AK56,"D") -> 17 | AM56: =COUNTIF(G56:AK56,"DE") -> 14 | AN56: =COUNTIF(G56:AK56,"N") -> 0 | AO56: =SUM(AL56:AN56) -> 31 | AP56: =COUNTIF(G56:AK56,"D")+COUNTIF(G56:AK56,"N") -> 17
A57: =A56+1 -> 54 | B57: 13748728-4 | C57: ALFARO CASTELLANOS CARLOS JAVIER | D57: B | E57: M | F57: AYUDANTE DE PERFORISTA | G57: D | H57: D | I57: DE | J57: DE | K57: DE | L57: DE | M57: DE | N57: DE | O57: DE | P57: DE | Q57: DE | R57: DE | S57: T | T57: T | U57: T | V57: T | W57: T | X57: T | Y57: T | Z57: T | AA57: T | AB57: T | AC57: T | AD57: T | AE57: T | AF57: T | AG57: T | AH57: T | AI57: T | AJ57: T | AK57: T | AL57: =COUNTIF(G57:AK57,"D") -> 2 | AM57: =COUNTIF(G57:AK57,"DE") -> 10 | AN57: =COUNTIF(G57:AK57,"N") -> 0 | AO57: =SUM(AL57:AN57) -> 12 | AP57: =COUNTIF(G57:AK57,"D")+COUNTIF(G57:AK57,"N") -> 2
...

Sheet NO OP
H1: METROS POR MÁQUINA DDH | P1: METROS RC
C2: VALOR METRO 0-500 | D2: VALOR METRO 501-1000 | E2: VALOR METRO 1001- | J2: 740/7 | N2: 740/14 | P2: 1200-01
J3: 0-500 | K3: 501-1000 | N3: 0-500 | O3: 501-1000 | P3: 0-600
B4: AYUDANTE | C4: 500 | D4: 700 | E4: 900 | G4: TURNO A | J4: ='740-7'!$AN$9 -> 298.3 | K4: ='740-7'!$AO$9 -> 0 | N4: ='740-14 '!$AO$9 -> 411.75 | O4: ='740-14 '!$AP$9 -> 43.75 | P4: ='1200-01'!$AK$9 -> 856
B5: PERFORISTA | C5: 750 | D5: 900 | E5: 1200 | J5: =J4+K4 -> 298.3 | N5: =N4+O4 -> 455.5
G6: TURNO B | J6: ='740-7'!$AP$9 -> 168.2 | K6: ='740-7'!$AQ$9 -> 0 | N6: ='740-14 '!$AQ$9 -> 237.15 | O6: ='740-14 '!$AR$9 -> 6.25 | P6: ='1200-01'!$AL$9 -> 336
C7: 0-600 RC | J7: =J6+K6 -> 168.2 | N7: =N6+O6 -> 243.4
B9: AYUDANTE | C9: 200 | G9: TOTAL MES | J9: 0-500 | K9: 501-1000 | N9: 0-500 | O9: 501-1000 | P9: 0-600
B10: PERFORISTA | C10: 300 | J10: =J4+J6 -> 466.5 | K10: =K4+K6 -> 0 | N10: =N4+N6 -> 648.9 | O10: =O4+O6 -> 50
J11: =J10+K10 -> 466.5 | N11: =N10+O10 -> 698.9 | P11: =P4+P6 -> 1192
B14: TURNO A | I14: METROS | L14: VALOR EN PESO | P14: 25
B15: RUT | C15: FECHA INGRESO MV | D15: FECHA SALIDA | E15: VIGENCIA | F15: NOMBRE | G15: CARGO | H15: MEJOR MAQUINA | I15: 0-500 | J15: 501-1000 | K15: 1001-1500 | L15: VALOR 0-500 | M15: VALOR 501-1000 | N15: VALOR 1001-1500 | O15: TOTAL | P15: ASISTENCIA | Q15: TOTAL A PAGO | R15: OBSERVACION | S15: CONTRATO HASTA | AD15: =$AD$2*AA15 -> 0 | AE15: =$AE$2*AB15 -> 0
B16: 17118820-2 | C16: 45691 | E16: VIGENTE | F16: FERNANDEZ CASTILLO CLAUDIO ANDRES | G16: ADMINISTRATIVA/O DE FAENA | H16: =MAX($H$11:$O$11) -> 698.9 | I16: {=_xlfn.IFS($J$11=MAX($J$11,$N$11),$J$10,$N$11=MAX($J$11,$N$11),$N$10)} -> 648.9 | J16: {=_xlfn.IFS( $J$11=MAX($J$11,$N$11),$K$10, $N$11=MAX($J$11,$N$11),$O$10)} -> 50 | K16: 0 | L16: =I16*$C$4 -> 324450 | M16: =J16*$D$4 -> 35000 | N16: =K16*$E$4 -> 0 | O16: 353450 | P16: =VLOOKUP(B16,'ASISTENCIA JULIO'!$B$4:$AP$128,41,FALSE) -> 19 | Q16: =(O16/$P$14)*P16 -> 268622
B17: 21336141-4 | C17: 46087 | E17: VIGENTE | F17: ASTORGA PINTO BARBARA ANAIS | G17: ADMINISTRATIVA/O DE FAENA | H17: =MAX($H$11:$O$11) -> 698.9 | I17: {=_xlfn.IFS( $H$11=MAX($H$11,$J$11,$L$11,$N$11),$H$10, $J$11=MAX($H$11,$J$11,$L$11,$N$11),$J$10, $L$11=MAX($H$11,$J$11,$L$11,$N$11),$L$10, $N$11=MAX($H$11,$J$11,$L$11,$N$11),$N$10)} -> 648.9 | J17: {=_xlfn.IFS( $J$11=MAX($J$11,$N$11),$K$10, $N$11=MAX($J$11,$N$11),$O$10)} -> 50 | K17: 0 | L17: =I17*$C$4 -> 324450 | M17: =J17*$D$4 -> 35000 | N17: =K17*$E$4 -> 0 | O17: 353450 | P17: =VLOOKUP(B17,'ASISTENCIA JULIO'!$B$4:$AP$128,41,FALSE) -> 10 | Q17: =(O17/$P$14)*P17 -> 141380
B18: 15050618-2 | C18: 45967 | E18: VIGENTE | F18: VIGORENA DUARTE KAREN ANDREA | G18: ADMINISTRATIVA/O DE FAENA | H18: =MAX($H$11:$O$11) -> 698.9 | I18: {=_xlfn.IFS( $H$11=MAX($H$11,$J$11,$L$11,$N$11),$H$10, $J$11=MAX($H$11,$J$11,$L$11,$N$11),$J$10, $L$11=MAX($H$11,$J$11,$L$11,$N$11),$L$10, $N$11=MAX($H$11,$J$11,$L$11,$N$11),$N$10)} -> 648.9 | J18: {=_xlfn.IFS( $J$11=MAX($J$11,$N$11),$K$10, $N$11=MAX($J$11,$N$11),$O$10)} -> 50 | K18: 0 | L18: =I18*$C$4 -> 324450 | M18: =J18*$D$4 -> 35000 | N18: =K18*$E$4 -> 0 | O18: 353450 | P18: =VLOOKUP(B18,'ASISTENCIA JULIO'!$B$4:$AP$128,41,FALSE) -> 19 | Q18: =(O18/$P$14)*P18 -> 268622
B19: 15446035-7 | C19: 45627 | E19: VIGENTE | F19: COFRE ROMERO VICTORIA DEL PILAR | G19: BODEGUERA/O | H19: =MAX($H$11:$O$11) -> 698.9 | I19: {=_xlfn.IFS( $H$11=MAX($H$11,$J$11,$L$11,$N$11),$H$10, $J$11=MAX($H$11,$J$11,$L$11,$N$11),$J$10, $L$11=MAX($H$11,$J$11,$L$11,$N$11),$L$10, $N$11=MAX($H$11,$J$11,$L$11,$N$11),$N$10)} -> 648.9 | J19: {=_xlfn.IFS( $J$11=MAX($J$11,$N$11),$K$10, $N$11=MAX($J$11,$N$11),$O$10)} -> 50 | K19: 0 | L19: =I19*$C$4 -> 324450 | M19: =J19*$D$4 -> 35000 | N19: =K19*$E$4 -> 0 | O19: 353450 | P19: =VLOOKUP(B19,'ASISTENCIA JULIO'!$B$4:$AP$128,41,FALSE) -> 13 | Q19: =(O19/$P$14)*P19 -> 183794
B20: 15056140-K | C20: 45627 | E20: VIGENTE | F20: ARDILES NUÑEZ JONATHAN ANDRES | G20: CHOFER | H20: =MAX($H$11:$O$11) -> 698.9 | I20: {=_xlfn.IFS( $H$11=MAX($H$11,$J$11,$L$11,$N$11),$H$10, $J$11=MAX($H$11,$J$11,$L$11,$N$11),$J$10, $L$11=MAX($H$11,$J$11,$L$11,$N$11),$L$10, $N$11=MAX($H$11,$J$11,$L$11,$N$11),$N$10)} -> 648.9 | J20: {=_xlfn.IFS( $J$11=MAX($J$11,$N$11),$K$10, $N$11=MAX($J$11,$N$11),$O$10)} -> 50 | K20: 0 | L20: =I20*$C$4 -> 324450 | M20: =J20*$D$4 -> 35000 | N20: =K20*$E$4 -> 0 | O20: 353450 | P20: =VLOOKUP(B20,'ASISTENCIA JULIO'!$B$4:$AP$128,41,FALSE) -> 19 | Q20: =(O20/$P$14)*P20 -> 268622
B21: 16052742-0 | C21: 45733 | E21: VIGENTE | F21: ARDILES NUÑEZ JOSE MIGUEL | G21: CHOFER | H21: =MAX($H$11:$O$11) -> 698.9 | I21: {=_xlfn.IFS( $H$11=MAX($H$11,$J$11,$L$11,$N$11),$H$10, $J$11=MAX($H$11,$J$11,$L$11,$N$11),$J$10, $L$11=MAX($H$11,$J$11,$L$11,$N$11),$L$10, $N$11=MAX($H$11,$J$11,$L$11,$N$11),$N$10)} -> 648.9 | J21: {=_xlfn.IFS( $J$11=MAX($J$11,$N$11),$K$10, $N$11=MAX($J$11,$N$11),$O$10)} -> 50 | K21: 0 | L21: =I21*$C$4 -> 324450 | M21: =J21*$D$4 -> 35000 | N21: =K21*$E$4 -> 0 | O21: 353450 | P21: =VLOOKUP(B21,'ASISTENCIA JULIO'!$B$4:$AP$128,41,FALSE) -> 19 | Q21: =(O21/$P$14)*P21 -> 268622
B22: 17294428-0 | C22: 45804 | E22: VIGENTE | F22: JIMENEZ VEGA LUIS RENATO DE JESUS | G22: CHOFER | H22: =MAX($H$11:$O$11) -> 698.9 | I22: {=_xlfn.IFS( $H$11=MAX($H$11,$J$11,$L$11,$N$11),$H$10, $J$11=MAX($H$11,$J$11,$L$11,$N$11),$J$10, $L$11=MAX($H$11,$J$11,$L$11,$N$11),$L$10, $N$11=MAX($H$11,$J$11,$L$11,$N$11),$N$10)} -> 648.9 | J22: {=_xlfn.IFS( $J$11=MAX($J$11,$N$11),$K$10, $N$11=MAX($J$11,$N$11),$O$10)} -> 50 | K22: 0 | L22: =I22*$C$4 -> 324450 | M22: =J22*$D$4 -> 35000 | N22: =K22*$E$4 -> 0 | O22: 353450 | P22: =VLOOKUP(B22,'ASISTENCIA JULIO'!$B$4:$AP$128,41,FALSE) -> 19 | Q22: =(O22/$P$14)*P22 -> 268622
B23: 18633143-5 | C23: 46063 | E23: VIGENTE | F23: MALDONADO MONDACA CRISTOFER JESUS | G23: CHOFER | H23: =MAX($H$11:$O$11) -> 698.9 | I23: {=_xlfn.IFS( $H$11=MAX($H$11,$J$11,$L$11,$N$11),$H$10, $J$11=MAX($H$11,$J$11,$L$11,$N$11),$J$10, $L$11=MAX($H$11,$J$11,$L$11,$N$11),$L$10, $N$11=MAX($H$11,$J$11,$L$11,$N$11),$N$10)} -> 648.9 | J23: {=_xlfn.IFS( $J$11=MAX($J$11,$N$11),$K$10, $N$11=MAX($J$11,$N$11),$O$10)} -> 50 | K23: 0 | L23: =I23*$C$4 -> 324450 | M23: =J23*$D$4 -> 35000 | N23: =K23*$E$4 -> 0 | O23: 353450 | P23: =VLOOKUP(B23,'ASISTENCIA JULIO'!$B$4:$AP$128,41,FALSE) -> 19 | Q23: =(O23/$P$14)*P23 -> 268622
B24: 19460207-3 | C24: 45876 | E24: VIGENTE | F24: POBLETE KUHNE PABLO LUCAS | G24: CHOFER | H24: =MAX($H$11:$O$11) -> 698.9 | I24: {=_xlfn.IFS( $H$11=MAX($H$11,$J$11,$L$11,$N$11),$H$10, $J$11=MAX($H$11,$J$11,$L$11,$N$11),$J$10, $L$11=MAX($H$11,$J$11,$L$11,$N$11),$L$10, $N$11=MAX($H$11,$J$11,$L$11,$N$11),$N$10)} -> 648.9 | J24: {=_xlfn.IFS( $J$11=MAX($J$11,$N$11),$K$10, $N$11=MAX($J$11,$N$11),$O$10)} -> 50 | K24: 0 | L24: =I24*$C$4 -> 324450 | M24: =J24*$D$4 -> 35000 | N24: =K24*$E$4 -> 0 | O24: 353450 | P24: =VLOOKUP(B24,'ASISTENCIA JULIO'!$B$4:$AP$128,41,FALSE) -> 10 | Q24: =(O24/$P$14)*P24 -> 141380 | R24: Traslado el 23-07
B25: 13804452-1 | C25: 45646 | E25: VIGENTE | F25: SANDOVAL SEPULVEDA GERSON ANDRES | G25: CHOFER | H25: =MAX($H$11:$O$11) -> 698.9 | I25: {=_xlfn.IFS( $H$11=MAX($H$11,$J$11,$L$11,$N$11),$H$10, $J$11=MAX($H$11,$J$11,$L$11,$N$11),$J$10, $L$11=MAX($H$11,$J$11,$L$11,$N$11),$L$10, $N$11=MAX($H$11,$J$11,$L$11,$N$11),$N$10)} -> 648.9 | J25: {=_xlfn.IFS( $J$11=MAX($J$11,$N$11),$K$10, $N$11=MAX($J$11,$N$11),$O$10)} -> 50 | K25: 0 | L25: =I25*$C$4 -> 324450 | M25: =J25*$D$4 -> 35000 | N25: =K25*$E$4 -> 0 | O25: 353450 | P25: =VLOOKUP(B25,'ASISTENCIA JULIO'!$B$4:$AP$128,41,FALSE) -> 19 | Q25: =(O25/$P$14)*P25 -> 268622
B26: 15831074-0 | C26: 46049 | E26: VIGENTE | F26: NAETER QUIROZ ESTEFANIA CONSTANZA | G26: CHOFER TRADUCTOR | H26: =MAX($H$11:$O$11) -> 698.9 | I26: {=_xlfn.IFS( $H$11=MAX($H$11,$J$11,$L$11,$N$11),$H$10, $J$11=MAX($H$11,$J$11,$L$11,$N$11),$J$10, $L$11=MAX($H$11,$J$11,$L$11,$N$11),$L$10, $N$11=MAX($H$11,$J$11,$L$11,$N$11),$N$10)} -> 648.9 | J26: {=_xlfn.IFS( $J$11=MAX($J$11,$N$11),$K$10, $N$11=MAX($J$11,$N$11),$O$10)} -> 50 | K26: 0 | L26: =I26*$C$4 -> 324450 | M26: =J26*$D$4 -> 35000 | N26: =K26*$E$4 -> 0 | O26: 353450 | P26: =VLOOKUP(B26,'ASISTENCIA JULIO'!$B$4:$AP$128,41,FALSE) -> 4 | Q26: =(O26/$P$14)*P26 -> 56552
B27: 15909798-6 | C27: 46148 | E27: VIGENTE | F27: GALLEGUILLOS ARANCIBIA GABRIEL ALEJANDRO | G27: MECANICO | H27: =MAX($H$11:$O$11) -> 698.9 | I27: {=_xlfn.IFS( $H$11=MAX($H$11,$J$11,$L$11,$N$11),$H$10, $J$11=MAX($H$11,$J$11,$L$11,$N$11),$J$10, $L$11=MAX($H$11,$J$11,$L$11,$N$11),$L$10, $N$11=MAX($H$11,$J$11,$L$11,$N$11),$N$10)} -> 648.9 | J27: {=_xlfn.IFS( $J$11=MAX($J$11,$N$11),$K$10, $N$11=MAX($J$11,$N$11),$O$10)} -> 50 | K27: 0 | L27: =I27*$C$4 -> 324450 | M27: =J27*$D$4 -> 35000 | N27: =K27*$E$4 -> 0 | O27: 353450 | P27: 19 | Q27: =(O27/$P$14)*P27 -> 268622
B28: 19910908-1 | C28: 45826 | E28: VIGENTE | F28: SANDERSON SALCEDO CRISTOBAL ALEXIC | G28: MECANICO | H28: =MAX($H$11:$O$11) -> 698.9 | I28: {=_xlfn.IFS( $H$11=MAX($H$11,$J$11,$L$11,$N$11),$H$10, $J$11=MAX($H$11,$J$11,$L$11,$N$11),$J$10, $L$11=MAX($H$11,$J$11,$L$11,$N$11),$L$10, $N$11=MAX($H$11,$J$11,$L$11,$N$11),$N$10)} -> 648.9 | J28: {=_xlfn.IFS( $J$11=MAX($J$11,$N$11),$K$10, $N$11=MAX($J$11,$N$11),$O$10)} -> 50 | K28: 0 | L28: =I28*$C$4 -> 324450 | M28: =J28*$D$4 -> 35000 | N28: =K28*$E$4 -> 0 | O28: 353450 | P28: =VLOOKUP(B28,'ASISTENCIA JULIO'!$B$4:$AP$128,41,FALSE) -> 19 | Q28: =(O28/$P$14)*P28 -> 268622
B29: 17998731-7 | C29: 45946 | E29: VIGENTE | F29: RIVERA HERRERA ANGELO PATRICIO | G29: MECANICO FLOTA | H29: =MAX($H$11:$O$11) -> 698.9 | I29: {=_xlfn.IFS( $H$11=MAX($H$11,$J$11,$L$11,$N$11),$H$10, $J$11=MAX($H$11,$J$11,$L$11,$N$11),$J$10, $L$11=MAX($H$11,$J$11,$L$11,$N$11),$L$10, $N$11=MAX($H$11,$J$11,$L$11,$N$11),$N$10)} -> 648.9 | J29: {=_xlfn.IFS( $J$11=MAX($J$11,$N$11),$K$10, $N$11=MAX($J$11,$N$11),$O$10)} -> 50 | K29: 0 | L29: =I29*$C$4 -> 324450 | M29: =J29*$D$4 -> 35000 | N29: =K29*$E$4 -> 0 | O29: 353450 | P29: =VLOOKUP(B29,'ASISTENCIA JULIO'!$B$4:$AP$128,41,FALSE) -> 19 | Q29: =(O29/$P$14)*P29 -> 268622
B30: 16581787-7 | C30: 45946 | E30: VIGENTE | F30: CASTILLO VALDIVIA FELIX JOEL | G30: SOLDADOR | H30: =MAX($H$11:$O$11) -> 698.9 | I30: {=_xlfn.IFS( $H$11=MAX($H$11,$J$11,$L$11,$N$11),$H$10, $J$11=MAX($H$11,$J$11,$L$11,$N$11),$J$10, $L$11=MAX($H$11,$J$11,$L$11,$N$11),$L$10, $N$11=MAX($H$11,$J$11,$L$11,$N$11),$N$10)} -> 648.9 | J30: {=_xlfn.IFS( $J$11=MAX($J$11,$N$11),$K$10, $N$11=MAX($J$11,$N$11),$O$10)} -> 50 | K30: 0 | L30: =I30*$C$4 -> 324450 | M30: =J30*$D$4 -> 35000 | N30: =K30*$E$4 -> 0 | O30: 353450 | P30: =VLOOKUP(B30,'ASISTENCIA JULIO'!$B$4:$AP$128,41,FALSE) -> 19 | Q30: =(O30/$P$14)*P30 -> 268622
B31: 13533794-3 | C31: 45946 | E31: VIGENTE | F31: MUÑOZ PORTILLA CRISTIAN GUMERCINDO | G31: SOLDADOR | H31: =MAX($H$11:$O$11) -> 698.9 | I31: {=_xlfn.IFS( $H$11=MAX($H$11,$J$11,$L$11,$N$11),$H$10, $J$11=MAX($H$11,$J$11,$L$11,$N$11),$J$10, $L$11=MAX($H$11,$J$11,$L$11,$N$11),$L$10, $N$11=MAX($H$11,$J$11,$L$11,$N$11),$N$10)} -> 648.9 | J31: {=_xlfn.IFS( $J$11=MAX($J$11,$N$11),$K$10, $N$11=MAX($J$11,$N$11),$O$10)} -> 50 | K31: 0 | L31: =I31*$C$4 -> 324450 | M31: =J31*$D$4 -> 35000 | N31: =K31*$E$4 -> 0 | O31: 353450 | P31: =VLOOKUP(B31,'ASISTENCIA JULIO'!$B$4:$AP$128,41,FALSE) -> 19 | Q31: =(O31/$P$14)*P31 -> 268622
B32: 13743972-7 | E32: VIGENTE | F32: VEGA GONZALEZ PATRICIO COLLO | G32: RIGGER | H32: =MAX($H$11:$O$11) -> 698.9 | I32: {=_xlfn.IFS( $H$11=MAX($H$11,$J$11,$L$11,$N$11),$H$10, $J$11=MAX($H$11,$J$11,$L$11,$N$11),$J$10, $L$11=MAX($H$11,$J$11,$L$11,$N$11),$L$10, $N$11=MAX($H$11,$J$11,$L$11,$N$11),$N$10)} -> 648.9 | J32: {=_xlfn.IFS( $J$11=MAX($J$11,$N$11),$K$10, $N$11=MAX($J$11,$N$11),$O$10)} -> 50 | K32: 0 | L32: =I32*$C$4 -> 324450 | M32: =J32*$D$4 -> 35000 | N32: =K32*$E$4 -> 0 | O32: 353450 | P32: =VLOOKUP(B32,'ASISTENCIA JULIO'!$B$4:$AP$128,41,FALSE) -> 10 | Q32: =(O32/$P$14)*P32 -> 141380
B41: TURNO B | I41: METROS | L41: VALOR EN PESO
B42: RUT | C42: FECHA INGRESO MV | D42: FECHA SALIDA | E42: VIGENCIA | F42: NOMBRE | G42: CARGO | H42: MEJOR MAQUINA | I42: 0-500 | J42: 501-1000 | K42: 1001-1500 | L42: VALOR 0-500 | M42: VALOR 501-1000 | N42: VALOR 1001-1500 | O42: TOTAL | P42: ASISTENCIA | Q42: TOTAL A PAGO | R42: OBSERVACION | S42: CONTRATO HASTA
B43: 16892086-5 | C43: 45627 | E43: VIGENTE | F43: LISAMBARTH CARABANTES MANUEL ANDRES | G43: ADMINISTRATIVA/O DE FAENA | H43: =MAX($H$11:$O$11) -> 698.9 | I43: {=_xlfn.IFS( $H$11=MAX($H$11,$J$11,$L$11,$N$11),$H$10, $J$11=MAX($H$11,$J$11,$L$11,$N$11),$J$10, $L$11=MAX($H$11,$J$11,$L$11,$N$11),$L$10, $N$11=MAX($H$11,$J$11,$L$11,$N$11),$N$10)} -> 648.9 | J43: {=_xlfn.IFS( $H$11=MAX($H$11,$J$11,$L$11,$N$11),$I$10, $J$11=MAX($H$11,$J$11,$L$11,$N$11),$K$10, $L$11=MAX($H$11,$J$11,$L$11,$N$11),$M$10, $N$11=MAX($H$11,$J$11,$L$11,$N$11),$O$10)} -> 50 | K43: 0 | L43: =I43*$C$4 -> 324450 | M43: =J43*$D$4 -> 35000 | N43: =K43*$E$4 -> 0 | O43: 353450 | P43: =VLOOKUP(B43,'ASISTENCIA JULIO'!$B$4:$AP$128,41,FALSE) -> 12 | Q43: =(O43/$P$14)*P43 -> 169656
B44: 10726051-k | C44: 46114 | E44: VIGENTE | F44: SOTO FARIÑA JORGE IVAN | G44: ADMINISTRATIVA/O DE FAENA | H44: =MAX($H$11:$O$11) -> 698.9 | I44: {=_xlfn.IFS( $H$11=MAX($H$11,$J$11,$L$11,$N$11),$H$10, $J$11=MAX($H$11,$J$11,$L$11,$N$11),$J$10, $L$11=MAX($H$11,$J$11,$L$11,$N$11),$L$10, $N$11=MAX($H$11,$J$11,$L$11,$N$11),$N$10)} -> 648.9 | J44: {=_xlfn.IFS( $H$11=MAX($H$11,$J$11,$L$11,$N$11),$I$10, $J$11=MAX($H$11,$J$11,$L$11,$N$11),$K$10, $L$11=MAX($H$11,$J$11,$L$11,$N$11),$M$10, $N$11=MAX($H$11,$J$11,$L$11,$N$11),$O$10)} -> 50 | K44: 0 | L44: =I44*$C$4 -> 324450 | M44: =J44*$D$4 -> 35000 | N44: =K44*$E$4 -> 0 | O44: 353450 | P44: =VLOOKUP(B44,'ASISTENCIA JULIO'!$B$4:$AP$128,41,FALSE) -> 2 | Q44: =(O44/$P$14)*P44 -> 28276
B45: 19825638-2 | C45: 45636 | E45: VIGENTE | F45: SOTO FLORES JENNIFER ALEJANDRA | G45: BODEGUERA/O | H45: =MAX($H$11:$O$11) -> 698.9 | I45: {=_xlfn.IFS( $H$11=MAX($H$11,$J$11,$L$11,$N$11),$H$10, $J$11=MAX($H$11,$J$11,$L$11,$N$11),$J$10, $L$11=MAX($H$11,$J$11,$L$11,$N$11),$L$10, $N$11=MAX($H$11,$J$11,$L$11,$N$11),$N$10)} -> 648.9 | J45: {=_xlfn.IFS( $H$11=MAX($H$11,$J$11,$L$11,$N$11),$I$10, $J$11=MAX($H$11,$J$11,$L$11,$N$11),$K$10, $L$11=MAX($H$11,$J$11,$L$11,$N$11),$M$10, $N$11=MAX($H$11,$J$11,$L$11,$N$11),$O$10)} -> 50 | K45: 0 | L45: =I45*$C$4 -> 324450 | M45: =J45*$D$4 -> 35000 | N45: =K45*$E$4 -> 0 | O45: 353450 | P45: =VLOOKUP(B45,'ASISTENCIA JULIO'!$B$4:$AP$128,41,FALSE) -> 12 | Q45: =(O45/$P$14)*P45 -> 169656
B46: 18403993-1 | C46: 46176 | E46: VIGENTE | F46: CARO GALLARDO JOEL | G46: CHOFER | H46: =MAX($H$11:$O$11) -> 698.9 | I46: {=_xlfn.IFS( $H$11=MAX($H$11,$J$11,$L$11,$N$11),$H$10, $J$11=MAX($H$11,$J$11,$L$11,$N$11),$J$10, $L$11=MAX($H$11,$J$11,$L$11,$N$11),$L$10, $N$11=MAX($H$11,$J$11,$L$11,$N$11),$N$10)} -> 648.9 | J46: {=_xlfn.IFS( $H$11=MAX($H$11,$J$11,$L$11,$N$11),$I$10, $J$11=MAX($H$11,$J$11,$L$11,$N$11),$K$10, $L$11=MAX($H$11,$J$11,$L$11,$N$11),$M$10, $N$11=MAX($H$11,$J$11,$L$11,$N$11),$O$10)} -> 50 | K46: 0 | L46: =I46*$C$4 -> 324450 | M46: =J46*$D$4 -> 35000 | N46: =K46*$E$4 -> 0 | O46: 353450 | P46: 12 | Q46: =(O46/$P$14)*P46 -> 169656
B47: 12707776-2 | C47: 45836 | E47: VIGENTE | F47: GUTIERREZ FUENTES RICARDO DE LAS NIEVES | G47: CHOFER | H47: =MAX($H$11:$O$11) -> 698.9 | I47: {=_xlfn.IFS( $H$11=MAX($H$11,$J$11,$L$11,$N$11),$H$10, $J$11=MAX($H$11,$J$11,$L$11,$N$11),$J$10, $L$11=MAX($H$11,$J$11,$L$11,$N$11),$L$10, $N$11=MAX($H$11,$J$11,$L$11,$N$11),$N$10)} -> 648.9 | J47: {=_xlfn.IFS( $H$11=MAX($H$11,$J$11,$L$11,$N$11),$I$10, $J$11=MAX($H$11,$J$11,$L$11,$N$11),$K$10, $L$11=MAX($H$11,$J$11,$L$11,$N$11),$M$10, $N$11=MAX($H$11,$J$11,$L$11,$N$11),$O$10)} -> 50 | K47: 0 | L47: =I47*$C$4 -> 324450 | M47: =J47*$D$4 -> 35000 | N47: =K47*$E$4 -> 0 | O47: 353450 | P47: =VLOOKUP(B47,'ASISTENCIA JULIO'!$B$4:$AP$128,41,FALSE) -> 2 | Q47: =(O47/$P$14)*P47 -> 28276
B48: 16581882-2 | C48: 46063 | E48: VIGENTE | F48: JUAREZ MORALES MIGUEL SEBASTIAN | G48: CHOFER | H48: =MAX($H$11:$O$11) -> 698.9 | I48: {=_xlfn.IFS( $H$11=MAX($H$11,$J$11,$L$11,$N$11),$H$10, $J$11=MAX($H$11,$J$11,$L$11,$N$11),$J$10, $L$11=MAX($H$11,$J$11,$L$11,$N$11),$L$10, $N$11=MAX($H$11,$J$11,$L$11,$N$11),$N$10)} -> 648.9 | J48: {=_xlfn.IFS( $H$11=MAX($H$11,$J$11,$L$11,$N$11),$I$10, $J$11=MAX($H$11,$J$11,$L$11,$N$11),$K$10, $L$11=MAX($H$11,$J$11,$L$11,$N$11),$M$10, $N$11=MAX($H$11,$J$11,$L$11,$N$11),$O$10)} -> 50 | K48: 0 | L48: =I48*$C$4 -> 324450 | M48: =J48*$D$4 -> 35000 | N48: =K48*$E$4 -> 0 | O48: 353450 | P48: =VLOOKUP(B48,'ASISTENCIA JULIO'!$B$4:$AP$128,41,FALSE) -> 2 | Q48: =(O48/$P$14)*P48 -> 28276
B49: 13223287-3 | C49: 45716 | E49: VIGENTE | F49: LOPEZ BARRIOS ESTEBAN DAGOBERTO | G49: CHOFER | H49: =MAX($H$11:$O$11) -> 698.9 | I49: {=_xlfn.IFS( $H$11=MAX($H$11,$J$11,$L$11,$N$11),$H$10, $J$11=MAX($H$11,$J$11,$L$11,$N$11),$J$10, $L$11=MAX($H$11,$J$11,$L$11,$N$11),$L$10, $N$11=MAX($H$11,$J$11,$L$11,$N$11),$N$10)} -> 648.9 | J49: {=_xlfn.IFS( $H$11=MAX($H$11,$J$11,$L$11,$N$11),$I$10, $J$11=MAX($H$11,$J$11,$L$11,$N$11),$K$10, $L$11=MAX($H$11,$J$11,$L$11,$N$11),$M$10, $N$11=MAX($H$11,$J$11,$L$11,$N$11),$O$10)} -> 50 | K49: 0 | L49: =I49*$C$4 -> 324450 | M49: =J49*$D$4 -> 35000 | N49: =K49*$E$4 -> 0 | O49: 353450 | P49: =VLOOKUP(B49,'ASISTENCIA JULIO'!$B$4:$AP$128,41,FALSE) -> 12 | Q49: =(O49/$P$14)*P49 -> 169656
B50: 18575188-0 | C50: 45636 | E50: VIGENTE | F50: LOPEZ GARCIA IVAN ESTEBAN | G50: CHOFER | H50: =MAX($H$11:$O$11) -> 698.9 | I50: {=_xlfn.IFS( $H$11=MAX($H$11,$J$11,$L$11,$N$11),$H$10, $J$11=MAX($H$11,$J$11,$L$11,$N$11),$J$10, $L$11=MAX($H$11,$J$11,$L$11,$N$11),$L$10, $N$11=MAX($H$11,$J$11,$L$11,$N$11),$N$10)} -> 648.9 | J50: {=_xlfn.IFS( $H$11=MAX($H$11,$J$11,$L$11,$N$11),$I$10, $J$11=MAX($H$11,$J$11,$L$11,$N$11),$K$10, $L$11=MAX($H$11,$J$11,$L$11,$N$11),$M$10, $N$11=MAX($H$11,$J$11,$L$11,$N$11),$O$10)} -> 50 | K50: 0 | L50: =I50*$C$4 -> 324450 | M50: =J50*$D$4 -> 35000 | N50: =K50*$E$4 -> 0 | O50: 353450 | P50: =VLOOKUP(B50,'ASISTENCIA JULIO'!$B$4:$AP$128,41,FALSE) -> 12 | Q50: =(O50/$P$14)*P50 -> 169656
B51: 13904830-K | C51: 45719 | E51: VIGENTE | F51: NUÑEZ PENDOLA HUGO ITALO | G51: CHOFER | H51: =MAX($H$11:$O$11) -> 698.9 | I51: {=_xlfn.IFS( $H$11=MAX($H$11,$J$11,$L$11,$N$11),$H$10, $J$11=MAX($H$11,$J$11,$L$11,$N$11),$J$10, $L$11=MAX($H$11,$J$11,$L$11,$N$11),$L$10, $N$11=MAX($H$11,$J$11,$L$11,$N$11),$N$10)} -> 648.9 | J51: {=_xlfn.IFS( $H$11=MAX($H$11,$J$11,$L$11,$N$11),$I$10, $J$11=MAX($H$11,$J$11,$L$11,$N$11),$K$10, $L$11=MAX($H$11,$J$11,$L$11,$N$11),$M$10, $N$11=MAX($H$11,$J$11,$L$11,$N$11),$O$10)} -> 50 | K51: 0 | L51: =I51*$C$4 -> 324450 | M51: =J51*$D$4 -> 35000 | N51: =K51*$E$4 -> 0 | O51: 353450 | P51: =VLOOKUP(B51,'ASISTENCIA JULIO'!$B$4:$AP$128,41,FALSE) -> 12 | Q51: =(O51/$P$14)*P51 -> 169656
...

Sheet SUP- PREV
H1: METROS POR MÁQUINA DDH | P1: METROS RC
C2: VALOR METRO 0-500 | D2: VALOR METRO 501-1000 | E2: VALOR METRO 1001- | J2: 740/7 | N2: 740/14 | P2: 1200-01
J3: 0-500 | K3: 501-1000 | N3: 0-500 | O3: 501-1000 | P3: 0-600
B4: AYUDANTE | C4: 500 | D4: 700 | E4: 900 | G4: TURNO A | J4: ='740-7'!$AN$9 -> 298.3 | K4: ='740-7'!$AO$9 -> 0 | N4: ='740-14 '!$AO$9 -> 411.75 | O4: ='740-14 '!$AP$9 -> 43.75 | P4: ='1200-01'!$AK$9 -> 856
B5: PERFORISTA | C5: 750 | D5: 900 | E5: 1200 | J5: =J4+K4 -> 298.3 | N5: =N4+O4 -> 455.5
G6: TURNO B | J6: ='740-7'!$AP$9 -> 168.2 | K6: ='740-7'!$AQ$9 -> 0 | N6: ='740-14 '!$AQ$9 -> 237.15 | O6: ='740-14 '!$AR$9 -> 6.25 | P6: ='1200-01'!$AL$9 -> 336
C7: 0-600 RC | J7: =J6+K6 -> 168.2 | N7: =N6+O6 -> 243.4
B9: AYUDANTE | C9: 200 | G9: TOTAL MES | J9: 0-500 | K9: 501-1000 | N9: 0-500 | O9: 501-1000 | P9: 0-600
B10: PERFORISTA | C10: 300 | J10: =J4+J6 -> 466.5 | K10: =K4+K6 -> 0 | N10: =N4+N6 -> 648.9 | O10: =O4+O6 -> 50
J11: =J10+K10 -> 466.5 | N11: =N10+O10 -> 698.9 | P11: =P4+P6 -> 1192
B14: 4X3 Y TRASLAPADOS | I14: METROS | L14: VALOR EN PESO | P14: 25
B15: RUT | C15: FECHA INGRESO MV | D15: FECHA SALIDA | E15: VIGENCIA | F15: NOMBRE | G15: CARGO | H15: MEJOR MAQUINA | I15: 0-500 | J15: 501-1000 | K15: 1001-1500 | L15: VALOR 0-500 | M15: VALOR 501-1000 | N15: VALOR 1001-1500 | O15: TOTAL | P15: ASISTENCIA | Q15: TOTAL A PAGO | R15: OBSERVACION | S15: CONTRATO HASTA
B16: 12419789-9 | C16: =VLOOKUP(B16,[1]ASISTENCIA!$B$4:$U$170,20,FALSE) -> 45964 | E16: VIGENTE | F16: NUÑEZ GONZALEZ ROBERTO CARLOS | G16: ADC | H16: =MAX($H$11:$O$11) -> 698.9 | I16: {=_xlfn.IFS($J$11=MAX($J$11,$N$11),$J$10,$N$11=MAX($J$11,$N$11),$N$10)} -> 648.9 | J16: {=_xlfn.IFS( $J$11=MAX($J$11,$N$11),$K$10, $N$11=MAX($J$11,$N$11),$O$10)} -> 50 | K16: 0 | L16: =I16*$C$5 -> 486675 | M16: =J16*$D$5 -> 45000 | N16: =K16*$E$5 -> 0 | O16: 522675 | P16: =VLOOKUP(B16,'ASISTENCIA JULIO'!$B$4:$AP$128,41,FALSE) -> 17 | Q16: =(O16/$P$14)*P16 -> 355419 | R16: 4X3
B17: 122192016 | C17: 46139 | E17: VIGENTE | F17: ALFARO VEAS RODRIGO FERNANDO | G17: LIDER HSEC | H17: =MAX($H$11:$O$11) -> 698.9 | I17: {=_xlfn.IFS($J$11=MAX($J$11,$N$11),$J$10,$N$11=MAX($J$11,$N$11),$N$10)} -> 648.9 | J17: {=_xlfn.IFS( $J$11=MAX($J$11,$N$11),$K$10, $N$11=MAX($J$11,$N$11),$O$10)} -> 50 | K17: 0 | L17: =I17*$C$5 -> 486675 | M17: =J17*$D$5 -> 45000 | N17: =K17*$E$5 -> 0 | O17: 522675 | P17: =VLOOKUP(B17,'ASISTENCIA JULIO'!$B$4:$AP$128,41,FALSE) -> 17 | Q17: =(O17/$P$14)*P17 -> 355419 | R17: 4X3
B18: 13011075-4 | C18: =VLOOKUP(B18,[1]ASISTENCIA!$B$4:$U$170,20,FALSE) -> 45627 | E18: VIGENTE | F18: BORQUEZ CARVAJAL IBAR ALEXIS | G18: JEFE DE FAENA | H18: =MAX($H$11:$O$11) -> 698.9 | I18: {=_xlfn.IFS($J$11=MAX($J$11,$N$11),$J$10,$N$11=MAX($J$11,$N$11),$N$10)} -> 648.9 | J18: {=_xlfn.IFS( $J$11=MAX($J$11,$N$11),$K$10, $N$11=MAX($J$11,$N$11),$O$10)} -> 50 | K18: 0 | L18: =I18*$C$5 -> 486675 | M18: =J18*$D$5 -> 45000 | N18: =K18*$E$5 -> 0 | O18: 522675 | P18: =VLOOKUP(B18,'ASISTENCIA JULIO'!$B$4:$AP$128,41,FALSE) -> 14 | Q18: =(O18/$P$14)*P18 -> 292698 | R18: 10X10 TRASLAPADO
B19: 16463792-1 | C19: =VLOOKUP(B19,[1]ASISTENCIA!$B$4:$U$170,20,FALSE) -> 45638 | E19: VIGENTE | F19: ROJAS MARTINEZ FRANCISCO JAVIER | G19: JEFE DE FAENA | H19: =MAX($H$11:$O$11) -> 698.9 | I19: {=_xlfn.IFS($J$11=MAX($J$11,$N$11),$J$10,$N$11=MAX($J$11,$N$11),$N$10)} -> 648.9 | J19: {=_xlfn.IFS( $J$11=MAX($J$11,$N$11),$K$10, $N$11=MAX($J$11,$N$11),$O$10)} -> 50 | K19: 0 | L19: =I19*$C$5 -> 486675 | M19: =J19*$D$5 -> 45000 | N19: =K19*$E$5 -> 0 | O19: 522675 | P19: =VLOOKUP(B19,'ASISTENCIA JULIO'!$B$4:$AP$128,41,FALSE) -> 17 | Q19: =(O19/$P$14)*P19 -> 355419 | R19: 10X10 TRASLAPADO
B20: 17169171-0 | C20: 45746 | E20: VIGENTE | F20: LOPEZ OLAVE LUIS GERARDO | G20: LIDER MECÁNICO | H20: =MAX($H$11:$O$11) -> 698.9 | I20: {=_xlfn.IFS($J$11=MAX($J$11,$N$11),$J$10,$N$11=MAX($J$11,$N$11),$N$10)} -> 648.9 | J20: {=_xlfn.IFS( $J$11=MAX($J$11,$N$11),$K$10, $N$11=MAX($J$11,$N$11),$O$10)} -> 50 | K20: 0 | L20: =I20*$C$5 -> 486675 | M20: =J20*$D$5 -> 45000 | N20: =K20*$E$5 -> 0 | O20: 522675 | P20: =VLOOKUP(B20,'ASISTENCIA JULIO'!$B$4:$AP$128,41,FALSE) -> 14 | Q20: =(O20/$P$14)*P20 -> 292698 | R20: 10X10 TRASLAPADO
B21: 19948246-7 | C21: 45646 | E21: VIGENTE | F21: RAMIREZ BARRAZA MARCELO GIOVANNI | G21: LIDER MECÁNICO | H21: =MAX($H$11:$O$11) -> 698.9 | I21: {=_xlfn.IFS($J$11=MAX($J$11,$N$11),$J$10,$N$11=MAX($J$11,$N$11),$N$10)} -> 648.9 | J21: {=_xlfn.IFS( $J$11=MAX($J$11,$N$11),$K$10, $N$11=MAX($J$11,$N$11),$O$10)} -> 50 | K21: 0 | L21: =I21*$C$5 -> 486675 | M21: =J21*$D$5 -> 45000 | N21: =K21*$E$5 -> 0 | O21: 522675 | P21: =VLOOKUP(B21,'ASISTENCIA JULIO'!$B$4:$AP$128,41,FALSE) -> 17 | Q21: =(O21/$P$14)*P21 -> 355419 | R21: 10X10 TRASLAPADO
B22: 17293946-5 | E22: VIGENTE | F22: GONZALEZ JERALDO HAMIR ALONSO | G22: INSTRUCTOR | H22: =MAX($H$11:$O$11) -> 698.9 | I22: {=_xlfn.IFS($J$11=MAX($J$11,$N$11),$J$10,$N$11=MAX($J$11,$N$11),$N$10)} -> 648.9 | J22: {=_xlfn.IFS( $J$11=MAX($J$11,$N$11),$K$10, $N$11=MAX($J$11,$N$11),$O$10)} -> 50 | K22: 0 | L22: =I22*$C$5 -> 486675 | M22: =J22*$D$5 -> 45000 | N22: =K22*$E$5 -> 0 | O22: 522675 | P22: =VLOOKUP(B22,'ASISTENCIA JULIO'!$B$4:$AP$128,41,FALSE) -> 7 | Q22: =(O22/$P$14)*P22 -> 146349 | R22: 10X10 TRASLAPADO + licencia médica
B23: TURNO A | I23: METROS | L23: VALOR EN PESO
B24: RUT | C24: FECHA INGRESO MV | D24: FECHA SALIDA | E24: VIGENCIA | F24: NOMBRE | G24: CARGO | H24: MEJOR MAQUINA | I24: 0-500 | J24: 501-1000 | K24: 1001-1500 | L24: VALOR 0-500 | M24: VALOR 501-1000 | N24: VALOR 1001-1500 | O24: TOTAL | P24: ASISTENCIA | Q24: TOTAL A PAGO | R24: OBSERVACION | S24: CONTRATO HASTA
B25: 16442692-0 | C25: =VLOOKUP(B25,[1]ASISTENCIA!$B$4:$U$170,20,FALSE) -> 45826 | E25: VIGENTE | F25: AGUIRRE CASTILLO ANITA FERNANDA | G25: PREVENCIONISTA | H25: =MAX($H$11:$O$11) -> 698.9 | I25: {=_xlfn.IFS($J$11=MAX($J$11,$N$11),$J$10,$N$11=MAX($J$11,$N$11),$N$10)} -> 648.9 | J25: {=_xlfn.IFS( $J$11=MAX($J$11,$N$11),$K$10, $N$11=MAX($J$11,$N$11),$O$10)} -> 50 | K25: 0 | L25: =I25*$C$5 -> 486675 | M25: =J25*$D$5 -> 45000 | N25: =K25*$E$5 -> 0 | O25: 522675 | P25: =VLOOKUP(B25,'ASISTENCIA JULIO'!$B$4:$AP$128,41,FALSE) -> 19 | Q25: =(O25/$P$14)*P25 -> 397233
B26: 17979787-9 | C26: =VLOOKUP(B26,[1]ASISTENCIA!$B$4:$U$170,20,FALSE) -> 45628 | E26: VIGENTE | F26: BRICEÑO HONORES JOHN ALEXIS | G26: PREVENCIONISTA | H26: =MAX($H$11:$O$11) -> 698.9 | I26: {=_xlfn.IFS($J$11=MAX($J$11,$N$11),$J$10,$N$11=MAX($J$11,$N$11),$N$10)} -> 648.9 | J26: {=_xlfn.IFS( $J$11=MAX($J$11,$N$11),$K$10, $N$11=MAX($J$11,$N$11),$O$10)} -> 50 | K26: 0 | L26: =I26*$C$5 -> 486675 | M26: =J26*$D$5 -> 45000 | N26: =K26*$E$5 -> 0 | O26: 522675 | P26: =VLOOKUP(B26,'ASISTENCIA JULIO'!$B$4:$AP$128,41,FALSE) -> 0 | Q26: =(O26/$P$14)*P26 -> 0 | R26: Licencia médica, luego traslado
B27: 10792747-6 | C27: =VLOOKUP(B27,[1]ASISTENCIA!$B$4:$U$170,20,FALSE) -> 45936 | E27: VIGENTE | F27: PASTEN GUERRERO GUMERCINDO DEL ROSARIO | G27: SUPERVISOR DE OPERACIONES | H27: =MAX($H$11:$O$11) -> 698.9 | I27: {=_xlfn.IFS($J$11=MAX($J$11,$N$11),$J$10,$N$11=MAX($J$11,$N$11),$N$10)} -> 648.9 | J27: {=_xlfn.IFS( $J$11=MAX($J$11,$N$11),$K$10, $N$11=MAX($J$11,$N$11),$O$10)} -> 50 | K27: 0 | L27: =I27*$C$5 -> 486675 | M27: =J27*$D$5 -> 45000 | N27: =K27*$E$5 -> 0 | O27: 522675 | P27: =VLOOKUP(B27,'ASISTENCIA JULIO'!$B$4:$AP$128,41,FALSE) -> 19 | Q27: =(O27/$P$14)*P27 -> 397233
B28: 14903561-3 | C28: =VLOOKUP(B28,[1]ASISTENCIA!$B$4:$U$170,20,FALSE) -> 45846 | E28: VIGENTE | F28: VALENCIA CAMPOS ANDRES ALEJANDRO | G28: SUPERVISOR DE OPERACIONES | H28: =MAX($H$11:$O$11) -> 698.9 | I28: {=_xlfn.IFS($J$11=MAX($J$11,$N$11),$J$10,$N$11=MAX($J$11,$N$11),$N$10)} -> 648.9 | J28: {=_xlfn.IFS( $J$11=MAX($J$11,$N$11),$K$10, $N$11=MAX($J$11,$N$11),$O$10)} -> 50 | K28: 0 | L28: =I28*$C$5 -> 486675 | M28: =J28*$D$5 -> 45000 | N28: =K28*$E$5 -> 0 | O28: 522675 | P28: =VLOOKUP(B28,'ASISTENCIA JULIO'!$B$4:$AP$128,41,FALSE) -> 19 | Q28: =(O28/$P$14)*P28 -> 397233
B30: TURNO B | I30: METROS | L30: VALOR EN PESO
