Workbook

Sheet Lista desplegable
B1: RUT | C1: NOMBRES Y APELLIDOS | D1: PUESTO | F1: MAQUINAS | H1: TIPOS DE PERFORACIÓN | J1: TRAMOS | L1: WORKERA | N1: ASISTENCIA
B2: 19353203-9 | C2: ABRAHAM NATANAEL MORALES ARANEDA | D2: ASISTENTE LOGISTICO | F2: EDM47K-2 | H2: PQ | J2: 0-500 | L2: SI | N2: PRESENTE
B3: 11345634-5 | C3: ALBERTO PATRICIO CALDERON CALDERON | D3: SUPERVISOR DE OPERACIONES | F3: EDM47K-1 | H3: HQ | J3: 500-1000 | L3: NO | N3: DESCANSO
B4: 16250239-5 | C4: ALBERTO SEGUNDO CALLPA NUÑEZ | D4: AYUDANTE DE PERFORISTA | F4: EDMGH40K | H4: NQ | J4: 1000-1500 | N4: AUSENTE
B5: 29067753-K | C5: ALDWIN CALAMBA REBUYA | D5: CONTADOR | F5: 200-11 | H5: NAVI | J5: 1500-2000 | N5: OBSERVACIÓN
B6: 13412582-9 | C6: ALEJANDRO ALBERTO CAMPILLAY RUIZ | D6: MECANICO | F6: 200-13 | H6: DEVICO | J6: 2000-2500
B7: 11819748-8 | C7: ALEJANDRO ANTONIO ZEPEDA CHACC | D7: SUPERVISOR DE OPERACIONES | F7: 200-12 | H7: AIRE REVERSO | J7: 0-600
B8: 12951196-6 | C8: ALEJANDRO MIGUEL APABLAZA GUZMAN | D8: SUPERVISOR DE OPERACIONES | F8: 200-7 | J8: 0-200
B9: 14313865-8 | C9: ALEX EDUARDO TABILO RIVERA | D9: PERFORISTA | F9: 650-14 | J9: 200-400
B10: 17364005-6 | C10: ALEXIS RUBEN ARAYA JULIO | D10: AYUDANTE DE PERFORISTA | F10: 740-3 | J10: 400-600
B11: 12732008-K | C11: ALEX ROBINSON VEJAR LOPEZ | D11: AYUDANTE DE PERFORISTA | F11: 740-5
B12: 18919440-4 | C12: ALISSON AYLEEN VILLAGRA CABALLERO | D12: CHOFER | F12: 740-6
B13: 22565722-K | C13: ALONSO EDUARDO SANCHEZ PINOCHET | D13: AYUDANTE MECANICO | F13: 740-7
B14: 44592663-9 | C14: ALTANKHUNDAGA SUGLEGMAA . | D14: PERFORISTA | F14: 740-9
B15: 12842966-2 | C15: ALVARO ANDRES CONTRERAS MUNIZAGA | D15: SOLDADOR | F15: 740-10
B16: 20168605-9 | C16: ALVARO IGNACIO GODOY BRUNA | D16: PERFORISTA | F16: 740-11
B17: 14903561-3 | C17: ANDRES ALEJANDRO VALENCIA CAMPOS | D17: SUPERVISOR DE OPERACIONES | F17: 740-14
B18: 18287449-3 | C18: ANDRES MISAEL CARVAJAL CAMUS | D18: CHOFER | F18: 1200-1
B19: 19668391-7 | C19: ANDRES ORLANDO VELIZ OLIVARES | D19: ASISTENTE DE RECURSOS HUMANOS | F19: 1200-2
B20: 15885524-0 | C20: ANDRES SEBASTIAN CASTILLO ENCINA | D20: CHOFER | F20: LM110-6
B21: 44632507-8 | C21: ANDREW JAMES WILSON . | D21: PERFORISTA
B22: 20037472-K | C22: ANGELO GIOVANNI BIZAMA ORELLANA | D22: AYUDANTE DE PERFORISTA
B23: 19662155-5 | C23: ANGELO IGNACIO GOMEZ PIZARRO | D23: AYUDANTE DE PERFORISTA
B24: 17998731-7 | C24: ANGELO PATRICIO RIVERA HERRERA | D24: MECANICO
B25: 13973699-0 | C25: ANGELO SEBASTIAN ROJAS GARCIA | D25: GERENTE DE HSEC
B26: 16442692-0 | C26: ANITA FERNANDA AGUIRRE CASTILLO | D26: PREVENCIONISTA DE RIESGOS
B27: 17453602-3 | C27: ANTONIO ALEJANDRO SEPULVEDA QUIROZ | D27: AYUDANTE DE PERFORISTA
B28: 44601894-9 | C28: ANTONIO HIPOLITO OTINIANO RUIZ | D28: PERFORISTA
B29: 15613806-1 | C29: ARIEL ANDRES SILVA RIQUELME | D29: SUPERVISOR DE OPERACIONES
B30: 14156135-9 | C30: ARIEL BENEDICTO LISBOA CASTRO | D30: CHOFER
B31: 28683244-K | C31: ARIUNBOLD TSOGKHORKHOI . | D31: PERFORISTA
B32: 17277089-4 | C32: ASTRY ROCIO TAPIA ALLENDES | D32: SUPERINTENDENTE DE RECURSOS HUMANOS
... B436: 20804293-9 | C436: YULISA NATALY DIAZ TORO | D436: ADMINISTRATIVO DE FAENA

Sheet 01-09
G2: DIA
D3: PROYECTO: | E3: CERRO BAYO / CHILE CHICO | G3: 46031
C6: TURNO DIA - B
B7: N° | C7: RUT | D7: NOMBRES Y APELLIDOS | E7: CARGO | F7: MAQUINA | G7: DIAMETRO | H7: ESCALA | I7: METROS | J7: ASISTENCIA | K7: WORKERA ENTRADA | L7: WORKERA SALIDA | M7: OBSERVACIONES
B8: 1 | C8: 44632507-8 | D8: =IFERROR(VLOOKUP(C8,'Lista desplegable'!B$1:C$436,2,FALSE),"") -> ANDREW JAMES WILSON . | E8: =IFERROR(VLOOKUP(D8,'Lista desplegable'!C$1:D$436,2,FALSE),"") -> PERFORISTA | F8: 200-13 | G8: HQ | H8: 0-200 | I8: 51,00 | J8: PRESENTE | M8: NO APLICA FIRMA, EXPATRIADO
B9: 2 | C9: 28935989-3 | D9: =IFERROR(VLOOKUP(C9,'Lista desplegable'!B$1:C$436,2,FALSE),"") -> STEWART PHILLIP WHITEHURST MEJIA | E9: =IFERROR(VLOOKUP(D9,'Lista desplegable'!C$1:D$436,2,FALSE),"") -> PERFORISTA | F9: 200-13 | G9: HQ | H9: 0-200 | I9: 51,00 | J9: PRESENTE | M9: NO APLICA FIRMA, EXPATRIADO
B10: 3 | C10: 13745724-5 | D10: =IFERROR(VLOOKUP(C10,'Lista desplegable'!B$1:C$436,2,FALSE),"") -> JOSE MANUEL CASTILLO GARCIA | E10: =IFERROR(VLOOKUP(D10,'Lista desplegable'!C$1:D$436,2,FALSE),"") -> INSTRUCTOR DE OPERACIONES | F10: 200-13 | G10: HQ | H10: 0-200 | I10: 51,00 | J10: PRESENTE | K10: SI | L10: SI
B11: 4 | C11: 18490734-8 | D11: =IFERROR(VLOOKUP(C11,'Lista desplegable'!B$1:C$436,2,FALSE),"") -> SIMONNE DE LA PAZ REYES BATLLE | E11: =IFERROR(VLOOKUP(D11,'Lista desplegable'!C$1:D$436,2,FALSE),"") -> ADMINISTRATIVO DE FAENA | F11: 200-13 | G11: HQ | H11: 0-200 | I11: 51,00 | J11: PRESENTE | K11: SI | L11: SI
B12: 5 | C12: 16892085-7 | D12: =IFERROR(VLOOKUP(C12,'Lista desplegable'!B$1:C$436,2,FALSE),"") -> MANUEL ALEJANDRO LISAMBARTH CARABANTES | E12: =IFERROR(VLOOKUP(D12,'Lista desplegable'!C$1:D$436,2,FALSE),"") -> ADMINISTRATIVO DE FAENA | F12: 200-13 | G12: HQ | H12: 0-200 | I12: 51,00 | J12: PRESENTE | K12: SI | L12: SI
B13: 6 | C13: 17697158-4 | D13: =IFERROR(VLOOKUP(C13,'Lista desplegable'!B$1:C$436,2,FALSE),"") -> RODRIGO ANDRES DIAZ INOSTROZA | E13: =IFERROR(VLOOKUP(D13,'Lista desplegable'!C$1:D$436,2,FALSE),"") -> BODEGUERO | F13: 200-13 | G13: HQ | H13: 0-200 | I13: 51,00 | J13: PRESENTE | K13: SI | L13: SI
B14: 7 | C14: 20456853-7 | D14: =IFERROR(VLOOKUP(C14,'Lista desplegable'!B$1:C$436,2,FALSE),"") -> CHRISTIAN DARIEM PIZARRO MUÑOZ | E14: =IFERROR(VLOOKUP(D14,'Lista desplegable'!C$1:D$436,2,FALSE),"") -> SOLDADOR | F14: 200-13 | G14: HQ | H14: 0-200 | I14: 51,00 | J14: PRESENTE | K14: SI | L14: SI
B15: 8 | C15: 17169171-0 | D15: =IFERROR(VLOOKUP(C15,'Lista desplegable'!B$1:C$436,2,FALSE),"") -> LUIS GERARDO LOPEZ OLAVE | E15: =IFERROR(VLOOKUP(D15,'Lista desplegable'!C$1:D$436,2,FALSE),"") -> MECANICO | F15: 200-13 | G15: HQ | H15: 0-200 | I15: 51,00 | J15: PRESENTE | K15: SI | L15: SI
B16: 9 | C16: 19506189-0 | D16: =IFERROR(VLOOKUP(C16,'Lista desplegable'!B$1:C$436,2,FALSE),"") -> DIEGO NICOLAS GONZALEZ OLIVARES | E16: =IFERROR(VLOOKUP(D16,'Lista desplegable'!C$1:D$436,2,FALSE),"") -> MECANICO | F16: 200-13 | G16: HQ | H16: 0-200 | I16: 51,00 | J16: PRESENTE | K16: SI | L16: SI
B17: 10 | C17: 19518296-5 | D17: =IFERROR(VLOOKUP(C17,'Lista desplegable'!B$1:C$436,2,FALSE),"") -> JORGE ANDRES LICANQUEO PEREZ | E17: =IFERROR(VLOOKUP(D17,'Lista desplegable'!C$1:D$436,2,FALSE),"") -> MECANICO | F17: 200-13 | G17: HQ | H17: 0-200 | I17: 51,00 | J17: PRESENTE | K17: SI | L17: SI
B18: 11 | C18: 16981319-1 | D18: =IFERROR(VLOOKUP(C18,'Lista desplegable'!B$1:C$436,2,FALSE),"") -> MARCOS ANTONIO ALDEA BEROIZA | E18: =IFERROR(VLOOKUP(D18,'Lista desplegable'!C$1:D$436,2,FALSE),"") -> CHOFER | F18: 200-13 | G18: HQ | H18: 0-200 | I18: 51,00 | J18: PRESENTE | K18: SI | L18: SI
B19: 12 | C19: 14400090-0 | D19: =IFERROR(VLOOKUP(C19,'Lista desplegable'!B$1:C$436,2,FALSE),"") -> CARLOS ALBERTO RAMOS VELASQUEZ | E19: =IFERROR(VLOOKUP(D19,'Lista desplegable'!C$1:D$436,2,FALSE),"") -> SUPERVISOR DE OPERACIONES | F19: 200-13 | G19: HQ | H19: 0-200 | I19: 51,00 | J19: PRESENTE | K19: SI | L19: SI
B20: 13 | C20: 15196627-6 | D20: =IFERROR(VLOOKUP(C20,'Lista desplegable'!B$1:C$436,2,FALSE),"") -> NELSON PATRICIO FLORES SANHUEZA | E20: =IFERROR(VLOOKUP(D20,'Lista desplegable'!C$1:D$436,2,FALSE),"") -> PREVENCIONISTA DE RIESGOS | F20: 200-13 | G20: HQ | H20: 0-200 | I20: 51,00 | J20: PRESENTE | K20: SI | L20: SI
B21: 14 | C21: 12218170-7 | D21: =IFERROR(VLOOKUP(C21,'Lista desplegable'!B$1:C$436,2,FALSE),"") -> EDUARDO ANTONIO CASTILLO VALENZUELA | E21: =IFERROR(VLOOKUP(D21,'Lista desplegable'!C$1:D$436,2,FALSE),"") -> PERFORISTA | F21: 200-11 | G21: HQ | H21: 0-200 | I21: 42,00 | J21: PRESENTE | K21: SI | L21: SI
... B29: 22 | C29: 44601894-9 | D29: =IFERROR(VLOOKUP(C29,'Lista desplegable'!B$1:C$436,2,FALSE),"") -> ANTONIO HIPOLITO OTINIANO RUIZ | E29: =IFERROR(VLOOKUP(D29,'Lista desplegable'!C$1:D$436,2,FALSE),"") -> PERFORISTA | F29: 200-11 | G29: HQ | H29: 0-200 | I29: 42,00 | J29: PRESENTE | K29: SI | L29: SI
B30: 23 | D30: =IFERROR(VLOOKUP(C30,'Lista desplegable'!B$1:C$436,2,FALSE),"") | E30: =IFERROR(VLOOKUP(D30,'Lista desplegable'!C$1:D$436,2,FALSE),"")
B31: 24 | D31: =IFERROR(VLOOKUP(C31,'Lista desplegable'!B$1:C$436,2,FALSE),"") | E31: =IFERROR(VLOOKUP(D31,'Lista desplegable'!C$1:D$436,2,FALSE),"")
B32: 25 | D32: =IFERROR(VLOOKUP(C32,'Lista desplegable'!B$1:C$436,2,FALSE),"") | E32: =IFERROR(VLOOKUP(D32,'Lista desplegable'!C$1:D$436,2,FALSE),"")
B33: 26 | D33: =IFERROR(VLOOKUP(C33,'Lista desplegable'!B$1:C$436,2,FALSE),"") | E33: =IFERROR(VLOOKUP(D33,'Lista desplegable'!C$1:D$436,2,FALSE),"")
B34: 27 | D34: =IFERROR(VLOOKUP(C34,'Lista desplegable'!B$1:C$436,2,FALSE),"") | E34: =IFERROR(VLOOKUP(D34,'Lista desplegable'!C$1:D$436,2,FALSE),"")
B35: 28 | D35: =IFERROR(VLOOKUP(C35,'Lista desplegable'!B$1:C$436,2,FALSE),"") | E35: =IFERROR(VLOOKUP(D35,'Lista desplegable'!C$1:D$436,2,FALSE),"")
B36: 29 | D36: =IFERROR(VLOOKUP(C36,'Lista desplegable'!B$1:C$436,2,FALSE),"") | E36: =IFERROR(VLOOKUP(D36,'Lista desplegable'!C$1:D$436,2,FALSE),"")
B37: 30 | D37: =IFERROR(VLOOKUP(C37,'Lista desplegable'!B$1:C$436,2,FALSE),"") | E37: =IFERROR(VLOOKUP(D37,'Lista desplegable'!C$1:D$436,2,FALSE),"")
C40: TURNO NOCHE - B
B41: N° | C41: RUT | D41: NOMBRES Y APELLIDOS | E41: CARGO | F41: MAQUINA | G41: DIAMETRO | H41: ESCALA | I41: METROS | J41: ASISTENCIA | K41: WORKERA ENTRADA | L41: WORKERA SALIDA | M41: OBSERVACIONES
B42: 1 | C42: 18494463-4 | D42: =IFERROR(VLOOKUP(C42,'Lista desplegable'!B$1:C$436,2,FALSE),"") -> RAUL ESTEBAN HERNANDEZ PIZARRO | E42: =IFERROR(VLOOKUP(D42,'Lista desplegable'!C$1:D$436,2,FALSE),"") -> PREVENCIONISTA DE RIESGOS | F42: 200-13 | G42: HQ | H42: 0-200 | I42: 51,00 | J42: PRESENTE | K42: SI | L42: SI
B43: 2 | C43: 44599978-4 | D43: =IFERROR(VLOOKUP(C43,'Lista desplegable'!B$1:C$436,2,FALSE),"") -> FRANCISCO PEDRO BORNAZ DELGADO | E43: =IFERROR(VLOOKUP(D43,'Lista desplegable'!C$1:D$436,2,FALSE),"") -> SUPERVISOR DE OPERACIONES | J43: DESCANSO
B44: 3 | C44: 17580584-2 | D44: =IFERROR(VLOOKUP(C44,'Lista desplegable'!B$1:C$436,2,FALSE),"") -> CAMILO FELIPE CRUZ MOLINA | E44: =IFERROR(VLOOKUP(D44,'Lista desplegable'!C$1:D$436,2,FALSE),"") -> SUPERVISOR DE OPERACIONES | F44: 200-13 | G44: HQ | H44: 0-200 | I44: 51,00 | J44: PRESENTE | K44: SI | L44: SI
B45: 4 | C45: 12707776-2 | D45: =IFERROR(VLOOKUP(C45,'Lista desplegable'!B$1:C$436,2,FALSE),"") -> RICARDO DE LAS NIEVES GUTIERREZ FUENTES | E45: =IFERROR(VLOOKUP(D45,'Lista desplegable'!C$1:D$436,2,FALSE),"") -> CHOFER | F45: 200-13 | G45: HQ | H45: 0-200 | I45: 51,00 | J45: PRESENTE | K45: SI | L45: SI
B46: 5 | C46: 26931695-0 | D46: =IFERROR(VLOOKUP(C46,'Lista desplegable'!B$1:C$436,2,FALSE),"") -> SEBASTIAN GONZALO ROJAS CLARO | E46: =IFERROR(VLOOKUP(D46,'Lista desplegable'!C$1:D$436,2,FALSE),"") -> MECANICO | F46: 200-13 | G46: HQ | H46: 0-200 | I46: 51,00 | J46: PRESENTE | K46: SI | L46: SI
B47: 6 | C47: 18665544-3 | D47: =IFERROR(VLOOKUP(C47,'Lista desplegable'!B$1:C$436,2,FALSE),"") -> DANIEL ANDRES VENEGAS CARRASCO | E47: =IFERROR(VLOOKUP(D47,'Lista desplegable'!C$1:D$436,2,FALSE),"") -> PERFORISTA | F47: 200-11 | G47: HQ | H47: 0-200 | I47: 37,80 | J47: PRESENTE | K47: SI | L47: SI
B48: 7 | C48: 19189343-3 | D48: =IFERROR(VLOOKUP(C48,'Lista desplegable'!B$1:C$436,2,FALSE),"") -> JOAQUIN IGNACIO TORO ALCAYAGA | E48: =IFERROR(VLOOKUP(D48,'Lista desplegable'!C$1:D$436,2,FALSE),"") -> AYUDANTE DE PERFORISTA | F48: 200-11 | G48: HQ | H48: 0-200 | I48: 37,80 | J48: PRESENTE | K48: SI | L48: SI
B49: 8 | C49: 12982701-7 | D49: =IFERROR(VLOOKUP(C49,'Lista desplegable'!B$1:C$436,2,FALSE),"") -> MARCO ANTONIO VELASQUEZ CIFUENTES | E49: =IFERROR(VLOOKUP(D49,'Lista desplegable'!C$1:D$436,2,FALSE),"") -> AYUDANTE DE PERFORISTA | F49: 200-11 | G49: HQ | H49: 0-200 | I49: 37,80 | J49: PRESENTE | K49: SI | L49: SI
B50: 9 | C50: 20168605-9 | D50: =IFERROR(VLOOKUP(C50,'Lista desplegable'!B$1:C$436,2,FALSE),"") -> ALVARO IGNACIO GODOY BRUNA | E50: =IFERROR(VLOOKUP(D50,'Lista desplegable'!C$1:D$436,2,FALSE),"") -> PERFORISTA | F50: 200-13 | G50: HQ | H50: 0-200 | I50: 51,00 | J50: PRESENTE | K50: SI | L50: SI
B51: 10 | C51: 15969452-6 | D51: =IFERROR(VLOOKUP(C51,'Lista desplegable'!B$1:C$436,2,FALSE),"") -> RICARDO ALEXIS LEMUS LOPEZ | E51: =IFERROR(VLOOKUP(D51,'Lista desplegable'!C$1:D$436,2,FALSE),"") -> AYUDANTE DE PERFORISTA | F51: 200-13 | G51: HQ | H51: 0-200 | I51: 51,00 | J51: PRESENTE | K51: SI | L51: SI
B52: 11 | C52: 18403269-4 | D52: =IFERROR(VLOOKUP(C52,'Lista desplegable'!B$1:C$436,2,FALSE),"") -> SEBASTIAN ANTONIO VALDERRAMA HERRERA | E52: =IFERROR(VLOOKUP(D52,'Lista desplegable'!C$1:D$436,2,FALSE),"") -> AYUDANTE DE PERFORISTA | F52: 200-13 | G52: HQ | H52: 0-200 | I52: 51,00 | J52: PRESENTE | K52: SI | L52: SI
...

Sheet 02-09
G2: DIA
D3: PROYECTO: | E3: CERRO BAYO / CHILE CHICO | G3: 46062
C6: TURNO DIA - B
B7: N° | C7: RUT | D7: NOMBRES Y APELLIDOS | E7: CARGO | F7: MAQUINA | G7: DIAMETRO | H7: ESCALA | I7: METROS | J7: ASISTENCIA | K7: WORKERA ENTRADA | L7: WORKERA SALIDA | M7: OBSERVACIONES
B8: 1 | C8: 44632507-8 | D8: =IFERROR(VLOOKUP(C8,'Lista desplegable'!B$1:C$436,2,FALSE),"") -> ANDREW JAMES WILSON . | E8: =IFERROR(VLOOKUP(D8,'Lista desplegable'!C$1:D$436,2,FALSE),"") -> PERFORISTA | F8: 200-13 | G8: HQ | H8: 0-200 | I8: 33,0 | J8: PRESENTE | M8: NO APLICA FIRMA, EXPATRIADO
B9: 2 | C9: 28935989-3 | D9: =IFERROR(VLOOKUP(C9,'Lista desplegable'!B$1:C$436,2,FALSE),"") -> STEWART PHILLIP WHITEHURST MEJIA | E9: =IFERROR(VLOOKUP(D9,'Lista desplegable'!C$1:D$436,2,FALSE),"") -> PERFORISTA | F9: 200-13 | G9: HQ | H9: 0-200 | I9: 33,0 | J9: PRESENTE | M9: NO APLICA FIRMA, EXPATRIADO
B10: 3 | C10: 13745724-5 | D10: =IFERROR(VLOOKUP(C10,'Lista desplegable'!B$1:C$436,2,FALSE),"") -> JOSE MANUEL CASTILLO GARCIA | E10: =IFERROR(VLOOKUP(D10,'Lista desplegable'!C$1:D$436,2,FALSE),"") -> INSTRUCTOR DE OPERACIONES | F10: 200-13 | G10: HQ | H10: 0-200 | I10: 33,0 | J10: PRESENTE | K10: SI | L10: SI
B11: 4 | C11: 18490734-8 | D11: =IFERROR(VLOOKUP(C11,'Lista desplegable'!B$1:C$436,2,FALSE),"") -> SIMONNE DE LA PAZ REYES BATLLE | E11: =IFERROR(VLOOKUP(D11,'Lista desplegable'!C$1:D$436,2,FALSE),"") -> ADMINISTRATIVO DE FAENA | F11: 200-13 | G11: HQ | H11: 0-200 | I11: 33,0 | J11: PRESENTE | K11: SI | L11: SI
B12: 5 | C12: 16892085-7 | D12: =IFERROR(VLOOKUP(C12,'Lista desplegable'!B$1:C$436,2,FALSE),"") -> MANUEL ALEJANDRO LISAMBARTH CARABANTES | E12: =IFERROR(VLOOKUP(D12,'Lista desplegable'!C$1:D$436,2,FALSE),"") -> ADMINISTRATIVO DE FAENA | F12: 200-13 | G12: HQ | H12: 0-200 | I12: 33,0 | J12: PRESENTE | K12: SI | L12: SI
B13: 6 | C13: 17697158-4 | D13: =IFERROR(VLOOKUP(C13,'Lista desplegable'!B$1:C$436,2,FALSE),"") -> RODRIGO ANDRES DIAZ INOSTROZA | E13: =IFERROR(VLOOKUP(D13,'Lista desplegable'!C$1:D$436,2,FALSE),"") -> BODEGUERO | F13: 200-13 | G13: HQ | H13: 0-200 | I13: 33,0 | J13: PRESENTE | K13: SI | L13: SI
B14: 7 | C14: 20456853-7 | D14: =IFERROR(VLOOKUP(C14,'Lista desplegable'!B$1:C$436,2,FALSE),"") -> CHRISTIAN DARIEM PIZARRO MUÑOZ | E14: =IFERROR(VLOOKUP(D14,'Lista desplegable'!C$1:D$436,2,FALSE),"") -> SOLDADOR | F14: 200-13 | G14: HQ | H14: 0-200 | I14: 33,0 | J14: PRESENTE | K14: SI | L14: SI
B15: 8 | C15: 17169171-0 | D15: =IFERROR(VLOOKUP(C15,'Lista desplegable'!B$1:C$436,2,FALSE),"") -> LUIS GERARDO LOPEZ OLAVE | E15: =IFERROR(VLOOKUP(D15,'Lista desplegable'!C$1:D$436,2,FALSE),"") -> MECANICO | F15: 200-13 | G15: HQ | H15: 0-200 | I15: 33,0 | J15: PRESENTE | K15: SI | L15: SI
B16: 9 | C16: 19506189-0 | D16: =IFERROR(VLOOKUP(C16,'Lista desplegable'!B$1:C$436,2,FALSE),"") -> DIEGO NICOLAS GONZALEZ OLIVARES | E16: =IFERROR(VLOOKUP(D16,'Lista desplegable'!C$1:D$436,2,FALSE),"") -> MECANICO | F16: 200-13 | G16: HQ | H16: 0-200 | I16: 33,0 | J16: PRESENTE | K16: SI | L16: SI
B17: 10 | C17: 19518296-5 | D17: =IFERROR(VLOOKUP(C17,'Lista desplegable'!B$1:C$436,2,FALSE),"") -> JORGE ANDRES LICANQUEO PEREZ | E17: =IFERROR(VLOOKUP(D17,'Lista desplegable'!C$1:D$436,2,FALSE),"") -> MECANICO | F17: 200-13 | G17: HQ | H17: 0-200 | I17: 33,0 | J17: PRESENTE | K17: SI | L17: SI
B18: 11 | C18: 16981319-1 | D18: =IFERROR(VLOOKUP(C18,'Lista desplegable'!B$1:C$436,2,FALSE),"") -> MARCOS ANTONIO ALDEA BEROIZA | E18: =IFERROR(VLOOKUP(D18,'Lista desplegable'!C$1:D$436,2,FALSE),"") -> CHOFER | F18: 200-13 | G18: HQ | H18: 0-200 | I18: 33,0 | J18: PRESENTE | K18: SI | L18: SI
B19: 12 | C19: 14400090-0 | D19: =IFERROR(VLOOKUP(C19,'Lista desplegable'!B$1:C$436,2,FALSE),"") -> CARLOS ALBERTO RAMOS VELASQUEZ | E19: =IFERROR(VLOOKUP(D19,'Lista desplegable'!C$1:D$436,2,FALSE),"") -> SUPERVISOR DE OPERACIONES | F19: 200-13 | G19: HQ | H19: 0-200 | I19: 33,0 | J19: PRESENTE | K19: SI | L19: SI
B20: 13 | C20: 15196627-6 | D20: =IFERROR(VLOOKUP(C20,'Lista desplegable'!B$1:C$436,2,FALSE),"") -> NELSON PATRICIO FLORES SANHUEZA | E20: =IFERROR(VLOOKUP(D20,'Lista desplegable'!C$1:D$436,2,FALSE),"") -> PREVENCIONISTA DE RIESGOS | F20: 200-13 | G20: HQ | H20: 0-200 | I20: 33,0 | J20: PRESENTE | K20: SI | L20: SI
B21: 14 | C21: 12218170-7 | D21: =IFERROR(VLOOKUP(C21,'Lista desplegable'!B$1:C$436,2,FALSE),"") -> EDUARDO ANTONIO CASTILLO VALENZUELA | E21: =IFERROR(VLOOKUP(D21,'Lista desplegable'!C$1:D$436,2,FALSE),"") -> PERFORISTA | F21: 200-11 | G21: HQ | H21: 0-200 | I21: 20,70 | J21: PRESENTE | K21: SI | L21: SI
... B29: 22 | C29: 44601894-9 | D29: =IFERROR(VLOOKUP(C29,'Lista desplegable'!B$1:C$436,2,FALSE),"") -> ANTONIO HIPOLITO OTINIANO RUIZ | E29: =IFERROR(VLOOKUP(D29,'Lista desplegable'!C$1:D$436,2,FALSE),"") -> PERFORISTA | F29: 200-11 | G29: HQ | H29: 0-200 | I29: 20,70 | J29: PRESENTE | K29: SI | L29: SI
B30: 23 | D30: =IFERROR(VLOOKUP(C30,'Lista desplegable'!B$1:C$436,2,FALSE),"") | E30: =IFERROR(VLOOKUP(D30,'Lista desplegable'!C$1:D$436,2,FALSE),"")
B31: 24 | D31: =IFERROR(VLOOKUP(C31,'Lista desplegable'!B$1:C$436,2,FALSE),"") | E31: =IFERROR(VLOOKUP(D31,'Lista desplegable'!C$1:D$436,2,FALSE),"")
B32: 25 | D32: =IFERROR(VLOOKUP(C32,'Lista desplegable'!B$1:C$436,2,FALSE),"") | E32: =IFERROR(VLOOKUP(D32,'Lista desplegable'!C$1:D$436,2,FALSE),"")
B33: 26 | D33: =IFERROR(VLOOKUP(C33,'Lista desplegable'!B$1:C$436,2,FALSE),"") | E33: =IFERROR(VLOOKUP(D33,'Lista desplegable'!C$1:D$436,2,FALSE),"")
B34: 27 | D34: =IFERROR(VLOOKUP(C34,'Lista desplegable'!B$1:C$436,2,FALSE),"") | E34: =IFERROR(VLOOKUP(D34,'Lista desplegable'!C$1:D$436,2,FALSE),"")
B35: 28 | D35: =IFERROR(VLOOKUP(C35,'Lista desplegable'!B$1:C$436,2,FALSE),"") | E35: =IFERROR(VLOOKUP(D35,'Lista desplegable'!C$1:D$436,2,FALSE),"")
B36: 29 | D36: =IFERROR(VLOOKUP(C36,'Lista desplegable'!B$1:C$436,2,FALSE),"") | E36: =IFERROR(VLOOKUP(D36,'Lista desplegable'!C$1:D$436,2,FALSE),"")
B37: 30 | D37: =IFERROR(VLOOKUP(C37,'Lista desplegable'!B$1:C$436,2,FALSE),"") | E37: =IFERROR(VLOOKUP(D37,'Lista desplegable'!C$1:D$436,2,FALSE),"")
C40: TURNO NOCHE - B
B41: N° | C41: RUT | D41: NOMBRES Y APELLIDOS | E41: CARGO | F41: MAQUINA | G41: DIAMETRO | H41: ESCALA | I41: METROS | J41: ASISTENCIA | K41: WORKERA ENTRADA | L41: WORKERA SALIDA | M41: OBSERVACIONES
B42: 1 | C42: 18494463-4 | D42: =IFERROR(VLOOKUP(C42,'Lista desplegable'!B$1:C$436,2,FALSE),"") -> RAUL ESTEBAN HERNANDEZ PIZARRO | E42: =IFERROR(VLOOKUP(D42,'Lista desplegable'!C$1:D$436,2,FALSE),"") -> PREVENCIONISTA DE RIESGOS | F42: 200-13 | G42: HQ | H42: 0-200 | I42: 10,5 | J42: PRESENTE | K42: SI | L42: SI
C43: 18494463-4 | D43: =IFERROR(VLOOKUP(C43,'Lista desplegable'!B$1:C$436,2,FALSE),"") -> RAUL ESTEBAN HERNANDEZ PIZARRO | E43: =IFERROR(VLOOKUP(D43,'Lista desplegable'!C$1:D$436,2,FALSE),"") -> PREVENCIONISTA DE RIESGOS | F43: 200-13 | G43: HQ | H43: 200-400 | I43: 5,10
B44: 2 | C44: 44599978-4 | D44: =IFERROR(VLOOKUP(C44,'Lista desplegable'!B$1:C$436,2,FALSE),"") -> FRANCISCO PEDRO BORNAZ DELGADO | E44: =IFERROR(VLOOKUP(D44,'Lista desplegable'!C$1:D$436,2,FALSE),"") -> SUPERVISOR DE OPERACIONES | F44: 200-13 | G44: HQ | H44: 0-200 | I44: 10,5 | J44: DESCANSO
C45: 44599978-4 | D45: =IFERROR(VLOOKUP(C45,'Lista desplegable'!B$1:C$436,2,FALSE),"") -> FRANCISCO PEDRO BORNAZ DELGADO | E45: =IFERROR(VLOOKUP(D45,'Lista desplegable'!C$1:D$436,2,FALSE),"") -> SUPERVISOR DE OPERACIONES | F45: 200-13 | G45: HQ | H45: 200-400 | I45: 5,10
B46: 3 | C46: 17580584-2 | D46: =IFERROR(VLOOKUP(C46,'Lista desplegable'!B$1:C$436,2,FALSE),"") -> CAMILO FELIPE CRUZ MOLINA | E46: =IFERROR(VLOOKUP(D46,'Lista desplegable'!C$1:D$436,2,FALSE),"") -> SUPERVISOR DE OPERACIONES | F46: 200-13 | G46: HQ | H46: 0-200 | I46: 10,5 | J46: PRESENTE | K46: SI | L46: SI
C47: 17580584-2 | D47: =IFERROR(VLOOKUP(C47,'Lista desplegable'!B$1:C$436,2,FALSE),"") -> CAMILO FELIPE CRUZ MOLINA | E47: =IFERROR(VLOOKUP(D47,'Lista desplegable'!C$1:D$436,2,FALSE),"") -> SUPERVISOR DE OPERACIONES | F47: 200-13 | G47: HQ | H47: 200-400 | I47: 5,10
B48: 4 | C48: 12707776-2 | D48: =IFERROR(VLOOKUP(C48,'Lista desplegable'!B$1:C$436,2,FALSE),"") -> RICARDO DE LAS NIEVES GUTIERREZ FUENTES | E48: =IFERROR(VLOOKUP(D48,'Lista desplegable'!C$1:D$436,2,FALSE),"") -> CHOFER | F48: 200-13 | G48: HQ | H48: 0-200 | I48: 10,5 | J48: PRESENTE | K48: SI | L48: SI
C49: 12707776-2 | D49: =IFERROR(VLOOKUP(C49,'Lista desplegable'!B$1:C$436,2,FALSE),"") -> RICARDO DE LAS NIEVES GUTIERREZ FUENTES | E49: =IFERROR(VLOOKUP(D49,'Lista desplegable'!C$1:D$436,2,FALSE),"") -> CHOFER | F49: 200-13 | G49: HQ | H49: 200-400 | I49: 5,10
B50: 5 | C50: 26931695-0 | D50: =IFERROR(VLOOKUP(C50,'Lista desplegable'!B$1:C$436,2,FALSE),"") -> SEBASTIAN GONZALO ROJAS CLARO | E50: =IFERROR(VLOOKUP(D50,'Lista desplegable'!C$1:D$436,2,FALSE),"") -> MECANICO | F50: 200-13 | G50: HQ | H50: 0-200 | I50: 10,5 | J50: PRESENTE | K50: SI | L50: SI
C51: 26931695-0 | D51: =IFERROR(VLOOKUP(C51,'Lista desplegable'!B$1:C$436,2,FALSE),"") -> SEBASTIAN GONZALO ROJAS CLARO | E51: =IFERROR(VLOOKUP(D51,'Lista desplegable'!C$1:D$436,2,FALSE),"") -> MECANICO | F51: 200-13 | G51: HQ | H51: 200-400 | I51: 5,10
B52: 6 | C52: 18665544-3 | D52: =IFERROR(VLOOKUP(C52,'Lista desplegable'!B$1:C$436,2,FALSE),"") -> DANIEL ANDRES VENEGAS CARRASCO | E52: =IFERROR(VLOOKUP(D52,'Lista desplegable'!C$1:D$436,2,FALSE),"") -> PERFORISTA | F52: 200-11 | G52: HQ | H52: 0-200 | I52: 0 | J52: PRESENTE | K52: SI | L52: SI | M52: CAMBIO DE POZO
...

Sheet 03-09
G2: DIA
D3: PROYECTO: | E3: CERRO BAYO / CHILE CHICO | G3: 46090
C6: TURNO DIA - B
B7: N° | C7: RUT | D7: NOMBRES Y APELLIDOS | E7: CARGO | F7: MAQUINA | G7: DIAMETRO | H7: ESCALA | I7: METROS | J7: ASISTENCIA | K7: WORKERA ENTRADA | L7: WORKERA SALIDA | M7: OBSERVACIONES
B8: 1 | C8: 44632507-8 | D8: =IFERROR(VLOOKUP(C8,'Lista desplegable'!B$1:C$436,2,FALSE),"") -> ANDREW JAMES WILSON . | E8: =IFERROR(VLOOKUP(D8,'Lista desplegable'!C$1:D$436,2,FALSE),"") -> PERFORISTA | F8: 200-11 | G8: HQ | H8: 0-200 | I8: 13,90 | J8: PRESENTE | M8: NO APLICA FIRMA, EXPATRIADO
B9: 2 | C9: 28935989-3 | D9: =IFERROR(VLOOKUP(C9,'Lista desplegable'!B$1:C$436,2,FALSE),"") -> STEWART PHILLIP WHITEHURST MEJIA | E9: =IFERROR(VLOOKUP(D9,'Lista desplegable'!C$1:D$436,2,FALSE),"") -> PERFORISTA | F9: 200-11 | G9: HQ | H9: 0-200 | I9: 13,90 | J9: PRESENTE | M9: NO APLICA FIRMA, EXPATRIADO
B10: 3 | C10: 13745724-5 | D10: =IFERROR(VLOOKUP(C10,'Lista desplegable'!B$1:C$436,2,FALSE),"") -> JOSE MANUEL CASTILLO GARCIA | E10: =IFERROR(VLOOKUP(D10,'Lista desplegable'!C$1:D$436,2,FALSE),"") -> INSTRUCTOR DE OPERACIONES | F10: 200-11 | G10: HQ | H10: 0-200 | I10: 13,90 | J10: PRESENTE | K10: SI | L10: SI
B11: 4 | C11: 18490734-8 | D11: =IFERROR(VLOOKUP(C11,'Lista desplegable'!B$1:C$436,2,FALSE),"") -> SIMONNE DE LA PAZ REYES BATLLE | E11: =IFERROR(VLOOKUP(D11,'Lista desplegable'!C$1:D$436,2,FALSE),"") -> ADMINISTRATIVO DE FAENA | F11: 200-11 | G11: HQ | H11: 0-200 | I11: 13,90 | J11: PRESENTE | K11: SI | L11: SI
B12: 5 | C12: 16892085-7 | D12: =IFERROR(VLOOKUP(C12,'Lista desplegable'!B$1:C$436,2,FALSE),"") -> MANUEL ALEJANDRO LISAMBARTH CARABANTES | E12: =IFERROR(VLOOKUP(D12,'Lista desplegable'!C$1:D$436,2,FALSE),"") -> ADMINISTRATIVO DE FAENA | F12: 200-11 | G12: HQ | H12: 0-200 | I12: 13,90 | J12: PRESENTE | K12: SI | L12: SI
B13: 6 | C13: 17697158-4 | D13: =IFERROR(VLOOKUP(C13,'Lista desplegable'!B$1:C$436,2,FALSE),"") -> RODRIGO ANDRES DIAZ INOSTROZA | E13: =IFERROR(VLOOKUP(D13,'Lista desplegable'!C$1:D$436,2,FALSE),"") -> BODEGUERO | F13: 200-11 | G13: HQ | H13: 0-200 | I13: 13,90 | J13: PRESENTE | K13: SI | L13: SI
B14: 7 | C14: 20456853-7 | D14: =IFERROR(VLOOKUP(C14,'Lista desplegable'!B$1:C$436,2,FALSE),"") -> CHRISTIAN DARIEM PIZARRO MUÑOZ | E14: =IFERROR(VLOOKUP(D14,'Lista desplegable'!C$1:D$436,2,FALSE),"") -> SOLDADOR | F14: 200-11 | G14: HQ | H14: 0-200 | I14: 13,90 | J14: PRESENTE | K14: SI | L14: SI
B15: 8 | C15: 17169171-0 | D15: =IFERROR(VLOOKUP(C15,'Lista desplegable'!B$1:C$436,2,FALSE),"") -> LUIS GERARDO LOPEZ OLAVE | E15: =IFERROR(VLOOKUP(D15,'Lista desplegable'!C$1:D$436,2,FALSE),"") -> MECANICO | F15: 200-11 | G15: HQ | H15: 0-200 | I15: 13,90 | J15: PRESENTE | K15: SI | L15: SI
B16: 9 | C16: 19506189-0 | D16: =IFERROR(VLOOKUP(C16,'Lista desplegable'!B$1:C$436,2,FALSE),"") -> DIEGO NICOLAS GONZALEZ OLIVARES | E16: =IFERROR(VLOOKUP(D16,'Lista desplegable'!C$1:D$436,2,FALSE),"") -> MECANICO | F16: 200-11 | G16: HQ | H16: 0-200 | I16: 13,90 | J16: PRESENTE | K16: SI | L16: SI
B17: 10 | C17: 19518296-5 | D17: =IFERROR(VLOOKUP(C17,'Lista desplegable'!B$1:C$436,2,FALSE),"") -> JORGE ANDRES LICANQUEO PEREZ | E17: =IFERROR(VLOOKUP(D17,'Lista desplegable'!C$1:D$436,2,FALSE),"") -> MECANICO | F17: 200-11 | G17: HQ | H17: 0-200 | I17: 13,90 | J17: PRESENTE | K17: SI | L17: SI
B18: 11 | C18: 16981319-1 | D18: =IFERROR(VLOOKUP(C18,'Lista desplegable'!B$1:C$436,2,FALSE),"") -> MARCOS ANTONIO ALDEA BEROIZA | E18: =IFERROR(VLOOKUP(D18,'Lista desplegable'!C$1:D$436,2,FALSE),"") -> CHOFER | F18: 200-11 | G18: HQ | H18: 0-200 | I18: 13,90 | J18: PRESENTE | K18: SI | L18: SI
B19: 12 | C19: 14400090-0 | D19: =IFERROR(VLOOKUP(C19,'Lista desplegable'!B$1:C$436,2,FALSE),"") -> CARLOS ALBERTO RAMOS VELASQUEZ | E19: =IFERROR(VLOOKUP(D19,'Lista desplegable'!C$1:D$436,2,FALSE),"") -> SUPERVISOR DE OPERACIONES | F19: 200-11 | G19: HQ | H19: 0-200 | I19: 13,90 | J19: PRESENTE | K19: SI | L19: SI
B20: 13 | C20: 15196627-6 | D20: =IFERROR(VLOOKUP(C20,'Lista desplegable'!B$1:C$436,2,FALSE),"") -> NELSON PATRICIO FLORES SANHUEZA | E20: =IFERROR(VLOOKUP(D20,'Lista desplegable'!C$1:D$436,2,FALSE),"") -> PREVENCIONISTA DE RIESGOS | F20: 200-11 | G20: HQ | H20: 0-200 | I20: 13,90 | J20: PRESENTE | K20: SI | L20: SI
B21: 14 | C21: 12218170-7 | D21: =IFERROR(VLOOKUP(C21,'Lista desplegable'!B$1:C$436,2,FALSE),"") -> EDUARDO ANTONIO CASTILLO VALENZUELA | E21: =IFERROR(VLOOKUP(D21,'Lista desplegable'!C$1:D$436,2,FALSE),"") -> PERFORISTA | F21: 200-11 | G21: HQ | H21: 0-200 | I21: 13,90 | J21: PRESENTE | K21: SI | L21: SI
... B24: 17 | C24: 19983747-8 | D24: =IFERROR(VLOOKUP(C24,'Lista desplegable'!B$1:C$436,2,FALSE),"") -> RUBEN IGNACIO CORTES BORBON | E24: =IFERROR(VLOOKUP(D24,'Lista desplegable'!C$1:D$436,2,FALSE),"") -> AYUDANTE DE PERFORISTA | F24: 200-11 | G24: HQ | H24: 0-200 | I24: 13,90 | J24: PRESENTE | K24: SI | L24: SI
B25: 18 | C25: 20460401-0 | D25: =IFERROR(VLOOKUP(C25,'Lista desplegable'!B$1:C$436,2,FALSE),"") -> KEVIN ALEXIS NEYRA CORTES | E25: =IFERROR(VLOOKUP(D25,'Lista desplegable'!C$1:D$436,2,FALSE),"") -> PERFORISTA | F25: 200-13 | G25: HQ | H25: 0-200 | I25: 0 | J25: PRESENTE | K25: SI | L25: SI
B26: 19 | C26: 17980395-K | D26: =IFERROR(VLOOKUP(C26,'Lista desplegable'!B$1:C$436,2,FALSE),"") -> PATRICIO RENAN GONZALEZ CABELLO | E26: =IFERROR(VLOOKUP(D26,'Lista desplegable'!C$1:D$436,2,FALSE),"") -> AYUDANTE DE PERFORISTA | F26: 200-13 | G26: HQ | H26: 0-200 | I26: 0 | J26: PRESENTE | K26: SI | L26: SI
B27: 20 | C27: 20456931-2 | D27: =IFERROR(VLOOKUP(C27,'Lista desplegable'!B$1:C$436,2,FALSE),"") -> DIEGO BRANCO BARRAZA CHAVEZ | E27: =IFERROR(VLOOKUP(D27,'Lista desplegable'!C$1:D$436,2,FALSE),"") -> AYUDANTE DE PERFORISTA | F27: 200-13 | G27: HQ | H27: 0-200 | I27: 0 | J27: PRESENTE | K27: SI | L27: SI
B28: 21 | C28: 20774155-8 | D28: =IFERROR(VLOOKUP(C28,'Lista desplegable'!B$1:C$436,2,FALSE),"") -> OSCAR RODRIGO ARIAS LEIVA | E28: =IFERROR(VLOOKUP(D28,'Lista desplegable'!C$1:D$436,2,FALSE),"") -> AYUDANTE DE PERFORISTA | F28: 200-13 | G28: HQ | H28: 0-200 | I28: 0 | J28: PRESENTE | K28: SI | L28: SI
B29: 22 | C29: 11778172-0 | D29: =IFERROR(VLOOKUP(C29,'Lista desplegable'!B$1:C$436,2,FALSE),"") -> ORLANDO PATRICIO CONTRERAS RIOS | E29: =IFERROR(VLOOKUP(D29,'Lista desplegable'!C$1:D$436,2,FALSE),"") -> PERFORISTA | F29: 200-11 | G29: HQ | H29: 0-200 | I29: 13,90 | J29: PRESENTE | K29: SI | L29: SI | M29: INGRESO A FAENA 03-09
B30: 23 | C30: 20037472-K | D30: =IFERROR(VLOOKUP(C30,'Lista desplegable'!B$1:C$436,2,FALSE),"") -> ANGELO GIOVANNI BIZAMA ORELLANA | E30: =IFERROR(VLOOKUP(D30,'Lista desplegable'!C$1:D$436,2,FALSE),"") -> AYUDANTE DE PERFORISTA | J30: OBSERVACIÓN | M30: INICIO CONTRATO 03-09
B31: 24 | C31: 15955871-1 | D31: =IFERROR(VLOOKUP(C31,'Lista desplegable'!B$1:C$436,2,FALSE),"") -> WALTER LISANDRO SALAS MESA | E31: =IFERROR(VLOOKUP(D31,'Lista desplegable'!C$1:D$436,2,FALSE),"") -> PERFORISTA | J31: OBSERVACIÓN | M31: INICIO CONTRATO 03-09
B32: 25 | D32: =IFERROR(VLOOKUP(C32,'Lista desplegable'!B$1:C$436,2,FALSE),"") | E32: =IFERROR(VLOOKUP(D32,'Lista desplegable'!C$1:D$436,2,FALSE),"")
B33: 26 | D33: =IFERROR(VLOOKUP(C33,'Lista desplegable'!B$1:C$436,2,FALSE),"") | E33: =IFERROR(VLOOKUP(D33,'Lista desplegable'!C$1:D$436,2,FALSE),"")
B34: 27 | D34: =IFERROR(VLOOKUP(C34,'Lista desplegable'!B$1:C$436,2,FALSE),"") | E34: =IFERROR(VLOOKUP(D34,'Lista desplegable'!C$1:D$436,2,FALSE),"")
B35: 28 | D35: =IFERROR(VLOOKUP(C35,'Lista desplegable'!B$1:C$436,2,FALSE),"") | E35: =IFERROR(VLOOKUP(D35,'Lista desplegable'!C$1:D$436,2,FALSE),"")
B36: 29 | D36: =IFERROR(VLOOKUP(C36,'Lista desplegable'!B$1:C$436,2,FALSE),"") | E36: =IFERROR(VLOOKUP(D36,'Lista desplegable'!C$1:D$436,2,FALSE),"")
B37: 30 | D37: =IFERROR(VLOOKUP(C37,'Lista desplegable'!B$1:C$436,2,FALSE),"") | E37: =IFERROR(VLOOKUP(D37,'Lista desplegable'!C$1:D$436,2,FALSE),"")
C40: TURNO NOCHE - B
B41: N° | C41: RUT | D41: NOMBRES Y APELLIDOS | E41: CARGO | F41: MAQUINA | G41: DIAMETRO | H41: ESCALA | I41: METROS | J41: ASISTENCIA | K41: WORKERA ENTRADA | L41: WORKERA SALIDA | M41: OBSERVACIONES
B42: 1 | C42: 18494463-4 | D42: =IFERROR(VLOOKUP(C42,'Lista desplegable'!B$1:C$436,2,FALSE),"") -> RAUL ESTEBAN HERNANDEZ PIZARRO | E42: =IFERROR(VLOOKUP(D42,'Lista desplegable'!C$1:D$436,2,FALSE),"") -> PREVENCIONISTA DE RIESGOS | F42: 200-11 | G42: HQ | H42: 0-200 | I42: 40,40 | J42: PRESENTE | K42: SI | L42: SI
B43: 2 | C43: 44599978-4 | D43: =IFERROR(VLOOKUP(C43,'Lista desplegable'!B$1:C$436,2,FALSE),"") -> FRANCISCO PEDRO BORNAZ DELGADO | E43: =IFERROR(VLOOKUP(D43,'Lista desplegable'!C$1:D$436,2,FALSE),"") -> SUPERVISOR DE OPERACIONES | F43: 200-11 | G43: HQ | H43: 0-200 | I43: 40,40 | J43: PRESENTE | K43: SI | L43: SI
B44: 3 | C44: 17580584-2 | D44: =IFERROR(VLOOKUP(C44,'Lista desplegable'!B$1:C$436,2,FALSE),"") -> CAMILO FELIPE CRUZ MOLINA | E44: =IFERROR(VLOOKUP(D44,'Lista desplegable'!C$1:D$436,2,FALSE),"") -> SUPERVISOR DE OPERACIONES | F44: 200-11 | G44: HQ | H44: 0-200 | I44: 40,40 | J44: PRESENTE | K44: SI | L44: SI
B45: 4 | C45: 12707776-2 | D45: =IFERROR(VLOOKUP(C45,'Lista desplegable'!B$1:C$436,2,FALSE),"") -> RICARDO DE LAS NIEVES GUTIERREZ FUENTES | E45: =IFERROR(VLOOKUP(D45,'Lista desplegable'!C$1:D$436,2,FALSE),"") -> CHOFER | F45: 200-11 | G45: HQ | H45: 0-200 | I45: 40,40 | J45: PRESENTE | K45: SI | L45: SI
B46: 5 | C46: 26931695-0 | D46: =IFERROR(VLOOKUP(C46,'Lista desplegable'!B$1:C$436,2,FALSE),"") -> SEBASTIAN GONZALO ROJAS CLARO | E46: =IFERROR(VLOOKUP(D46,'Lista desplegable'!C$1:D$436,2,FALSE),"") -> MECANICO | F46: 200-11 | G46: HQ | H46: 0-200 | I46: 40,40 | J46: PRESENTE | K46: SI | L46: SI
B47: 6 | C47: 18665544-3 | D47: =IFERROR(VLOOKUP(C47,'Lista desplegable'!B$1:C$436,2,FALSE),"") -> DANIEL ANDRES VENEGAS CARRASCO | E47: =IFERROR(VLOOKUP(D47,'Lista desplegable'!C$1:D$436,2,FALSE),"") -> PERFORISTA | F47: 200-11 | G47: HQ | H47: 0-200 | I47: 40,40 | J47: PRESENTE | K47: SI | L47: SI
...

Sheet 04-09
G2: DIA
D3: PROYECTO: | E3: CERRO BAYO / CHILE CHICO | G3: 46121
C6: TURNO DIA - B
B7: N° | C7: RUT | D7: NOMBRES Y APELLIDOS | E7: CARGO | F7: MAQUINA | G7: DIAMETRO | H7: ESCALA | I7: METROS | J7: ASISTENCIA | K7: WORKERA ENTRADA | L7: WORKERA SALIDA | M7: OBSERVACIONES
B8: 1 | C8: 44632507-8 | D8: =IFERROR(VLOOKUP(C8,'Lista desplegable'!B$1:C$436,2,FALSE),"") -> ANDREW JAMES WILSON . | E8: =IFERROR(VLOOKUP(D8,'Lista desplegable'!C$1:D$436,2,FALSE),"") -> PERFORISTA | F8: 200-11 | G8: HQ | H8: 0-200 | I8: 39,05 | J8: PRESENTE | M8: NO APLICA FIRMA, EXPATRIADO
B9: 2 | C9: 28935989-3 | D9: =IFERROR(VLOOKUP(C9,'Lista desplegable'!B$1:C$436,2,FALSE),"") -> STEWART PHILLIP WHITEHURST MEJIA | E9: =IFERROR(VLOOKUP(D9,'Lista desplegable'!C$1:D$436,2,FALSE),"") -> PERFORISTA | F9: 200-11 | G9: HQ | H9: 0-200 | I9: 39,05 | J9: PRESENTE | M9: NO APLICA FIRMA, EXPATRIADO
B10: 3 | C10: 15475908-5 | D10: =IFERROR(VLOOKUP(C10,'Lista desplegable'!B$1:C$436,2,FALSE),"") -> ISRAEL AARÓN VERGARA ELGUETA | E10: =IFERROR(VLOOKUP(D10,'Lista desplegable'!C$1:D$436,2,FALSE),"") -> ADMINISTRADOR DE CONTRATO | F10: 200-11 | G10: HQ | H10: 0-200 | I10: 39,05 | J10: PRESENTE | K10: SI | L10: SI | M10: INGRESO 04-09
B11: 4 | C11: 18490734-8 | D11: =IFERROR(VLOOKUP(C11,'Lista desplegable'!B$1:C$436,2,FALSE),"") -> SIMONNE DE LA PAZ REYES BATLLE | E11: =IFERROR(VLOOKUP(D11,'Lista desplegable'!C$1:D$436,2,FALSE),"") -> ADMINISTRATIVO DE FAENA | J11: DESCANSO
B12: 5 | C12: 16892085-7 | D12: =IFERROR(VLOOKUP(C12,'Lista desplegable'!B$1:C$436,2,FALSE),"") -> MANUEL ALEJANDRO LISAMBARTH CARABANTES | E12: =IFERROR(VLOOKUP(D12,'Lista desplegable'!C$1:D$436,2,FALSE),"") -> ADMINISTRATIVO DE FAENA | F12: 200-11 | G12: HQ | H12: 0-200 | I12: 39,05 | J12: PRESENTE | K12: SI | L12: SI
B13: 6 | C13: 17697158-4 | D13: =IFERROR(VLOOKUP(C13,'Lista desplegable'!B$1:C$436,2,FALSE),"") -> RODRIGO ANDRES DIAZ INOSTROZA | E13: =IFERROR(VLOOKUP(D13,'Lista desplegable'!C$1:D$436,2,FALSE),"") -> BODEGUERO | F13: 200-11 | G13: HQ | H13: 0-200 | I13: 39,05 | J13: PRESENTE | K13: SI | L13: SI
B14: 7 | C14: 20456853-7 | D14: =IFERROR(VLOOKUP(C14,'Lista desplegable'!B$1:C$436,2,FALSE),"") -> CHRISTIAN DARIEM PIZARRO MUÑOZ | E14: =IFERROR(VLOOKUP(D14,'Lista desplegable'!C$1:D$436,2,FALSE),"") -> SOLDADOR | F14: 200-11 | G14: HQ | H14: 0-200 | I14: 39,05 | J14: PRESENTE | K14: SI | L14: SI
B15: 8 | C15: 17465056-K | D15: =IFERROR(VLOOKUP(C15,'Lista desplegable'!B$1:C$436,2,FALSE),"") -> DANIEL ANDRES ANDRADE AGUILAR | E15: =IFERROR(VLOOKUP(D15,'Lista desplegable'!C$1:D$436,2,FALSE),"") -> MECANICO | F15: 200-11 | G15: HQ | H15: 0-200 | I15: 39,05 | J15: PRESENTE | K15: SI | L15: SI | M15: INGRESO 04-09
B16: 9 | C16: 19506189-0 | D16: =IFERROR(VLOOKUP(C16,'Lista desplegable'!B$1:C$436,2,FALSE),"") -> DIEGO NICOLAS GONZALEZ OLIVARES | E16: =IFERROR(VLOOKUP(D16,'Lista desplegable'!C$1:D$436,2,FALSE),"") -> MECANICO | F16: 200-11 | G16: HQ | H16: 0-200 | I16: 39,05 | J16: PRESENTE | K16: SI | L16: SI
B17: 10 | C17: 19518296-5 | D17: =IFERROR(VLOOKUP(C17,'Lista desplegable'!B$1:C$436,2,FALSE),"") -> JORGE ANDRES LICANQUEO PEREZ | E17: =IFERROR(VLOOKUP(D17,'Lista desplegable'!C$1:D$436,2,FALSE),"") -> MECANICO | F17: 200-11 | G17: HQ | H17: 0-200 | I17: 39,05 | J17: PRESENTE | K17: SI | L17: SI
B18: 11 | C18: 16981319-1 | D18: =IFERROR(VLOOKUP(C18,'Lista desplegable'!B$1:C$436,2,FALSE),"") -> MARCOS ANTONIO ALDEA BEROIZA | E18: =IFERROR(VLOOKUP(D18,'Lista desplegable'!C$1:D$436,2,FALSE),"") -> CHOFER | F18: 200-11 | G18: HQ | H18: 0-200 | I18: 39,05 | J18: PRESENTE | K18: SI | L18: SI
B19: 12 | C19: 14400090-0 | D19: =IFERROR(VLOOKUP(C19,'Lista desplegable'!B$1:C$436,2,FALSE),"") -> CARLOS ALBERTO RAMOS VELASQUEZ | E19: =IFERROR(VLOOKUP(D19,'Lista desplegable'!C$1:D$436,2,FALSE),"") -> SUPERVISOR DE OPERACIONES | F19: 200-11 | G19: HQ | H19: 0-200 | I19: 39,05 | J19: PRESENTE | K19: SI | L19: SI
B20: 13 | C20: 15196627-6 | D20: =IFERROR(VLOOKUP(C20,'Lista desplegable'!B$1:C$436,2,FALSE),"") -> NELSON PATRICIO FLORES SANHUEZA | E20: =IFERROR(VLOOKUP(D20,'Lista desplegable'!C$1:D$436,2,FALSE),"") -> PREVENCIONISTA DE RIESGOS | F20: 200-11 | G20: HQ | H20: 0-200 | I20: 39,05 | J20: PRESENTE | K20: SI | L20: SI
B21: 14 | C21: 12218170-7 | D21: =IFERROR(VLOOKUP(C21,'Lista desplegable'!B$1:C$436,2,FALSE),"") -> EDUARDO ANTONIO CASTILLO VALENZUELA | E21: =IFERROR(VLOOKUP(D21,'Lista desplegable'!C$1:D$436,2,FALSE),"") -> PERFORISTA | F21: 200-11 | G21: HQ | H21: 0-200 | I21: 39,05 | J21: PRESENTE | K21: SI | L21: SI
B22: 15 | C22: 19349619-9 | D22: =IFERROR(VLOOKUP(C22,'Lista desplegable'!B$1:C$436,2,FALSE),"") -> JEAN CHARLES CERDA ORREGO | E22: =IFERROR(VLOOKUP(D22,'Lista desplegable'!C$1:D$436,2,FALSE),"") -> AYUDANTE DE PERFORISTA | F22: 200-11 | G22: HQ | H22: 0-200 | I22: 39,05 | J22: PRESENTE | K22: SI | L22: SI
B23: 16 | C23: 16771866-3 | D23: =IFERROR(VLOOKUP(C23,'Lista desplegable'!B$1:C$436,2,FALSE),"") -> OMAR ANDRES ARAYA ZUÑIGA | E23: =IFERROR(VLOOKUP(D23,'Lista desplegable'!C$1:D$436,2,FALSE),"") -> AYUDANTE DE PERFORISTA | F23: 200-11 | G23: HQ | H23: 0-200 | I23: 39,05 | J23: PRESENTE | K23: SI | L23: SI
B24: 17 | C24: 19983747-8 | D24: =IFERROR(VLOOKUP(C24,'Lista desplegable'!B$1:C$436,2,FALSE),"") -> RUBEN IGNACIO CORTES BORBON | E24: =IFERROR(VLOOKUP(D24,'Lista desplegable'!C$1:D$436,2,FALSE),"") -> AYUDANTE DE PERFORISTA | F24: 200-11 | G24: HQ | H24: 0-200 | I24: 39,05 | J24: PRESENTE | K24: SI | L24: SI
B25: 18 | C25: 20460401-0 | D25: =IFERROR(VLOOKUP(C25,'Lista desplegable'!B$1:C$436,2,FALSE),"") -> KEVIN ALEXIS NEYRA CORTES | E25: =IFERROR(VLOOKUP(D25,'Lista desplegable'!C$1:D$436,2,FALSE),"") -> PERFORISTA | F25: 200-13 | G25: HQ | H25: 0-200 | I25: 0 | J25: PRESENTE | K25: SI | L25: SI
B26: 19 | C26: 17980395-K | D26: =IFERROR(VLOOKUP(C26,'Lista desplegable'!B$1:C$436,2,FALSE),"") -> PATRICIO RENAN GONZALEZ CABELLO | E26: =IFERROR(VLOOKUP(D26,'Lista desplegable'!C$1:D$436,2,FALSE),"") -> AYUDANTE DE PERFORISTA | F26: 200-13 | G26: HQ | H26: 0-200 | I26: 0 | J26: PRESENTE | K26: SI | L26: SI
B27: 20 | C27: 20456931-2 | D27: =IFERROR(VLOOKUP(C27,'Lista desplegable'!B$1:C$436,2,FALSE),"") -> DIEGO BRANCO BARRAZA CHAVEZ | E27: =IFERROR(VLOOKUP(D27,'Lista desplegable'!C$1:D$436,2,FALSE),"") -> AYUDANTE DE PERFORISTA | F27: 200-13 | G27: HQ | H27: 0-200 | I27: 0 | J27: PRESENTE | K27: SI | L27: SI
B28: 21 | C28: 20774155-8 | D28: =IFERROR(VLOOKUP(C28,'Lista desplegable'!B$1:C$436,2,FALSE),"") -> OSCAR RODRIGO ARIAS LEIVA | E28: =IFERROR(VLOOKUP(D28,'Lista desplegable'!C$1:D$436,2,FALSE),"") -> AYUDANTE DE PERFORISTA | F28: 200-13 | G28: HQ | H28: 0-200 | I28: 0 | J28: PRESENTE | K28: SI | L28: SI
B29: 22 | C29: 44599981-4 | D29: =IFERROR(VLOOKUP(C29,'Lista desplegable'!B$1:C$436,2,FALSE),"") -> DENYS SAUL VERGARA TOCAS | E29: =IFERROR(VLOOKUP(D29,'Lista desplegable'!C$1:D$436,2,FALSE),"") -> PERFORISTA | F29: 200-11 | G29: HQ | H29: 0-200 | I29: 39,05 | J29: PRESENTE | K29: SI | L29: SI | M29: INGRESO 04-09
B30: 23 | C30: 11778172-0 | D30: =IFERROR(VLOOKUP(C30,'Lista desplegable'!B$1:C$436,2,FALSE),"") -> ORLANDO PATRICIO CONTRERAS RIOS | E30: =IFERROR(VLOOKUP(D30,'Lista desplegable'!C$1:D$436,2,FALSE),"") -> PERFORISTA | F30: 200-11 | G30: HQ | H30: 0-200 | I30: 39,05 | J30: OBSERVACIÓN
B31: 24 | C31: 20037472-K | D31: =IFERROR(VLOOKUP(C31,'Lista desplegable'!B$1:C$436,2,FALSE),"") -> ANGELO GIOVANNI BIZAMA ORELLANA | E31: =IFERROR(VLOOKUP(D31,'Lista desplegable'!C$1:D$436,2,FALSE),"") -> AYUDANTE DE PERFORISTA | J31: OBSERVACIÓN | M31: EN DOMICILIO A LA ESPERA DE SUBIR A FAENA
B32: 25 | C32: 15955871-1 | D32: =IFERROR(VLOOKUP(C32,'Lista desplegable'!B$1:C$436,2,FALSE),"") -> WALTER LISANDRO SALAS MESA | E32: =IFERROR(VLOOKUP(D32,'Lista desplegable'!C$1:D$436,2,FALSE),"") -> PERFORISTA | M32: EN DOMICILIO A LA ESPERA DE SUBIR A FAENA
B33: 26 | D33: =IFERROR(VLOOKUP(C33,'Lista desplegable'!B$1:C$436,2,FALSE),"") | E33: =IFERROR(VLOOKUP(D33,'Lista desplegable'!C$1:D$436,2,FALSE),"")
B34: 27 | D34: =IFERROR(VLOOKUP(C34,'Lista desplegable'!B$1:C$436,2,FALSE),"") | E34: =IFERROR(VLOOKUP(D34,'Lista desplegable'!C$1:D$436,2,FALSE),"")
B35: 28 | D35: =IFERROR(VLOOKUP(C35,'Lista desplegable'!B$1:C$436,2,FALSE),"") | E35: =IFERROR(VLOOKUP(D35,'Lista desplegable'!C$1:D$436,2,FALSE),"")
B36: 29 | D36: =IFERROR(VLOOKUP(C36,'Lista desplegable'!B$1:C$436,2,FALSE),"") | E36: =IFERROR(VLOOKUP(D36,'Lista desplegable'!C$1:D$436,2,FALSE),"")
B37: 30 | D37: =IFERROR(VLOOKUP(C37,'Lista desplegable'!B$1:C$436,2,FALSE),"") | E37: =IFERROR(VLOOKUP(D37,'Lista desplegable'!C$1:D$436,2,FALSE),"")
C40: TURNO NOCHE - B
B41: N° | C41: RUT | D41: NOMBRES Y APELLIDOS | E41: CARGO | F41: MAQUINA | G41: DIAMETRO | H41: ESCALA | I41: METROS | J41: ASISTENCIA | K41: WORKERA ENTRADA | L41: WORKERA SALIDA | M41: OBSERVACIONES
B42: 1 | C42: 18494463-4 | D42: =IFERROR(VLOOKUP(C42,'Lista desplegable'!B$1:C$436,2,FALSE),"") -> RAUL ESTEBAN HERNANDEZ PIZARRO | E42: =IFERROR(VLOOKUP(D42,'Lista desplegable'!C$1:D$436,2,FALSE),"") -> PREVENCIONISTA DE RIESGOS | F42: 200-11 | G42: HQ | H42: 0-200 | I42: 41,95 | J42: PRESENTE | K42: SI | L42: SI
B43: 2 | C43: 44599978-4 | D43: =IFERROR(VLOOKUP(C43,'Lista desplegable'!B$1:C$436,2,FALSE),"") -> FRANCISCO PEDRO BORNAZ DELGADO | E43: =IFERROR(VLOOKUP(D43,'Lista desplegable'!C$1:D$436,2,FALSE),"") -> SUPERVISOR DE OPERACIONES | F43: 200-11 | G43: HQ | H43: 0-200 | I43: 41,95 | J43: PRESENTE | K43: SI | L43: SI
B44: 3 | C44: 17580584-2 | D44: =IFERROR(VLOOKUP(C44,'Lista desplegable'!B$1:C$436,2,FALSE),"") -> CAMILO FELIPE CRUZ MOLINA | E44: =IFERROR(VLOOKUP(D44,'Lista desplegable'!C$1:D$436,2,FALSE),"") -> SUPERVISOR DE OPERACIONES | F44: 200-11 | G44: HQ | H44: 0-200 | I44: 41,95 | J44: PRESENTE | K44: SI | L44: SI
B45: 4 | C45: 12707776-2 | D45: =IFERROR(VLOOKUP(C45,'Lista desplegable'!B$1:C$436,2,FALSE),"") -> RICARDO DE LAS NIEVES GUTIERREZ FUENTES | E45: =IFERROR(VLOOKUP(D45,'Lista desplegable'!C$1:D$436,2,FALSE),"") -> CHOFER | F45: 200-11 | G45: HQ | H45: 0-200 | I45: 41,95 | J45: PRESENTE | K45: SI | L45: SI
...

Sheet 05-09
G2: DIA
D3: PROYECTO: | E3: CERRO BAYO / CHILE CHICO | G3: 46151
C6: TURNO DIA - B
B7: N° | C7: RUT | D7: NOMBRES Y APELLIDOS | E7: CARGO | F7: MAQUINA | G7: DIAMETRO | H7: ESCALA | I7: METROS | J7: ASISTENCIA | K7: WORKERA ENTRADA | L7: WORKERA SALIDA | M7: OBSERVACIONES
B8: 1 | C8: 44632507-8 | D8: =IFERROR(VLOOKUP(C8,'Lista desplegable'!B$1:C$436,2,FALSE),"") -> ANDREW JAMES WILSON . | E8: =IFERROR(VLOOKUP(D8,'Lista desplegable'!C$1:D$436,2,FALSE),"") -> PERFORISTA | F8: 200-11 | G8: HQ | H8: 0-200 | I8: 34.5 | J8: PRESENTE | M8: NO APLICA FIRMA, EXPATRIADO
B9: 2 | C9: 28935989-3 | D9: =IFERROR(VLOOKUP(C9,'Lista desplegable'!B$1:C$436,2,FALSE),"") -> STEWART PHILLIP WHITEHURST MEJIA | E9: =IFERROR(VLOOKUP(D9,'Lista desplegable'!C$1:D$436,2,FALSE),"") -> PERFORISTA | F9: 200-11 | G9: HQ | H9: 0-200 | I9: 34.5 | J9: PRESENTE | M9: NO APLICA FIRMA, EXPATRIADO
B10: 3 | C10: 15475908-5 | D10: =IFERROR(VLOOKUP(C10,'Lista desplegable'!B$1:C$436,2,FALSE),"") -> ISRAEL AARÓN VERGARA ELGUETA | E10: =IFERROR(VLOOKUP(D10,'Lista desplegable'!C$1:D$436,2,FALSE),"") -> ADMINISTRADOR DE CONTRATO | F10: 200-11 | G10: HQ | H10: 0-200 | I10: 34.5 | J10: PRESENTE | K10: SI | L10: SI
B11: 4 | C11: 18490734-8 | D11: =IFERROR(VLOOKUP(C11,'Lista desplegable'!B$1:C$436,2,FALSE),"") -> SIMONNE DE LA PAZ REYES BATLLE | E11: =IFERROR(VLOOKUP(D11,'Lista desplegable'!C$1:D$436,2,FALSE),"") -> ADMINISTRATIVO DE FAENA | J11: DESCANSO
B12: 5 | C12: 16892085-7 | D12: =IFERROR(VLOOKUP(C12,'Lista desplegable'!B$1:C$436,2,FALSE),"") -> MANUEL ALEJANDRO LISAMBARTH CARABANTES | E12: =IFERROR(VLOOKUP(D12,'Lista desplegable'!C$1:D$436,2,FALSE),"") -> ADMINISTRATIVO DE FAENA | F12: 200-11 | G12: HQ | H12: 0-200 | I12: 34.5 | J12: PRESENTE | K12: SI | L12: SI
B13: 6 | C13: 17697158-4 | D13: =IFERROR(VLOOKUP(C13,'Lista desplegable'!B$1:C$436,2,FALSE),"") -> RODRIGO ANDRES DIAZ INOSTROZA | E13: =IFERROR(VLOOKUP(D13,'Lista desplegable'!C$1:D$436,2,FALSE),"") -> BODEGUERO | F13: 200-11 | G13: HQ | H13: 0-200 | I13: 34.5 | J13: PRESENTE | K13: SI | L13: SI
B14: 7 | C14: 20456853-7 | D14: =IFERROR(VLOOKUP(C14,'Lista desplegable'!B$1:C$436,2,FALSE),"") -> CHRISTIAN DARIEM PIZARRO MUÑOZ | E14: =IFERROR(VLOOKUP(D14,'Lista desplegable'!C$1:D$436,2,FALSE),"") -> SOLDADOR | F14: 200-11 | G14: HQ | H14: 0-200 | I14: 34.5 | J14: PRESENTE | K14: SI | L14: SI
B15: 8 | C15: 17465056-K | D15: =IFERROR(VLOOKUP(C15,'Lista desplegable'!B$1:C$436,2,FALSE),"") -> DANIEL ANDRES ANDRADE AGUILAR | E15: =IFERROR(VLOOKUP(D15,'Lista desplegable'!C$1:D$436,2,FALSE),"") -> MECANICO | F15: 200-11 | G15: HQ | H15: 0-200 | I15: 34.5 | J15: PRESENTE | K15: SI | L15: SI
B16: 9 | C16: 19506189-0 | D16: =IFERROR(VLOOKUP(C16,'Lista desplegable'!B$1:C$436,2,FALSE),"") -> DIEGO NICOLAS GONZALEZ OLIVARES | E16: =IFERROR(VLOOKUP(D16,'Lista desplegable'!C$1:D$436,2,FALSE),"") -> MECANICO | F16: 200-11 | G16: HQ | H16: 0-200 | I16: 34.5 | J16: PRESENTE | K16: SI | L16: SI
B17: 10 | C17: 19518296-5 | D17: =IFERROR(VLOOKUP(C17,'Lista desplegable'!B$1:C$436,2,FALSE),"") -> JORGE ANDRES LICANQUEO PEREZ | E17: =IFERROR(VLOOKUP(D17,'Lista desplegable'!C$1:D$436,2,FALSE),"") -> MECANICO | F17: 200-11 | G17: HQ | H17: 0-200 | I17: 34.5 | J17: PRESENTE | K17: SI | L17: SI
B18: 11 | C18: 16981319-1 | D18: =IFERROR(VLOOKUP(C18,'Lista desplegable'!B$1:C$436,2,FALSE),"") -> MARCOS ANTONIO ALDEA BEROIZA | E18: =IFERROR(VLOOKUP(D18,'Lista desplegable'!C$1:D$436,2,FALSE),"") -> CHOFER | F18: 200-11 | G18: HQ | H18: 0-200 | I18: 34.5 | J18: PRESENTE | K18: SI | L18: SI
B19: 12 | C19: 14400090-0 | D19: =IFERROR(VLOOKUP(C19,'Lista desplegable'!B$1:C$436,2,FALSE),"") -> CARLOS ALBERTO RAMOS VELASQUEZ | E19: =IFERROR(VLOOKUP(D19,'Lista desplegable'!C$1:D$436,2,FALSE),"") -> SUPERVISOR DE OPERACIONES | F19: 200-11 | G19: HQ | H19: 0-200 | I19: 34.5 | J19: PRESENTE | K19: SI | L19: SI
B20: 13 | C20: 15196627-6 | D20: =IFERROR(VLOOKUP(C20,'Lista desplegable'!B$1:C$436,2,FALSE),"") -> NELSON PATRICIO FLORES SANHUEZA | E20: =IFERROR(VLOOKUP(D20,'Lista desplegable'!C$1:D$436,2,FALSE),"") -> PREVENCIONISTA DE RIESGOS | F20: 200-11 | G20: HQ | H20: 0-200 | I20: 34.5 | J20: PRESENTE | K20: SI | L20: SI
B21: 14 | C21: 12218170-7 | D21: =IFERROR(VLOOKUP(C21,'Lista desplegable'!B$1:C$436,2,FALSE),"") -> EDUARDO ANTONIO CASTILLO VALENZUELA | E21: =IFERROR(VLOOKUP(D21,'Lista desplegable'!C$1:D$436,2,FALSE),"") -> PERFORISTA | F21: 200-11 | G21: HQ | H21: 0-200 | I21: 34.5 | J21: PRESENTE | K21: SI | L21: SI
B22: 15 | C22: 19349619-9 | D22: =IFERROR(VLOOKUP(C22,'Lista desplegable'!B$1:C$436,2,FALSE),"") -> JEAN CHARLES CERDA ORREGO | E22: =IFERROR(VLOOKUP(D22,'Lista desplegable'!C$1:D$436,2,FALSE),"") -> AYUDANTE DE PERFORISTA | F22: 200-11 | G22: HQ | H22: 0-200 | I22: 34.5 | J22: PRESENTE | K22: SI | L22: SI
B23: 16 | C23: 16771866-3 | D23: =IFERROR(VLOOKUP(C23,'Lista desplegable'!B$1:C$436,2,FALSE),"") -> OMAR ANDRES ARAYA ZUÑIGA | E23: =IFERROR(VLOOKUP(D23,'Lista desplegable'!C$1:D$436,2,FALSE),"") -> AYUDANTE DE PERFORISTA | F23: 200-11 | G23: HQ | H23: 0-200 | I23: 34.5 | J23: PRESENTE | K23: SI | L23: SI
... B25: 18 | C25: 44599981-4 | D25: =IFERROR(VLOOKUP(C25,'Lista desplegable'!B$1:C$436,2,FALSE),"") -> DENYS SAUL VERGARA TOCAS | E25: =IFERROR(VLOOKUP(D25,'Lista desplegable'!C$1:D$436,2,FALSE),"") -> PERFORISTA | F25: 200-11 | G25: HQ | H25: 0-200 | I25: 34.5 | J25: PRESENTE | K25: SI | L25: SI
B26: 19 | C26: 20460401-0 | D26: =IFERROR(VLOOKUP(C26,'Lista desplegable'!B$1:C$436,2,FALSE),"") -> KEVIN ALEXIS NEYRA CORTES | E26: =IFERROR(VLOOKUP(D26,'Lista desplegable'!C$1:D$436,2,FALSE),"") -> PERFORISTA | F26: 200-13 | G26: HQ | H26: 0-200 | I26: 0 | J26: PRESENTE | K26: SI | L26: SI | M26: CAMBIO DE PLATAFORMA
B27: 20 | C27: 17980395-K | D27: =IFERROR(VLOOKUP(C27,'Lista desplegable'!B$1:C$436,2,FALSE),"") -> PATRICIO RENAN GONZALEZ CABELLO | E27: =IFERROR(VLOOKUP(D27,'Lista desplegable'!C$1:D$436,2,FALSE),"") -> AYUDANTE DE PERFORISTA | F27: 200-13 | G27: HQ | H27: 0-200 | I27: 0 | J27: PRESENTE | K27: SI | L27: SI | M27: CAMBIO DE PLATAFORMA
B28: 21 | C28: 20456931-2 | D28: =IFERROR(VLOOKUP(C28,'Lista desplegable'!B$1:C$436,2,FALSE),"") -> DIEGO BRANCO BARRAZA CHAVEZ | E28: =IFERROR(VLOOKUP(D28,'Lista desplegable'!C$1:D$436,2,FALSE),"") -> AYUDANTE DE PERFORISTA | F28: 200-13 | G28: HQ | H28: 0-200 | I28: 0 | J28: PRESENTE | K28: SI | L28: SI | M28: CAMBIO DE PLATAFORMA
B29: 22 | C29: 20774155-8 | D29: =IFERROR(VLOOKUP(C29,'Lista desplegable'!B$1:C$436,2,FALSE),"") -> OSCAR RODRIGO ARIAS LEIVA | E29: =IFERROR(VLOOKUP(D29,'Lista desplegable'!C$1:D$436,2,FALSE),"") -> AYUDANTE DE PERFORISTA | F29: 200-13 | G29: HQ | H29: 0-200 | I29: 0 | J29: PRESENTE | K29: SI | L29: SI | M29: CAMBIO DE PLATAFORMA
B30: 23 | C30: 11778172-0 | D30: =IFERROR(VLOOKUP(C30,'Lista desplegable'!B$1:C$436,2,FALSE),"") -> ORLANDO PATRICIO CONTRERAS RIOS | E30: =IFERROR(VLOOKUP(D30,'Lista desplegable'!C$1:D$436,2,FALSE),"") -> PERFORISTA | F30: 200-11 | G30: HQ | H30: 0-200 | I30: 34.5 | J30: PRESENTE | K30: SI | L30: SI
B31: 24 | C31: 20037472-K | D31: =IFERROR(VLOOKUP(C31,'Lista desplegable'!B$1:C$436,2,FALSE),"") -> ANGELO GIOVANNI BIZAMA ORELLANA | E31: =IFERROR(VLOOKUP(D31,'Lista desplegable'!C$1:D$436,2,FALSE),"") -> AYUDANTE DE PERFORISTA | J31: OBSERVACIÓN | M31: EN DOMICILIO A LA ESPERA DE SUBIR A FAENA
B32: 25 | C32: 15955871-1 | D32: =IFERROR(VLOOKUP(C32,'Lista desplegable'!B$1:C$436,2,FALSE),"") -> WALTER LISANDRO SALAS MESA | E32: =IFERROR(VLOOKUP(D32,'Lista desplegable'!C$1:D$436,2,FALSE),"") -> PERFORISTA | J32: OBSERVACIÓN | M32: EN DOMICILIO A LA ESPERA DE SUBIR A FAENA
B33: 26 | D33: =IFERROR(VLOOKUP(C33,'Lista desplegable'!B$1:C$436,2,FALSE),"") | E33: =IFERROR(VLOOKUP(D33,'Lista desplegable'!C$1:D$436,2,FALSE),"")
B34: 27 | D34: =IFERROR(VLOOKUP(C34,'Lista desplegable'!B$1:C$436,2,FALSE),"") | E34: =IFERROR(VLOOKUP(D34,'Lista desplegable'!C$1:D$436,2,FALSE),"")
B35: 28 | D35: =IFERROR(VLOOKUP(C35,'Lista desplegable'!B$1:C$436,2,FALSE),"") | E35: =IFERROR(VLOOKUP(D35,'Lista desplegable'!C$1:D$436,2,FALSE),"")
B36: 29 | D36: =IFERROR(VLOOKUP(C36,'Lista desplegable'!B$1:C$436,2,FALSE),"") | E36: =IFERROR(VLOOKUP(D36,'Lista desplegable'!C$1:D$436,2,FALSE),"")
B37: 30 | D37: =IFERROR(VLOOKUP(C37,'Lista desplegable'!B$1:C$436,2,FALSE),"") | E37: =IFERROR(VLOOKUP(D37,'Lista desplegable'!C$1:D$436,2,FALSE),"")
C40: TURNO NOCHE - B
B41: N° | C41: RUT | D41: NOMBRES Y APELLIDOS | E41: CARGO | F41: MAQUINA | G41: DIAMETRO | H41: ESCALA | I41: METROS | J41: ASISTENCIA | K41: WORKERA ENTRADA | L41: WORKERA SALIDA | M41: OBSERVACIONES
B42: 1 | C42: 18494463-4 | D42: =IFERROR(VLOOKUP(C42,'Lista desplegable'!B$1:C$436,2,FALSE),"") -> RAUL ESTEBAN HERNANDEZ PIZARRO | E42: =IFERROR(VLOOKUP(D42,'Lista desplegable'!C$1:D$436,2,FALSE),"") -> PREVENCIONISTA DE RIESGOS | F42: 200-11 | G42: HQ | H42: 0-200 | I42: 28,20 | J42: PRESENTE | K42: SI | L42: SI
B43: 2 | C43: 44599978-4 | D43: =IFERROR(VLOOKUP(C43,'Lista desplegable'!B$1:C$436,2,FALSE),"") -> FRANCISCO PEDRO BORNAZ DELGADO | E43: =IFERROR(VLOOKUP(D43,'Lista desplegable'!C$1:D$436,2,FALSE),"") -> SUPERVISOR DE OPERACIONES | F43: 200-11 | G43: HQ | H43: 0-200 | I43: 28,20 | J43: PRESENTE | K43: SI | L43: SI
B44: 3 | C44: 17580584-2 | D44: =IFERROR(VLOOKUP(C44,'Lista desplegable'!B$1:C$436,2,FALSE),"") -> CAMILO FELIPE CRUZ MOLINA | E44: =IFERROR(VLOOKUP(D44,'Lista desplegable'!C$1:D$436,2,FALSE),"") -> SUPERVISOR DE OPERACIONES | F44: 200-11 | G44: HQ | H44: 0-200 | I44: 28,20 | J44: PRESENTE | K44: SI | L44: SI
B45: 4 | C45: 12707776-2 | D45: =IFERROR(VLOOKUP(C45,'Lista desplegable'!B$1:C$436,2,FALSE),"") -> RICARDO DE LAS NIEVES GUTIERREZ FUENTES | E45: =IFERROR(VLOOKUP(D45,'Lista desplegable'!C$1:D$436,2,FALSE),"") -> CHOFER | F45: 200-11 | G45: HQ | H45: 0-200 | I45: 28,20 | J45: PRESENTE | K45: SI | L45: SI
B46: 5 | C46: 26931695-0 | D46: =IFERROR(VLOOKUP(C46,'Lista desplegable'!B$1:C$436,2,FALSE),"") -> SEBASTIAN GONZALO ROJAS CLARO | E46: =IFERROR(VLOOKUP(D46,'Lista desplegable'!C$1:D$436,2,FALSE),"") -> MECANICO | F46: 200-11 | G46: HQ | H46: 0-200 | I46: 28,20 | J46: PRESENTE | K46: SI | L46: SI
...

Sheet 06-09
G2: DIA
D3: PROYECTO: | E3: CERRO BAYO / CHILE CHICO | G3: 46182
C6: TURNO DIA - B
B7: N° | C7: RUT | D7: NOMBRES Y APELLIDOS | E7: CARGO | F7: MAQUINA | G7: DIAMETRO | H7: ESCALA | I7: METROS | J7: ASISTENCIA | K7: WORKERA ENTRADA | L7: WORKERA SALIDA | M7: OBSERVACIONES
B8: 1 | C8: 44632507-8 | D8: =IFERROR(VLOOKUP(C8,'Lista desplegable'!B$1:C$436,2,FALSE),"") -> ANDREW JAMES WILSON . | E8: =IFERROR(VLOOKUP(D8,'Lista desplegable'!C$1:D$436,2,FALSE),"") -> PERFORISTA | F8: 200-11 | G8: HQ | H8: 0-200 | I8: 2,00 | J8: PRESENTE | M8: NO APLICA FIRMA, EXPATRIADO
C9: 44632507-8 | D9: =IFERROR(VLOOKUP(C9,'Lista desplegable'!B$1:C$436,2,FALSE),"") -> ANDREW JAMES WILSON . | E9: =IFERROR(VLOOKUP(D9,'Lista desplegable'!C$1:D$436,2,FALSE),"") -> PERFORISTA | F9: 200-11 | G9: HQ | H9: 200-400 | I9: 14,00
B10: 2 | C10: 28935989-3 | D10: =IFERROR(VLOOKUP(C10,'Lista desplegable'!B$1:C$436,2,FALSE),"") -> STEWART PHILLIP WHITEHURST MEJIA | E10: =IFERROR(VLOOKUP(D10,'Lista desplegable'!C$1:D$436,2,FALSE),"") -> PERFORISTA | F10: 200-11 | G10: HQ | H10: 0-200 | I10: 2,00 | J10: PRESENTE | M10: NO APLICA FIRMA, EXPATRIADO
C11: 28935989-3 | D11: =IFERROR(VLOOKUP(C11,'Lista desplegable'!B$1:C$436,2,FALSE),"") -> STEWART PHILLIP WHITEHURST MEJIA | E11: =IFERROR(VLOOKUP(D11,'Lista desplegable'!C$1:D$436,2,FALSE),"") -> PERFORISTA | F11: 200-11 | G11: HQ | H11: 200-400 | I11: 14,00
B12: 3 | C12: 15475908-5 | D12: =IFERROR(VLOOKUP(C12,'Lista desplegable'!B$1:C$436,2,FALSE),"") -> ISRAEL AARÓN VERGARA ELGUETA | E12: =IFERROR(VLOOKUP(D12,'Lista desplegable'!C$1:D$436,2,FALSE),"") -> ADMINISTRADOR DE CONTRATO | F12: 200-11 | G12: HQ | H12: 0-200 | I12: 2,00 | J12: PRESENTE | K12: SI | L12: SI
C13: 15475908-5 | D13: =IFERROR(VLOOKUP(C13,'Lista desplegable'!B$1:C$436,2,FALSE),"") -> ISRAEL AARÓN VERGARA ELGUETA | E13: =IFERROR(VLOOKUP(D13,'Lista desplegable'!C$1:D$436,2,FALSE),"") -> ADMINISTRADOR DE CONTRATO | F13: 200-11 | G13: HQ | H13: 200-400 | I13: 14,00
B14: 4 | C14: 18490734-8 | D14: =IFERROR(VLOOKUP(C14,'Lista desplegable'!B$1:C$436,2,FALSE),"") -> SIMONNE DE LA PAZ REYES BATLLE | E14: =IFERROR(VLOOKUP(D14,'Lista desplegable'!C$1:D$436,2,FALSE),"") -> ADMINISTRATIVO DE FAENA | F14: 200-11 | G14: HQ | H14: 0-200 | I14: 2,00 | J14: DESCANSO
C15: 18490734-8 | D15: =IFERROR(VLOOKUP(C15,'Lista desplegable'!B$1:C$436,2,FALSE),"") -> SIMONNE DE LA PAZ REYES BATLLE | E15: =IFERROR(VLOOKUP(D15,'Lista desplegable'!C$1:D$436,2,FALSE),"") -> ADMINISTRATIVO DE FAENA | F15: 200-11 | G15: HQ | H15: 200-400 | I15: 14,00
B16: 5 | C16: 16892085-7 | D16: =IFERROR(VLOOKUP(C16,'Lista desplegable'!B$1:C$436,2,FALSE),"") -> MANUEL ALEJANDRO LISAMBARTH CARABANTES | E16: =IFERROR(VLOOKUP(D16,'Lista desplegable'!C$1:D$436,2,FALSE),"") -> ADMINISTRATIVO DE FAENA | F16: 200-11 | G16: HQ | H16: 0-200 | I16: 2,00 | J16: PRESENTE | K16: SI | L16: SI
C17: 16892085-7 | D17: =IFERROR(VLOOKUP(C17,'Lista desplegable'!B$1:C$436,2,FALSE),"") -> MANUEL ALEJANDRO LISAMBARTH CARABANTES | E17: =IFERROR(VLOOKUP(D17,'Lista desplegable'!C$1:D$436,2,FALSE),"") -> ADMINISTRATIVO DE FAENA | F17: 200-11 | G17: HQ | H17: 200-400 | I17: 14,00
B18: 6 | C18: 17697158-4 | D18: =IFERROR(VLOOKUP(C18,'Lista desplegable'!B$1:C$436,2,FALSE),"") -> RODRIGO ANDRES DIAZ INOSTROZA | E18: =IFERROR(VLOOKUP(D18,'Lista desplegable'!C$1:D$436,2,FALSE),"") -> BODEGUERO | F18: 200-11 | G18: HQ | H18: 0-200 | I18: 2,00 | J18: PRESENTE | K18: SI | L18: SI
C19: 17697158-4 | D19: =IFERROR(VLOOKUP(C19,'Lista desplegable'!B$1:C$436,2,FALSE),"") -> RODRIGO ANDRES DIAZ INOSTROZA | E19: =IFERROR(VLOOKUP(D19,'Lista desplegable'!C$1:D$436,2,FALSE),"") -> BODEGUERO | F19: 200-11 | G19: HQ | H19: 200-400 | I19: 14,00
B20: 7 | C20: 20456853-7 | D20: =IFERROR(VLOOKUP(C20,'Lista desplegable'!B$1:C$436,2,FALSE),"") -> CHRISTIAN DARIEM PIZARRO MUÑOZ | E20: =IFERROR(VLOOKUP(D20,'Lista desplegable'!C$1:D$436,2,FALSE),"") -> SOLDADOR | F20: 200-11 | G20: HQ | H20: 0-200 | I20: 2,00 | J20: PRESENTE | K20: SI | L20: SI
C21: 20456853-7 | D21: =IFERROR(VLOOKUP(C21,'Lista desplegable'!B$1:C$436,2,FALSE),"") -> CHRISTIAN DARIEM PIZARRO MUÑOZ | E21: =IFERROR(VLOOKUP(D21,'Lista desplegable'!C$1:D$436,2,FALSE),"") -> SOLDADOR | F21: 200-11 | G21: HQ | H21: 200-400 | I21: 14,00
B22: 8 | C22: 17465056-K | D22: =IFERROR(VLOOKUP(C22,'Lista desplegable'!B$1:C$436,2,FALSE),"") -> DANIEL ANDRES ANDRADE AGUILAR | E22: =IFERROR(VLOOKUP(D22,'Lista desplegable'!C$1:D$436,2,FALSE),"") -> MECANICO | F22: 200-11 | G22: HQ | H22: 0-200 | I22: 2,00 | J22: PRESENTE | K22: SI | L22: SI
C23: 17465056-K | D23: =IFERROR(VLOOKUP(C23,'Lista desplegable'!B$1:C$436,2,FALSE),"") -> DANIEL ANDRES ANDRADE AGUILAR | E23: =IFERROR(VLOOKUP(D23,'Lista desplegable'!C$1:D$436,2,FALSE),"") -> MECANICO | F23: 200-11 | G23: HQ | H23: 200-400 | I23: 14,00
B24: 9 | C24: 19506189-0 | D24: =IFERROR(VLOOKUP(C24,'Lista desplegable'!B$1:C$436,2,FALSE),"") -> DIEGO NICOLAS GONZALEZ OLIVARES | E24: =IFERROR(VLOOKUP(D24,'Lista desplegable'!C$1:D$436,2,FALSE),"") -> MECANICO | F24: 200-11 | G24: HQ | H24: 0-200 | I24: 2,00 | J24: PRESENTE | K24: SI | L24: SI
C25: 19506189-0 | D25: =IFERROR(VLOOKUP(C25,'Lista desplegable'!B$1:C$436,2,FALSE),"") -> DIEGO NICOLAS GONZALEZ OLIVARES | E25: =IFERROR(VLOOKUP(D25,'Lista desplegable'!C$1:D$436,2,FALSE),"") -> MECANICO | F25: 200-11 | G25: HQ | H25: 200-400 | I25: 14,00
B26: 10 | C26: 19518296-5 | D26: =IFERROR(VLOOKUP(C26,'Lista desplegable'!B$1:C$436,2,FALSE),"") -> JORGE ANDRES LICANQUEO PEREZ | E26: =IFERROR(VLOOKUP(D26,'Lista desplegable'!C$1:D$436,2,FALSE),"") -> MECANICO | F26: 200-11 | G26: HQ | H26: 0-200 | I26: 2,00 | J26: PRESENTE | K26: SI | L26: SI
C27: 19518296-5 | D27: =IFERROR(VLOOKUP(C27,'Lista desplegable'!B$1:C$436,2,FALSE),"") -> JORGE ANDRES LICANQUEO PEREZ | E27: =IFERROR(VLOOKUP(D27,'Lista desplegable'!C$1:D$436,2,FALSE),"") -> MECANICO | F27: 200-11 | G27: HQ | H27: 200-400 | I27: 14,00
B28: 11 | C28: 16981319-1 | D28: =IFERROR(VLOOKUP(C28,'Lista desplegable'!B$1:C$436,2,FALSE),"") -> MARCOS ANTONIO ALDEA BEROIZA | E28: =IFERROR(VLOOKUP(D28,'Lista desplegable'!C$1:D$436,2,FALSE),"") -> CHOFER | F28: 200-11 | G28: HQ | H28: 0-200 | I28: 2,00 | J28: PRESENTE | K28: SI | L28: SI
C29: 16981319-1 | D29: =IFERROR(VLOOKUP(C29,'Lista desplegable'!B$1:C$436,2,FALSE),"") -> MARCOS ANTONIO ALDEA BEROIZA | E29: =IFERROR(VLOOKUP(D29,'Lista desplegable'!C$1:D$436,2,FALSE),"") -> CHOFER | F29: 200-11 | G29: HQ | H29: 200-400 | I29: 14,00
B30: 12 | C30: 14400090-0 | D30: =IFERROR(VLOOKUP(C30,'Lista desplegable'!B$1:C$436,2,FALSE),"") -> CARLOS ALBERTO RAMOS VELASQUEZ | E30: =IFERROR(VLOOKUP(D30,'Lista desplegable'!C$1:D$436,2,FALSE),"") -> SUPERVISOR DE OPERACIONES | F30: 200-11 | G30: HQ | H30: 0-200 | I30: 2,00 | J30: PRESENTE | K30: SI | L30: SI
C31: 14400090-0 | D31: =IFERROR(VLOOKUP(C31,'Lista desplegable'!B$1:C$436,2,FALSE),"") -> CARLOS ALBERTO RAMOS VELASQUEZ | E31: =IFERROR(VLOOKUP(D31,'Lista desplegable'!C$1:D$436,2,FALSE),"") -> SUPERVISOR DE OPERACIONES | F31: 200-11 | G31: HQ | H31: 200-400 | I31: 14,00
B32: 13 | C32: 15196627-6 | D32: =IFERROR(VLOOKUP(C32,'Lista desplegable'!B$1:C$436,2,FALSE),"") -> NELSON PATRICIO FLORES SANHUEZA | E32: =IFERROR(VLOOKUP(D32,'Lista desplegable'!C$1:D$436,2,FALSE),"") -> PREVENCIONISTA DE RIESGOS | F32: 200-11 | G32: HQ | H32: 0-200 | I32: 2,00 | J32: PRESENTE | K32: SI | L32: SI
