Workbook

Sheet 01-08-2026
B1: PROYECTO: | C1: LA COIPA | F1: 1 | G1: 8 | H1: 2026 | J1: =IF($B1="","",IF(COUNTIFS('Ayuda Workera'!$C$5:$C$3004,UPPER(SUBSTITUTE($B1,".","")),'Ayuda Workera'!$B$5:$B$3004,DATE($H$1,$G$1,$F$1),'Marcación Workera'!$H$5:$H$3004,"Entrada")>0,"SI","NO")) -> NO | K1: =IF($B1="","",IF(COUNTIFS('Ayuda Workera'!$C$5:$C$3004,UPPER(SUBSTITUTE($B1,".","")),'Ayuda Workera'!$B$5:$B$3004,DATE($H$1,$G$1,$F$1),'Marcación Workera'!$H$5:$H$3004,"Salida")>0,"SI","NO")) -> NO
F2: DIA | G2: MES | H2: AÑO
A4: TURNO A DÍA
A5: N° | B5: RUT | C5: NOMBRE COMPLETO | D5: CARGO | E5: MAQUINA | F5: DIAMETRO | G5: ESCALA | H5: METROS | I5: H. EXTRAS | J5: workera entrada | K5: workera salida | L5: MOTIVO HORAS EXTRAS
A6: 1 | B6: =IFERROR(INDEX(Dotación!$A$5:$A$160,MATCH($C6,Dotación!$B$5:$B$160,0)),"11384027-7") -> 11384027-7 | C6: Alex Mario Morales Antiquera | D6: JEFE DE FAENA | E6: EDM-47K2 | F6: PQ | G6: 500-1000 | H6: 15,00 | J6: =IF($B6="","",IF(COUNTIFS('Ayuda Workera'!$C$5:$C$3004,UPPER(SUBSTITUTE($B6,".","")),'Ayuda Workera'!$B$5:$B$3004,DATE($H$1,$G$1,$F$1),'Marcación Workera'!$H$5:$H$3004,"Entrada")>0,"SI","NO")) -> NO | K6: =IF($B6="","",IF(COUNTIFS('Ayuda Workera'!$C$5:$C$3004,UPPER(SUBSTITUTE($B6,".","")),'Ayuda Workera'!$B$5:$B$3004,DATE($H$1,$G$1,$F$1),'Marcación Workera'!$H$5:$H$3004,"Salida")>0,"SI","NO")) -> NO
A7: 2 | B7: =IFERROR(INDEX(Dotación!$A$5:$A$160,MATCH($C7,Dotación!$B$5:$B$160,0)),"18352777-0") -> 18352777-0 | C7: Nora Alexandra Salas Rojas | D7: HSEC | E7: EDM-47K2 | F7: PQ | G7: 500-1000 | H7: 15,00 | J7: =IF($B7="","",IF(COUNTIFS('Ayuda Workera'!$C$5:$C$3004,UPPER(SUBSTITUTE($B7,".","")),'Ayuda Workera'!$B$5:$B$3004,DATE($H$1,$G$1,$F$1),'Marcación Workera'!$H$5:$H$3004,"Entrada")>0,"SI","NO")) -> NO | K7: =IF($B7="","",IF(COUNTIFS('Ayuda Workera'!$C$5:$C$3004,UPPER(SUBSTITUTE($B7,".","")),'Ayuda Workera'!$B$5:$B$3004,DATE($H$1,$G$1,$F$1),'Marcación Workera'!$H$5:$H$3004,"Salida")>0,"SI","NO")) -> NO
A8: 3 | B8: =IFERROR(INDEX(Dotación!$A$5:$A$160,MATCH($C8,Dotación!$B$5:$B$160,0)),"21516063-7") -> 21516063-7 | C8: Nataly Antonia Salas Escobar | D8: ADMINISTRATIVO | E8: EDM-47K2 | F8: PQ | G8: 500-1000 | H8: 15,00 | J8: =IF($B8="","",IF(COUNTIFS('Ayuda Workera'!$C$5:$C$3004,UPPER(SUBSTITUTE($B8,".","")),'Ayuda Workera'!$B$5:$B$3004,DATE($H$1,$G$1,$F$1),'Marcación Workera'!$H$5:$H$3004,"Entrada")>0,"SI","NO")) -> SI | K8: =IF($B8="","",IF(COUNTIFS('Ayuda Workera'!$C$5:$C$3004,UPPER(SUBSTITUTE($B8,".","")),'Ayuda Workera'!$B$5:$B$3004,DATE($H$1,$G$1,$F$1),'Marcación Workera'!$H$5:$H$3004,"Salida")>0,"SI","NO")) -> NO
A9: 4 | B9: =IFERROR(INDEX(Dotación!$A$5:$A$160,MATCH($C9,Dotación!$B$5:$B$160,0)),"14043656-9") -> 14043656-9 | C9: Leonardo Andres Meneses Arredondo | D9: SUPERVISOR | E9: EDM-47K2 | F9: PQ | G9: 500-1000 | H9: 15,00 | J9: =IF($B9="","",IF(COUNTIFS('Ayuda Workera'!$C$5:$C$3004,UPPER(SUBSTITUTE($B9,".","")),'Ayuda Workera'!$B$5:$B$3004,DATE($H$1,$G$1,$F$1),'Marcación Workera'!$H$5:$H$3004,"Entrada")>0,"SI","NO")) -> SI | K9: =IF($B9="","",IF(COUNTIFS('Ayuda Workera'!$C$5:$C$3004,UPPER(SUBSTITUTE($B9,".","")),'Ayuda Workera'!$B$5:$B$3004,DATE($H$1,$G$1,$F$1),'Marcación Workera'!$H$5:$H$3004,"Salida")>0,"SI","NO")) -> SI
A10: 5 | B10: =IFERROR(INDEX(Dotación!$A$5:$A$160,MATCH($C10,Dotación!$B$5:$B$160,0)),"18889617-0") -> 18889617-0 | C10: Leonel Guillermo Campusano Dubo | D10: AYUDANTE | E10: EDM-47K2 | F10: PQ | G10: 500-1000 | H10: 15,00 | J10: =IF($B10="","",IF(COUNTIFS('Ayuda Workera'!$C$5:$C$3004,UPPER(SUBSTITUTE($B10,".","")),'Ayuda Workera'!$B$5:$B$3004,DATE($H$1,$G$1,$F$1),'Marcación Workera'!$H$5:$H$3004,"Entrada")>0,"SI","NO")) -> SI | K10: =IF($B10="","",IF(COUNTIFS('Ayuda Workera'!$C$5:$C$3004,UPPER(SUBSTITUTE($B10,".","")),'Ayuda Workera'!$B$5:$B$3004,DATE($H$1,$G$1,$F$1),'Marcación Workera'!$H$5:$H$3004,"Salida")>0,"SI","NO")) -> NO
A11: 6 | B11: =IFERROR(INDEX(Dotación!$A$5:$A$160,MATCH($C11,Dotación!$B$5:$B$160,0)),"16.706.064-1") -> 16.706.064-1 | C11: Victor Manuel Mondaca Vega | D11: AYUDANTE | E11: EDM-47K2 | F11: PQ | G11: 500-1000 | H11: 15,00 | J11: =IF($B11="","",IF(COUNTIFS('Ayuda Workera'!$C$5:$C$3004,UPPER(SUBSTITUTE($B11,".","")),'Ayuda Workera'!$B$5:$B$3004,DATE($H$1,$G$1,$F$1),'Marcación Workera'!$H$5:$H$3004,"Entrada")>0,"SI","NO")) -> SI | K11: =IF($B11="","",IF(COUNTIFS('Ayuda Workera'!$C$5:$C$3004,UPPER(SUBSTITUTE($B11,".","")),'Ayuda Workera'!$B$5:$B$3004,DATE($H$1,$G$1,$F$1),'Marcación Workera'!$H$5:$H$3004,"Salida")>0,"SI","NO")) -> NO
A12: 7 | B12: =IFERROR(INDEX(Dotación!$A$5:$A$160,MATCH($C12,Dotación!$B$5:$B$160,0)),"11508866-1") -> 11508866-1 | C12: William Hernan Alvares Trujillo | D12: SOLDADOR | E12: EDM-47K2 | F12: PQ | G12: 500-1000 | H12: 15,00 | J12: =IF($B12="","",IF(COUNTIFS('Ayuda Workera'!$C$5:$C$3004,UPPER(SUBSTITUTE($B12,".","")),'Ayuda Workera'!$B$5:$B$3004,DATE($H$1,$G$1,$F$1),'Marcación Workera'!$H$5:$H$3004,"Entrada")>0,"SI","NO")) -> SI | K12: =IF($B12="","",IF(COUNTIFS('Ayuda Workera'!$C$5:$C$3004,UPPER(SUBSTITUTE($B12,".","")),'Ayuda Workera'!$B$5:$B$3004,DATE($H$1,$G$1,$F$1),'Marcación Workera'!$H$5:$H$3004,"Salida")>0,"SI","NO")) -> NO
A13: 8 | B13: =IFERROR(INDEX(Dotación!$A$5:$A$160,MATCH($C13,Dotación!$B$5:$B$160,0)),"13855440-6") -> 13855440-6 | C13: Paolo Alejandro Manriquez Silva | D13: BODEGUERO | E13: EDM-47K2 | F13: PQ | G13: 500-1000 | H13: 15,00 | J13: =IF($B13="","",IF(COUNTIFS('Ayuda Workera'!$C$5:$C$3004,UPPER(SUBSTITUTE($B13,".","")),'Ayuda Workera'!$B$5:$B$3004,DATE($H$1,$G$1,$F$1),'Marcación Workera'!$H$5:$H$3004,"Entrada")>0,"SI","NO")) -> SI | K13: =IF($B13="","",IF(COUNTIFS('Ayuda Workera'!$C$5:$C$3004,UPPER(SUBSTITUTE($B13,".","")),'Ayuda Workera'!$B$5:$B$3004,DATE($H$1,$G$1,$F$1),'Marcación Workera'!$H$5:$H$3004,"Salida")>0,"SI","NO")) -> NO
A14: 9 | B14: =IFERROR(INDEX(Dotación!$A$5:$A$160,MATCH($C14,Dotación!$B$5:$B$160,0)),"12814487-0") -> 12814487-0 | C14: Walter del Carmen Pizarro Alvarez | D14: CHOFER | E14: EDM-47K2 | F14: PQ | G14: 500-1000 | H14: 15,00 | J14: =IF($B14="","",IF(COUNTIFS('Ayuda Workera'!$C$5:$C$3004,UPPER(SUBSTITUTE($B14,".","")),'Ayuda Workera'!$B$5:$B$3004,DATE($H$1,$G$1,$F$1),'Marcación Workera'!$H$5:$H$3004,"Entrada")>0,"SI","NO")) -> NO | K14: =IF($B14="","",IF(COUNTIFS('Ayuda Workera'!$C$5:$C$3004,UPPER(SUBSTITUTE($B14,".","")),'Ayuda Workera'!$B$5:$B$3004,DATE($H$1,$G$1,$F$1),'Marcación Workera'!$H$5:$H$3004,"Salida")>0,"SI","NO")) -> NO
A15: 10 | B15: =IFERROR(INDEX(Dotación!$A$5:$A$160,MATCH($C15,Dotación!$B$5:$B$160,0)),"21254681-K") -> 21254681-K | C15: Jorge Erikson Durand Ruiz | D15: MECÁNICO | E15: EDM-47K2 | F15: PQ | G15: 500-1000 | H15: 15,00 | J15: =IF($B15="","",IF(COUNTIFS('Ayuda Workera'!$C$5:$C$3004,UPPER(SUBSTITUTE($B15,".","")),'Ayuda Workera'!$B$5:$B$3004,DATE($H$1,$G$1,$F$1),'Marcación Workera'!$H$5:$H$3004,"Entrada")>0,"SI","NO")) -> NO | K15: =IF($B15="","",IF(COUNTIFS('Ayuda Workera'!$C$5:$C$3004,UPPER(SUBSTITUTE($B15,".","")),'Ayuda Workera'!$B$5:$B$3004,DATE($H$1,$G$1,$F$1),'Marcación Workera'!$H$5:$H$3004,"Salida")>0,"SI","NO")) -> NO
A16: 11 | B16: =IFERROR(INDEX(Dotación!$A$5:$A$160,MATCH($C16,Dotación!$B$5:$B$160,0)),"17805184-9") -> 17805184-9 | C16: Benjamin Josafatt Espinoza Uribe | D16: CHOFER | E16: EDM-47K2 | F16: PQ | G16: 500-1000 | H16: 15,00 | J16: =IF($B16="","",IF(COUNTIFS('Ayuda Workera'!$C$5:$C$3004,UPPER(SUBSTITUTE($B16,".","")),'Ayuda Workera'!$B$5:$B$3004,DATE($H$1,$G$1,$F$1),'Marcación Workera'!$H$5:$H$3004,"Entrada")>0,"SI","NO")) -> SI | K16: =IF($B16="","",IF(COUNTIFS('Ayuda Workera'!$C$5:$C$3004,UPPER(SUBSTITUTE($B16,".","")),'Ayuda Workera'!$B$5:$B$3004,DATE($H$1,$G$1,$F$1),'Marcación Workera'!$H$5:$H$3004,"Salida")>0,"SI","NO")) -> SI
A17: 12 | B17: =IFERROR(INDEX(Dotación!$A$5:$A$160,MATCH($C17,Dotación!$B$5:$B$160,0)),"23868099-9") -> 23868099-9 | C17: Jorge Armando Tinoco Ospino | D17: CHOFER TRADUCTOR | E17: EDM-47K2 | F17: PQ | G17: 500-1000 | H17: 15,00 | J17: =IF($B17="","",IF(COUNTIFS('Ayuda Workera'!$C$5:$C$3004,UPPER(SUBSTITUTE($B17,".","")),'Ayuda Workera'!$B$5:$B$3004,DATE($H$1,$G$1,$F$1),'Marcación Workera'!$H$5:$H$3004,"Entrada")>0,"SI","NO")) -> SI | K17: =IF($B17="","",IF(COUNTIFS('Ayuda Workera'!$C$5:$C$3004,UPPER(SUBSTITUTE($B17,".","")),'Ayuda Workera'!$B$5:$B$3004,DATE($H$1,$G$1,$F$1),'Marcación Workera'!$H$5:$H$3004,"Salida")>0,"SI","NO")) -> SI
A18: 13 | B18: =IFERROR(INDEX(Dotación!$A$5:$A$160,MATCH($C18,Dotación!$B$5:$B$160,0)),"4500989-0") -> 4500989-0 | C18: Jason Fletcher | D18: GERENTE TECNICO | E18: EDM-47K2 | F18: PQ | G18: 500-1000 | H18: 15,00 | J18: =IF($B18="","",IF(COUNTIFS('Ayuda Workera'!$C$5:$C$3004,UPPER(SUBSTITUTE($B18,".","")),'Ayuda Workera'!$B$5:$B$3004,DATE($H$1,$G$1,$F$1),'Marcación Workera'!$H$5:$H$3004,"Entrada")>0,"SI","NO")) -> NO | K18: =IF($B18="","",IF(COUNTIFS('Ayuda Workera'!$C$5:$C$3004,UPPER(SUBSTITUTE($B18,".","")),'Ayuda Workera'!$B$5:$B$3004,DATE($H$1,$G$1,$F$1),'Marcación Workera'!$H$5:$H$3004,"Salida")>0,"SI","NO")) -> NO
A19: 14 | B19: =IFERROR(INDEX(Dotación!$A$5:$A$160,MATCH($C19,Dotación!$B$5:$B$160,0)),"17626968-5") -> 17626968-5 | C19: Mauricio Enrique Tapia Carvajal | D19: PERFORISTA BU | E19: EDM-47K2 | F19: PQ | G19: 500-1000 | H19: 15,00 | J19: =IF($B19="","",IF(COUNTIFS('Ayuda Workera'!$C$5:$C$3004,UPPER(SUBSTITUTE($B19,".","")),'Ayuda Workera'!$B$5:$B$3004,DATE($H$1,$G$1,$F$1),'Marcación Workera'!$H$5:$H$3004,"Entrada")>0,"SI","NO")) -> NO | K19: =IF($B19="","",IF(COUNTIFS('Ayuda Workera'!$C$5:$C$3004,UPPER(SUBSTITUTE($B19,".","")),'Ayuda Workera'!$B$5:$B$3004,DATE($H$1,$G$1,$F$1),'Marcación Workera'!$H$5:$H$3004,"Salida")>0,"SI","NO")) -> NO
A20: 15 | B20: =IFERROR(INDEX(Dotación!$A$5:$A$160,MATCH($C20,Dotación!$B$5:$B$160,0)),"28683244-K") -> 28683244-K | C20: Ariunbold Tsogkhorkhoi | D20: PERFORISTA | E20: EDM-47K2 | F20: PQ | G20: 500-1000 | H20: 15,00 | J20: =IF($B20="","",IF(COUNTIFS('Ayuda Workera'!$C$5:$C$3004,UPPER(SUBSTITUTE($B20,".","")),'Ayuda Workera'!$B$5:$B$3004,DATE($H$1,$G$1,$F$1),'Marcación Workera'!$H$5:$H$3004,"Entrada")>0,"SI","NO")) -> NO | K20: =IF($B20="","",IF(COUNTIFS('Ayuda Workera'!$C$5:$C$3004,UPPER(SUBSTITUTE($B20,".","")),'Ayuda Workera'!$B$5:$B$3004,DATE($H$1,$G$1,$F$1),'Marcación Workera'!$H$5:$H$3004,"Salida")>0,"SI","NO")) -> NO
A21: 16 | B21: =IFERROR(INDEX(Dotación!$A$5:$A$160,MATCH($C21,Dotación!$B$5:$B$160,0)),"19949787-1") -> 19949787-1 | C21: Fabian Patricio Cabrera Godoy | D21: AYUDANTE | E21: EDM-47K2 | F21: PQ | G21: 500-1000 | H21: 15,00 | J21: =IF($B21="","",IF(COUNTIFS('Ayuda Workera'!$C$5:$C$3004,UPPER(SUBSTITUTE($B21,".","")),'Ayuda Workera'!$B$5:$B$3004,DATE($H$1,$G$1,$F$1),'Marcación Workera'!$H$5:$H$3004,"Entrada")>0,"SI","NO")) -> SI | K21: =IF($B21="","",IF(COUNTIFS('Ayuda Workera'!$C$5:$C$3004,UPPER(SUBSTITUTE($B21,".","")),'Ayuda Workera'!$B$5:$B$3004,DATE($H$1,$G$1,$F$1),'Marcación Workera'!$H$5:$H$3004,"Salida")>0,"SI","NO")) -> NO
A23: TURNO NOCHE
A24: N° | B24: RUT | C24: NOMBRE COMPLETO | D24: CARGO | E24: MAQUINA | F24: DIAMETRO | G24: ESCALA | H24: METROS | I24: H. EXTRAS | J24: workera entrada | K24: workera salida | L24: MOTIVO HORAS EXTRAS
A25: 1 | B25: =IFERROR(INDEX(Dotación!$A$5:$A$160,MATCH($C25,Dotación!$B$5:$B$160,0)),"15.814.058-6") -> 15.814.058-6 | C25: Ulinson Diaz Cortes | D25: SUPERVISOR | E25: EDM-47K2 | F25: PQ | G25: 500-1000 | H25: 6,00 | J25: =IF($B25="","",IF(COUNTIFS('Ayuda Workera'!$C$5:$C$3004,UPPER(SUBSTITUTE($B25,".","")),'Ayuda Workera'!$B$5:$B$3004,DATE($H$1,$G$1,$F$1),'Marcación Workera'!$H$5:$H$3004,"Entrada")>0,"SI","NO")) -> NO | K25: =IF($B25="","",IF(COUNTIFS('Ayuda Workera'!$C$5:$C$3004,UPPER(SUBSTITUTE($B25,".","")),'Ayuda Workera'!$B$5:$B$3004,DATE($H$1,$G$1,$F$1),'Marcación Workera'!$H$5:$H$3004,"Salida")>0,"SI","NO")) -> SI
A26: 2 | B26: =IFERROR(INDEX(Dotación!$A$5:$A$160,MATCH($C26,Dotación!$B$5:$B$160,0)),"16188552-5") -> 16188552-5 | C26: Rodrigo Alejandro Flores Zepeda | D26: AYUDANTE | E26: EDM-47K2 | F26: PQ | G26: 500-1000 | H26: 6,00 | J26: =IF($B26="","",IF(COUNTIFS('Ayuda Workera'!$C$5:$C$3004,UPPER(SUBSTITUTE($B26,".","")),'Ayuda Workera'!$B$5:$B$3004,DATE($H$1,$G$1,$F$1),'Marcación Workera'!$H$5:$H$3004,"Entrada")>0,"SI","NO")) -> NO | K26: =IF($B26="","",IF(COUNTIFS('Ayuda Workera'!$C$5:$C$3004,UPPER(SUBSTITUTE($B26,".","")),'Ayuda Workera'!$B$5:$B$3004,DATE($H$1,$G$1,$F$1),'Marcación Workera'!$H$5:$H$3004,"Salida")>0,"SI","NO")) -> SI
A27: 3 | B27: =IFERROR(INDEX(Dotación!$A$5:$A$160,MATCH($C27,Dotación!$B$5:$B$160,0)),"20718093-9") -> 20718093-9 | C27: Ignacio Alejandro Robles Barrios | D27: AYUDANTE | E27: EDM-47K2 | F27: PQ | G27: 500-1000 | H27: 6,00 | J27: =IF($B27="","",IF(COUNTIFS('Ayuda Workera'!$C$5:$C$3004,UPPER(SUBSTITUTE($B27,".","")),'Ayuda Workera'!$B$5:$B$3004,DATE($H$1,$G$1,$F$1),'Marcación Workera'!$H$5:$H$3004,"Entrada")>0,"SI","NO")) -> NO | K27: =IF($B27="","",IF(COUNTIFS('Ayuda Workera'!$C$5:$C$3004,UPPER(SUBSTITUTE($B27,".","")),'Ayuda Workera'!$B$5:$B$3004,DATE($H$1,$G$1,$F$1),'Marcación Workera'!$H$5:$H$3004,"Salida")>0,"SI","NO")) -> SI
A28: 4 | B28: =IFERROR(INDEX(Dotación!$A$5:$A$160,MATCH($C28,Dotación!$B$5:$B$160,0)),"17643998-k") -> 17643998-k | C28: Benigno Eduardo Paez Meneses | D28: CHOFER | E28: EDM-47K2 | F28: PQ | G28: 500-1000 | H28: 6,00 | J28: =IF($B28="","",IF(COUNTIFS('Ayuda Workera'!$C$5:$C$3004,UPPER(SUBSTITUTE($B28,".","")),'Ayuda Workera'!$B$5:$B$3004,DATE($H$1,$G$1,$F$1),'Marcación Workera'!$H$5:$H$3004,"Entrada")>0,"SI","NO")) -> NO | K28: =IF($B28="","",IF(COUNTIFS('Ayuda Workera'!$C$5:$C$3004,UPPER(SUBSTITUTE($B28,".","")),'Ayuda Workera'!$B$5:$B$3004,DATE($H$1,$G$1,$F$1),'Marcación Workera'!$H$5:$H$3004,"Salida")>0,"SI","NO")) -> SI
A29: 5 | B29: =IFERROR(INDEX(Dotación!$A$5:$A$160,MATCH($C29,Dotación!$B$5:$B$160,0)),"15831074-0") -> 15831074-0 | C29: Estefania Constanza Naeter Quiroz | D29: CONDUCTOR TRADUCTOR | E29: EDM-47K2 | F29: PQ | G29: 500-1000 | H29: 6,00 | J29: =IF($B29="","",IF(COUNTIFS('Ayuda Workera'!$C$5:$C$3004,UPPER(SUBSTITUTE($B29,".","")),'Ayuda Workera'!$B$5:$B$3004,DATE($H$1,$G$1,$F$1),'Marcación Workera'!$H$5:$H$3004,"Entrada")>0,"SI","NO")) -> NO | K29: =IF($B29="","",IF(COUNTIFS('Ayuda Workera'!$C$5:$C$3004,UPPER(SUBSTITUTE($B29,".","")),'Ayuda Workera'!$B$5:$B$3004,DATE($H$1,$G$1,$F$1),'Marcación Workera'!$H$5:$H$3004,"Salida")>0,"SI","NO")) -> SI
A30: 6 | B30: =IFERROR(INDEX(Dotación!$A$5:$A$160,MATCH($C30,Dotación!$B$5:$B$160,0)),"14594999-8") -> 14594999-8 | C30: Roberto Mario Vargas Rodriguez | D30: MECANICO | E30: EDM-47K2 | F30: PQ | G30: 500-1000 | H30: 6,00 | J30: =IF($B30="","",IF(COUNTIFS('Ayuda Workera'!$C$5:$C$3004,UPPER(SUBSTITUTE($B30,".","")),'Ayuda Workera'!$B$5:$B$3004,DATE($H$1,$G$1,$F$1),'Marcación Workera'!$H$5:$H$3004,"Entrada")>0,"SI","NO")) -> NO | K30: =IF($B30="","",IF(COUNTIFS('Ayuda Workera'!$C$5:$C$3004,UPPER(SUBSTITUTE($B30,".","")),'Ayuda Workera'!$B$5:$B$3004,DATE($H$1,$G$1,$F$1),'Marcación Workera'!$H$5:$H$3004,"Salida")>0,"SI","NO")) -> NO
A31: 7 | B31: =IFERROR(INDEX(Dotación!$A$5:$A$160,MATCH($C31,Dotación!$B$5:$B$160,0)),"4.500.919-K") -> 4.500.919-K | C31: GANTSOOJ KHISHIGBAYAR | D31: PERFORISTA | E31: EDM-47K2 | F31: PQ | G31: 500-1000 | H31: 6,00 | J31: =IF($B31="","",IF(COUNTIFS('Ayuda Workera'!$C$5:$C$3004,UPPER(SUBSTITUTE($B31,".","")),'Ayuda Workera'!$B$5:$B$3004,DATE($H$1,$G$1,$F$1),'Marcación Workera'!$H$5:$H$3004,"Entrada")>0,"SI","NO")) -> NO | K31: =IF($B31="","",IF(COUNTIFS('Ayuda Workera'!$C$5:$C$3004,UPPER(SUBSTITUTE($B31,".","")),'Ayuda Workera'!$B$5:$B$3004,DATE($H$1,$G$1,$F$1),'Marcación Workera'!$H$5:$H$3004,"Salida")>0,"SI","NO")) -> NO

Sheet 02-08-2026
B1: PROYECTO: | C1: LA COIPA | F1: 2 | G1: 8 | H1: 2026 | J1: =IF($B1="","",IF(COUNTIFS('Ayuda Workera'!$C$5:$C$3004,UPPER(SUBSTITUTE($B1,".","")),'Ayuda Workera'!$B$5:$B$3004,DATE($H$1,$G$1,$F$1),'Marcación Workera'!$H$5:$H$3004,"Entrada")>0,"SI","NO")) -> NO | K1: =IF($B1="","",IF(COUNTIFS('Ayuda Workera'!$C$5:$C$3004,UPPER(SUBSTITUTE($B1,".","")),'Ayuda Workera'!$B$5:$B$3004,DATE($H$1,$G$1,$F$1),'Marcación Workera'!$H$5:$H$3004,"Salida")>0,"SI","NO")) -> NO
F2: DIA | G2: MES | H2: AÑO
A4: TURNO A DÍA
A5: N° | B5: RUT | C5: NOMBRE COMPLETO | D5: CARGO | E5: MAQUINA | F5: DIAMETRO | G5: ESCALA | H5: METROS | I5: H. EXTRAS | J5: workera entrada | K5: workera salida | L5: MOTIVO HORAS EXTRAS
A6: 1 | B6: =IFERROR(INDEX(Dotación!$A$5:$A$160,MATCH($C6,Dotación!$B$5:$B$160,0)),"11384027-7") -> 11384027-7 | C6: Alex Mario Morales Antiquera | D6: JEFE DE FAENA | E6: EDM-47K2 | F6: PQ | G6: 500-1000 | H6: 14,00 | J6: =IF($B6="","",IF(COUNTIFS('Ayuda Workera'!$C$5:$C$3004,UPPER(SUBSTITUTE($B6,".","")),'Ayuda Workera'!$B$5:$B$3004,DATE($H$1,$G$1,$F$1),'Marcación Workera'!$H$5:$H$3004,"Entrada")>0,"SI","NO")) -> NO | K6: =IF($B6="","",IF(COUNTIFS('Ayuda Workera'!$C$5:$C$3004,UPPER(SUBSTITUTE($B6,".","")),'Ayuda Workera'!$B$5:$B$3004,DATE($H$1,$G$1,$F$1),'Marcación Workera'!$H$5:$H$3004,"Salida")>0,"SI","NO")) -> NO
A7: 2 | B7: =IFERROR(INDEX(Dotación!$A$5:$A$160,MATCH($C7,Dotación!$B$5:$B$160,0)),"18352777-0") -> 18352777-0 | C7: Nora Alexandra Salas Rojas | D7: HSEC | E7: EDM-47K2 | F7: PQ | G7: 500-1000 | H7: 14,00 | J7: =IF($B7="","",IF(COUNTIFS('Ayuda Workera'!$C$5:$C$3004,UPPER(SUBSTITUTE($B7,".","")),'Ayuda Workera'!$B$5:$B$3004,DATE($H$1,$G$1,$F$1),'Marcación Workera'!$H$5:$H$3004,"Entrada")>0,"SI","NO")) -> NO | K7: =IF($B7="","",IF(COUNTIFS('Ayuda Workera'!$C$5:$C$3004,UPPER(SUBSTITUTE($B7,".","")),'Ayuda Workera'!$B$5:$B$3004,DATE($H$1,$G$1,$F$1),'Marcación Workera'!$H$5:$H$3004,"Salida")>0,"SI","NO")) -> NO
A8: 3 | B8: =IFERROR(INDEX(Dotación!$A$5:$A$160,MATCH($C8,Dotación!$B$5:$B$160,0)),"21516063-7") -> 21516063-7 | C8: Nataly Antonia Salas Escobar | D8: ADMINISTRATIVO | E8: EDM-47K2 | F8: PQ | G8: 500-1000 | H8: 14,00 | J8: =IF($B8="","",IF(COUNTIFS('Ayuda Workera'!$C$5:$C$3004,UPPER(SUBSTITUTE($B8,".","")),'Ayuda Workera'!$B$5:$B$3004,DATE($H$1,$G$1,$F$1),'Marcación Workera'!$H$5:$H$3004,"Entrada")>0,"SI","NO")) -> SI | K8: =IF($B8="","",IF(COUNTIFS('Ayuda Workera'!$C$5:$C$3004,UPPER(SUBSTITUTE($B8,".","")),'Ayuda Workera'!$B$5:$B$3004,DATE($H$1,$G$1,$F$1),'Marcación Workera'!$H$5:$H$3004,"Salida")>0,"SI","NO")) -> NO
A9: 4 | B9: =IFERROR(INDEX(Dotación!$A$5:$A$160,MATCH($C9,Dotación!$B$5:$B$160,0)),"14043656-9") -> 14043656-9 | C9: Leonardo Andres Meneses Arredondo | D9: SUPERVISOR | E9: EDM-47K2 | F9: PQ | G9: 500-1000 | H9: 14,00 | J9: =IF($B9="","",IF(COUNTIFS('Ayuda Workera'!$C$5:$C$3004,UPPER(SUBSTITUTE($B9,".","")),'Ayuda Workera'!$B$5:$B$3004,DATE($H$1,$G$1,$F$1),'Marcación Workera'!$H$5:$H$3004,"Entrada")>0,"SI","NO")) -> SI | K9: =IF($B9="","",IF(COUNTIFS('Ayuda Workera'!$C$5:$C$3004,UPPER(SUBSTITUTE($B9,".","")),'Ayuda Workera'!$B$5:$B$3004,DATE($H$1,$G$1,$F$1),'Marcación Workera'!$H$5:$H$3004,"Salida")>0,"SI","NO")) -> NO
A10: 5 | B10: =IFERROR(INDEX(Dotación!$A$5:$A$160,MATCH($C10,Dotación!$B$5:$B$160,0)),"18889617-0") -> 18889617-0 | C10: Leonel Guillermo Campusano Dubo | D10: AYUDANTE | E10: EDM-47K2 | F10: PQ | G10: 500-1000 | H10: 14,00 | J10: =IF($B10="","",IF(COUNTIFS('Ayuda Workera'!$C$5:$C$3004,UPPER(SUBSTITUTE($B10,".","")),'Ayuda Workera'!$B$5:$B$3004,DATE($H$1,$G$1,$F$1),'Marcación Workera'!$H$5:$H$3004,"Entrada")>0,"SI","NO")) -> SI | K10: =IF($B10="","",IF(COUNTIFS('Ayuda Workera'!$C$5:$C$3004,UPPER(SUBSTITUTE($B10,".","")),'Ayuda Workera'!$B$5:$B$3004,DATE($H$1,$G$1,$F$1),'Marcación Workera'!$H$5:$H$3004,"Salida")>0,"SI","NO")) -> NO
A11: 6 | B11: =IFERROR(INDEX(Dotación!$A$5:$A$160,MATCH($C11,Dotación!$B$5:$B$160,0)),"16.706.064-1") -> 16.706.064-1 | C11: Victor Manuel Mondaca Vega | D11: AYUDANTE | E11: EDM-47K2 | F11: PQ | G11: 500-1000 | H11: 14,00 | J11: =IF($B11="","",IF(COUNTIFS('Ayuda Workera'!$C$5:$C$3004,UPPER(SUBSTITUTE($B11,".","")),'Ayuda Workera'!$B$5:$B$3004,DATE($H$1,$G$1,$F$1),'Marcación Workera'!$H$5:$H$3004,"Entrada")>0,"SI","NO")) -> SI | K11: =IF($B11="","",IF(COUNTIFS('Ayuda Workera'!$C$5:$C$3004,UPPER(SUBSTITUTE($B11,".","")),'Ayuda Workera'!$B$5:$B$3004,DATE($H$1,$G$1,$F$1),'Marcación Workera'!$H$5:$H$3004,"Salida")>0,"SI","NO")) -> NO
A12: 7 | B12: =IFERROR(INDEX(Dotación!$A$5:$A$160,MATCH($C12,Dotación!$B$5:$B$160,0)),"11508866-1") -> 11508866-1 | C12: William Hernan Alvares Trujillo | D12: SOLDADOR | E12: EDM-47K2 | F12: PQ | G12: 500-1000 | H12: 14,00 | J12: =IF($B12="","",IF(COUNTIFS('Ayuda Workera'!$C$5:$C$3004,UPPER(SUBSTITUTE($B12,".","")),'Ayuda Workera'!$B$5:$B$3004,DATE($H$1,$G$1,$F$1),'Marcación Workera'!$H$5:$H$3004,"Entrada")>0,"SI","NO")) -> SI | K12: =IF($B12="","",IF(COUNTIFS('Ayuda Workera'!$C$5:$C$3004,UPPER(SUBSTITUTE($B12,".","")),'Ayuda Workera'!$B$5:$B$3004,DATE($H$1,$G$1,$F$1),'Marcación Workera'!$H$5:$H$3004,"Salida")>0,"SI","NO")) -> NO
A13: 8 | B13: =IFERROR(INDEX(Dotación!$A$5:$A$160,MATCH($C13,Dotación!$B$5:$B$160,0)),"13855440-6") -> 13855440-6 | C13: Paolo Alejandro Manriquez Silva | D13: BODEGUERO | E13: EDM-47K2 | F13: PQ | G13: 500-1000 | H13: 14,00 | J13: =IF($B13="","",IF(COUNTIFS('Ayuda Workera'!$C$5:$C$3004,UPPER(SUBSTITUTE($B13,".","")),'Ayuda Workera'!$B$5:$B$3004,DATE($H$1,$G$1,$F$1),'Marcación Workera'!$H$5:$H$3004,"Entrada")>0,"SI","NO")) -> SI | K13: =IF($B13="","",IF(COUNTIFS('Ayuda Workera'!$C$5:$C$3004,UPPER(SUBSTITUTE($B13,".","")),'Ayuda Workera'!$B$5:$B$3004,DATE($H$1,$G$1,$F$1),'Marcación Workera'!$H$5:$H$3004,"Salida")>0,"SI","NO")) -> SI
A14: 9 | B14: =IFERROR(INDEX(Dotación!$A$5:$A$160,MATCH($C14,Dotación!$B$5:$B$160,0)),"12814487-0") -> 12814487-0 | C14: Walter del Carmen Pizarro Alvarez | D14: CHOFER | E14: EDM-47K2 | F14: PQ | G14: 500-1000 | H14: 14,00 | J14: =IF($B14="","",IF(COUNTIFS('Ayuda Workera'!$C$5:$C$3004,UPPER(SUBSTITUTE($B14,".","")),'Ayuda Workera'!$B$5:$B$3004,DATE($H$1,$G$1,$F$1),'Marcación Workera'!$H$5:$H$3004,"Entrada")>0,"SI","NO")) -> NO | K14: =IF($B14="","",IF(COUNTIFS('Ayuda Workera'!$C$5:$C$3004,UPPER(SUBSTITUTE($B14,".","")),'Ayuda Workera'!$B$5:$B$3004,DATE($H$1,$G$1,$F$1),'Marcación Workera'!$H$5:$H$3004,"Salida")>0,"SI","NO")) -> NO
A15: 10 | B15: =IFERROR(INDEX(Dotación!$A$5:$A$160,MATCH($C15,Dotación!$B$5:$B$160,0)),"21254681-K") -> 21254681-K | C15: Jorge Erikson Durand Ruiz | D15: MECÁNICO | E15: EDM-47K2 | F15: PQ | G15: 500-1000 | H15: 14,00 | J15: =IF($B15="","",IF(COUNTIFS('Ayuda Workera'!$C$5:$C$3004,UPPER(SUBSTITUTE($B15,".","")),'Ayuda Workera'!$B$5:$B$3004,DATE($H$1,$G$1,$F$1),'Marcación Workera'!$H$5:$H$3004,"Entrada")>0,"SI","NO")) -> NO | K15: =IF($B15="","",IF(COUNTIFS('Ayuda Workera'!$C$5:$C$3004,UPPER(SUBSTITUTE($B15,".","")),'Ayuda Workera'!$B$5:$B$3004,DATE($H$1,$G$1,$F$1),'Marcación Workera'!$H$5:$H$3004,"Salida")>0,"SI","NO")) -> NO
A16: 11 | B16: =IFERROR(INDEX(Dotación!$A$5:$A$160,MATCH($C16,Dotación!$B$5:$B$160,0)),"17805184-9") -> 17805184-9 | C16: Benjamin Josafatt Espinoza Uribe | D16: CHOFER | E16: EDM-47K2 | F16: PQ | G16: 500-1000 | H16: 14,00 | J16: =IF($B16="","",IF(COUNTIFS('Ayuda Workera'!$C$5:$C$3004,UPPER(SUBSTITUTE($B16,".","")),'Ayuda Workera'!$B$5:$B$3004,DATE($H$1,$G$1,$F$1),'Marcación Workera'!$H$5:$H$3004,"Entrada")>0,"SI","NO")) -> NO | K16: =IF($B16="","",IF(COUNTIFS('Ayuda Workera'!$C$5:$C$3004,UPPER(SUBSTITUTE($B16,".","")),'Ayuda Workera'!$B$5:$B$3004,DATE($H$1,$G$1,$F$1),'Marcación Workera'!$H$5:$H$3004,"Salida")>0,"SI","NO")) -> NO
A17: 12 | B17: =IFERROR(INDEX(Dotación!$A$5:$A$160,MATCH($C17,Dotación!$B$5:$B$160,0)),"23868099-9") -> 23868099-9 | C17: Jorge Armando Tinoco Ospino | D17: CHOFER TRADUCTOR | E17: EDM-47K2 | F17: PQ | G17: 500-1000 | H17: 14,00 | J17: =IF($B17="","",IF(COUNTIFS('Ayuda Workera'!$C$5:$C$3004,UPPER(SUBSTITUTE($B17,".","")),'Ayuda Workera'!$B$5:$B$3004,DATE($H$1,$G$1,$F$1),'Marcación Workera'!$H$5:$H$3004,"Entrada")>0,"SI","NO")) -> NO | K17: =IF($B17="","",IF(COUNTIFS('Ayuda Workera'!$C$5:$C$3004,UPPER(SUBSTITUTE($B17,".","")),'Ayuda Workera'!$B$5:$B$3004,DATE($H$1,$G$1,$F$1),'Marcación Workera'!$H$5:$H$3004,"Salida")>0,"SI","NO")) -> SI
A18: 13 | B18: =IFERROR(INDEX(Dotación!$A$5:$A$160,MATCH($C18,Dotación!$B$5:$B$160,0)),"4500989-0") -> 4500989-0 | C18: Jason Fletcher | D18: GERENTE TECNICO | E18: EDM-47K2 | F18: PQ | G18: 500-1000 | H18: 14,00 | J18: =IF($B18="","",IF(COUNTIFS('Ayuda Workera'!$C$5:$C$3004,UPPER(SUBSTITUTE($B18,".","")),'Ayuda Workera'!$B$5:$B$3004,DATE($H$1,$G$1,$F$1),'Marcación Workera'!$H$5:$H$3004,"Entrada")>0,"SI","NO")) -> NO | K18: =IF($B18="","",IF(COUNTIFS('Ayuda Workera'!$C$5:$C$3004,UPPER(SUBSTITUTE($B18,".","")),'Ayuda Workera'!$B$5:$B$3004,DATE($H$1,$G$1,$F$1),'Marcación Workera'!$H$5:$H$3004,"Salida")>0,"SI","NO")) -> NO
A19: 14 | B19: =IFERROR(INDEX(Dotación!$A$5:$A$160,MATCH($C19,Dotación!$B$5:$B$160,0)),"17626968-5") -> 17626968-5 | C19: Mauricio Enrique Tapia Carvajal | D19: PERFORISTA BU | E19: EDM-47K2 | F19: PQ | G19: 500-1000 | H19: 14,00 | J19: =IF($B19="","",IF(COUNTIFS('Ayuda Workera'!$C$5:$C$3004,UPPER(SUBSTITUTE($B19,".","")),'Ayuda Workera'!$B$5:$B$3004,DATE($H$1,$G$1,$F$1),'Marcación Workera'!$H$5:$H$3004,"Entrada")>0,"SI","NO")) -> NO | K19: =IF($B19="","",IF(COUNTIFS('Ayuda Workera'!$C$5:$C$3004,UPPER(SUBSTITUTE($B19,".","")),'Ayuda Workera'!$B$5:$B$3004,DATE($H$1,$G$1,$F$1),'Marcación Workera'!$H$5:$H$3004,"Salida")>0,"SI","NO")) -> NO
A20: 15 | B20: =IFERROR(INDEX(Dotación!$A$5:$A$160,MATCH($C20,Dotación!$B$5:$B$160,0)),"28683244-K") -> 28683244-K | C20: Ariunbold Tsogkhorkhoi | D20: PERFORISTA | E20: EDM 2000-8 | F20: PQ | G20: 500-1000 | H20: 14,00 | J20: =IF($B20="","",IF(COUNTIFS('Ayuda Workera'!$C$5:$C$3004,UPPER(SUBSTITUTE($B20,".","")),'Ayuda Workera'!$B$5:$B$3004,DATE($H$1,$G$1,$F$1),'Marcación Workera'!$H$5:$H$3004,"Entrada")>0,"SI","NO")) -> NO | K20: =IF($B20="","",IF(COUNTIFS('Ayuda Workera'!$C$5:$C$3004,UPPER(SUBSTITUTE($B20,".","")),'Ayuda Workera'!$B$5:$B$3004,DATE($H$1,$G$1,$F$1),'Marcación Workera'!$H$5:$H$3004,"Salida")>0,"SI","NO")) -> NO
A21: 16 | B21: =IFERROR(INDEX(Dotación!$A$5:$A$160,MATCH($C21,Dotación!$B$5:$B$160,0)),"19949787-1") -> 19949787-1 | C21: Fabian Patricio Cabrera Godoy | D21: AYUDANTE | E21: EDM-47K2 | F21: PQ | G21: 500-1000 | H21: 14,00 | J21: =IF($B21="","",IF(COUNTIFS('Ayuda Workera'!$C$5:$C$3004,UPPER(SUBSTITUTE($B21,".","")),'Ayuda Workera'!$B$5:$B$3004,DATE($H$1,$G$1,$F$1),'Marcación Workera'!$H$5:$H$3004,"Entrada")>0,"SI","NO")) -> SI | K21: =IF($B21="","",IF(COUNTIFS('Ayuda Workera'!$C$5:$C$3004,UPPER(SUBSTITUTE($B21,".","")),'Ayuda Workera'!$B$5:$B$3004,DATE($H$1,$G$1,$F$1),'Marcación Workera'!$H$5:$H$3004,"Salida")>0,"SI","NO")) -> NO
A23: TURNO NOCHE
A24: N° | B24: RUT | C24: NOMBRE COMPLETO | D24: CARGO | E24: MAQUINA | F24: DIAMETRO | G24: ESCALA | H24: METROS | I24: H. EXTRAS | J24: workera entrada | K24: workera salida | L24: MOTIVO HORAS EXTRAS
A25: 1 | B25: =IFERROR(INDEX(Dotación!$A$5:$A$160,MATCH($C25,Dotación!$B$5:$B$160,0)),"15.814.058-6") -> 15.814.058-6 | C25: Ulinson Diaz Cortes | D25: SUPERVISOR | E25: EDM-47K2 | F25: PQ | G25: 500-1000 | H25: 16,00 | J25: =IF($B25="","",IF(COUNTIFS('Ayuda Workera'!$C$5:$C$3004,UPPER(SUBSTITUTE($B25,".","")),'Ayuda Workera'!$B$5:$B$3004,DATE($H$1,$G$1,$F$1),'Marcación Workera'!$H$5:$H$3004,"Entrada")>0,"SI","NO")) -> NO | K25: =IF($B25="","",IF(COUNTIFS('Ayuda Workera'!$C$5:$C$3004,UPPER(SUBSTITUTE($B25,".","")),'Ayuda Workera'!$B$5:$B$3004,DATE($H$1,$G$1,$F$1),'Marcación Workera'!$H$5:$H$3004,"Salida")>0,"SI","NO")) -> NO
A26: 2 | B26: =IFERROR(INDEX(Dotación!$A$5:$A$160,MATCH($C26,Dotación!$B$5:$B$160,0)),"16188552-5") -> 16188552-5 | C26: Rodrigo Alejandro Flores Zepeda | D26: AYUDANTE | E26: EDM-47K2 | F26: PQ | G26: 500-1000 | H26: 16,00 | J26: =IF($B26="","",IF(COUNTIFS('Ayuda Workera'!$C$5:$C$3004,UPPER(SUBSTITUTE($B26,".","")),'Ayuda Workera'!$B$5:$B$3004,DATE($H$1,$G$1,$F$1),'Marcación Workera'!$H$5:$H$3004,"Entrada")>0,"SI","NO")) -> NO | K26: =IF($B26="","",IF(COUNTIFS('Ayuda Workera'!$C$5:$C$3004,UPPER(SUBSTITUTE($B26,".","")),'Ayuda Workera'!$B$5:$B$3004,DATE($H$1,$G$1,$F$1),'Marcación Workera'!$H$5:$H$3004,"Salida")>0,"SI","NO")) -> NO
A27: 3 | B27: =IFERROR(INDEX(Dotación!$A$5:$A$160,MATCH($C27,Dotación!$B$5:$B$160,0)),"20718093-9") -> 20718093-9 | C27: Ignacio Alejandro Robles Barrios | D27: AYUDANTE | E27: EDM-47K2 | F27: PQ | G27: 500-1000 | H27: 16,00 | J27: =IF($B27="","",IF(COUNTIFS('Ayuda Workera'!$C$5:$C$3004,UPPER(SUBSTITUTE($B27,".","")),'Ayuda Workera'!$B$5:$B$3004,DATE($H$1,$G$1,$F$1),'Marcación Workera'!$H$5:$H$3004,"Entrada")>0,"SI","NO")) -> NO | K27: =IF($B27="","",IF(COUNTIFS('Ayuda Workera'!$C$5:$C$3004,UPPER(SUBSTITUTE($B27,".","")),'Ayuda Workera'!$B$5:$B$3004,DATE($H$1,$G$1,$F$1),'Marcación Workera'!$H$5:$H$3004,"Salida")>0,"SI","NO")) -> NO
A28: 4 | B28: =IFERROR(INDEX(Dotación!$A$5:$A$160,MATCH($C28,Dotación!$B$5:$B$160,0)),"17643998-k") -> 17643998-k | C28: Benigno Eduardo Paez Meneses | D28: CHOFER | E28: EDM-47K2 | F28: PQ | G28: 500-1000 | H28: 16,00 | J28: =IF($B28="","",IF(COUNTIFS('Ayuda Workera'!$C$5:$C$3004,UPPER(SUBSTITUTE($B28,".","")),'Ayuda Workera'!$B$5:$B$3004,DATE($H$1,$G$1,$F$1),'Marcación Workera'!$H$5:$H$3004,"Entrada")>0,"SI","NO")) -> NO | K28: =IF($B28="","",IF(COUNTIFS('Ayuda Workera'!$C$5:$C$3004,UPPER(SUBSTITUTE($B28,".","")),'Ayuda Workera'!$B$5:$B$3004,DATE($H$1,$G$1,$F$1),'Marcación Workera'!$H$5:$H$3004,"Salida")>0,"SI","NO")) -> NO
A29: 5 | B29: =IFERROR(INDEX(Dotación!$A$5:$A$160,MATCH($C29,Dotación!$B$5:$B$160,0)),"15831074-0") -> 15831074-0 | C29: Estefania Constanza Naeter Quiroz | D29: CONDUCTOR TRADUCTOR | E29: EDM-47K2 | F29: PQ | G29: 500-1000 | H29: 16,00 | J29: =IF($B29="","",IF(COUNTIFS('Ayuda Workera'!$C$5:$C$3004,UPPER(SUBSTITUTE($B29,".","")),'Ayuda Workera'!$B$5:$B$3004,DATE($H$1,$G$1,$F$1),'Marcación Workera'!$H$5:$H$3004,"Entrada")>0,"SI","NO")) -> NO | K29: =IF($B29="","",IF(COUNTIFS('Ayuda Workera'!$C$5:$C$3004,UPPER(SUBSTITUTE($B29,".","")),'Ayuda Workera'!$B$5:$B$3004,DATE($H$1,$G$1,$F$1),'Marcación Workera'!$H$5:$H$3004,"Salida")>0,"SI","NO")) -> NO
A30: 6 | B30: =IFERROR(INDEX(Dotación!$A$5:$A$160,MATCH($C30,Dotación!$B$5:$B$160,0)),"14594999-8") -> 14594999-8 | C30: Roberto Mario Vargas Rodriguez | D30: MECANICO | E30: EDM-47K2 | F30: PQ | G30: 500-1000 | H30: 16,00 | J30: =IF($B30="","",IF(COUNTIFS('Ayuda Workera'!$C$5:$C$3004,UPPER(SUBSTITUTE($B30,".","")),'Ayuda Workera'!$B$5:$B$3004,DATE($H$1,$G$1,$F$1),'Marcación Workera'!$H$5:$H$3004,"Entrada")>0,"SI","NO")) -> NO | K30: =IF($B30="","",IF(COUNTIFS('Ayuda Workera'!$C$5:$C$3004,UPPER(SUBSTITUTE($B30,".","")),'Ayuda Workera'!$B$5:$B$3004,DATE($H$1,$G$1,$F$1),'Marcación Workera'!$H$5:$H$3004,"Salida")>0,"SI","NO")) -> NO
A31: 7 | B31: =IFERROR(INDEX(Dotación!$A$5:$A$160,MATCH($C31,Dotación!$B$5:$B$160,0)),"4.500.919-K") -> 4.500.919-K | C31: GANTSOOJ KHISHIGBAYAR | D31: PERFORISTA | E31: EDM-47K2 | F31: PQ | G31: 500-1000 | H31: 16,00 | J31: =IF($B31="","",IF(COUNTIFS('Ayuda Workera'!$C$5:$C$3004,UPPER(SUBSTITUTE($B31,".","")),'Ayuda Workera'!$B$5:$B$3004,DATE($H$1,$G$1,$F$1),'Marcación Workera'!$H$5:$H$3004,"Entrada")>0,"SI","NO")) -> NO | K31: =IF($B31="","",IF(COUNTIFS('Ayuda Workera'!$C$5:$C$3004,UPPER(SUBSTITUTE($B31,".","")),'Ayuda Workera'!$B$5:$B$3004,DATE($H$1,$G$1,$F$1),'Marcación Workera'!$H$5:$H$3004,"Salida")>0,"SI","NO")) -> NO

Sheet 03-08-2026
B1: PROYECTO: | C1: LA COIPA | F1: 3 | G1: 8 | H1: 2026 | J1: =IF($B1="","",IF(COUNTIFS('Ayuda Workera'!$C$5:$C$3004,UPPER(SUBSTITUTE($B1,".","")),'Ayuda Workera'!$B$5:$B$3004,DATE($H$1,$G$1,$F$1),'Marcación Workera'!$H$5:$H$3004,"Entrada")>0,"SI","NO")) -> NO | K1: =IF($B1="","",IF(COUNTIFS('Ayuda Workera'!$C$5:$C$3004,UPPER(SUBSTITUTE($B1,".","")),'Ayuda Workera'!$B$5:$B$3004,DATE($H$1,$G$1,$F$1),'Marcación Workera'!$H$5:$H$3004,"Salida")>0,"SI","NO")) -> NO
F2: DIA | G2: MES | H2: AÑO
A4: TURNO A DÍA
A5: N° | B5: RUT | C5: NOMBRE COMPLETO | D5: CARGO | E5: MAQUINA | F5: DIAMETRO | G5: ESCALA | H5: METROS | I5: H. EXTRAS | J5: workera entrada | K5: workera salida | L5: MOTIVO HORAS EXTRAS
A6: 1 | B6: =IFERROR(INDEX(Dotación!$A$5:$A$160,MATCH($C6,Dotación!$B$5:$B$160,0)),"11384027-7") -> 11384027-7 | C6: Alex Mario Morales Antiquera | D6: JEFE DE FAENA | E6: EDM-47K2 | F6: PQ | G6: 500-1000 | H6: 7,05 | J6: =IF($B6="","",IF(COUNTIFS('Ayuda Workera'!$C$5:$C$3004,UPPER(SUBSTITUTE($B6,".","")),'Ayuda Workera'!$B$5:$B$3004,DATE($H$1,$G$1,$F$1),'Marcación Workera'!$H$5:$H$3004,"Entrada")>0,"SI","NO")) -> NO | K6: =IF($B6="","",IF(COUNTIFS('Ayuda Workera'!$C$5:$C$3004,UPPER(SUBSTITUTE($B6,".","")),'Ayuda Workera'!$B$5:$B$3004,DATE($H$1,$G$1,$F$1),'Marcación Workera'!$H$5:$H$3004,"Salida")>0,"SI","NO")) -> NO
A7: 2 | B7: =IFERROR(INDEX(Dotación!$A$5:$A$160,MATCH($C7,Dotación!$B$5:$B$160,0)),"18352777-0") -> 18352777-0 | C7: Nora Alexandra Salas Rojas | D7: HSEC | E7: EDM-47K2 | F7: PQ | G7: 500-1000 | H7: 7,05 | J7: =IF($B7="","",IF(COUNTIFS('Ayuda Workera'!$C$5:$C$3004,UPPER(SUBSTITUTE($B7,".","")),'Ayuda Workera'!$B$5:$B$3004,DATE($H$1,$G$1,$F$1),'Marcación Workera'!$H$5:$H$3004,"Entrada")>0,"SI","NO")) -> NO | K7: =IF($B7="","",IF(COUNTIFS('Ayuda Workera'!$C$5:$C$3004,UPPER(SUBSTITUTE($B7,".","")),'Ayuda Workera'!$B$5:$B$3004,DATE($H$1,$G$1,$F$1),'Marcación Workera'!$H$5:$H$3004,"Salida")>0,"SI","NO")) -> NO
A8: 3 | B8: =IFERROR(INDEX(Dotación!$A$5:$A$160,MATCH($C8,Dotación!$B$5:$B$160,0)),"21516063-7") -> 21516063-7 | C8: Nataly Antonia Salas Escobar | D8: ADMINISTRATIVO | E8: EDM-47K2 | F8: PQ | G8: 500-1000 | H8: 7,05 | J8: =IF($B8="","",IF(COUNTIFS('Ayuda Workera'!$C$5:$C$3004,UPPER(SUBSTITUTE($B8,".","")),'Ayuda Workera'!$B$5:$B$3004,DATE($H$1,$G$1,$F$1),'Marcación Workera'!$H$5:$H$3004,"Entrada")>0,"SI","NO")) -> SI | K8: =IF($B8="","",IF(COUNTIFS('Ayuda Workera'!$C$5:$C$3004,UPPER(SUBSTITUTE($B8,".","")),'Ayuda Workera'!$B$5:$B$3004,DATE($H$1,$G$1,$F$1),'Marcación Workera'!$H$5:$H$3004,"Salida")>0,"SI","NO")) -> SI
A9: 4 | B9: =IFERROR(INDEX(Dotación!$A$5:$A$160,MATCH($C9,Dotación!$B$5:$B$160,0)),"15593625-8") -> 15593625-8 | C9: Carlos Rodrigez Hernandez | D9: ADC | E9: EDM-47K2 | F9: PQ | G9: 500-1000 | H9: 7,05 | J9: =IF($B9="","",IF(COUNTIFS('Ayuda Workera'!$C$5:$C$3004,UPPER(SUBSTITUTE($B9,".","")),'Ayuda Workera'!$B$5:$B$3004,DATE($H$1,$G$1,$F$1),'Marcación Workera'!$H$5:$H$3004,"Entrada")>0,"SI","NO")) -> SI | K9: =IF($B9="","",IF(COUNTIFS('Ayuda Workera'!$C$5:$C$3004,UPPER(SUBSTITUTE($B9,".","")),'Ayuda Workera'!$B$5:$B$3004,DATE($H$1,$G$1,$F$1),'Marcación Workera'!$H$5:$H$3004,"Salida")>0,"SI","NO")) -> SI
A10: 5 | B10: =IFERROR(INDEX(Dotación!$A$5:$A$160,MATCH($C10,Dotación!$B$5:$B$160,0)),"14043656-9") -> 14043656-9 | C10: Leonardo Andres Meneses Arredondo | D10: SUPERVISOR | E10: EDM-47K2 | F10: PQ | G10: 500-1000 | H10: 7,05 | J10: =IF($B10="","",IF(COUNTIFS('Ayuda Workera'!$C$5:$C$3004,UPPER(SUBSTITUTE($B10,".","")),'Ayuda Workera'!$B$5:$B$3004,DATE($H$1,$G$1,$F$1),'Marcación Workera'!$H$5:$H$3004,"Entrada")>0,"SI","NO")) -> NO | K10: =IF($B10="","",IF(COUNTIFS('Ayuda Workera'!$C$5:$C$3004,UPPER(SUBSTITUTE($B10,".","")),'Ayuda Workera'!$B$5:$B$3004,DATE($H$1,$G$1,$F$1),'Marcación Workera'!$H$5:$H$3004,"Salida")>0,"SI","NO")) -> NO
A11: 6 | B11: =IFERROR(INDEX(Dotación!$A$5:$A$160,MATCH($C11,Dotación!$B$5:$B$160,0)),"18889617-0") -> 18889617-0 | C11: Leonel Guillermo Campusano Dubo | D11: AYUDANTE | E11: EDM-47K2 | F11: PQ | G11: 500-1000 | H11: 7,05 | J11: =IF($B11="","",IF(COUNTIFS('Ayuda Workera'!$C$5:$C$3004,UPPER(SUBSTITUTE($B11,".","")),'Ayuda Workera'!$B$5:$B$3004,DATE($H$1,$G$1,$F$1),'Marcación Workera'!$H$5:$H$3004,"Entrada")>0,"SI","NO")) -> SI | K11: =IF($B11="","",IF(COUNTIFS('Ayuda Workera'!$C$5:$C$3004,UPPER(SUBSTITUTE($B11,".","")),'Ayuda Workera'!$B$5:$B$3004,DATE($H$1,$G$1,$F$1),'Marcación Workera'!$H$5:$H$3004,"Salida")>0,"SI","NO")) -> NO
A12: 7 | B12: =IFERROR(INDEX(Dotación!$A$5:$A$160,MATCH($C12,Dotación!$B$5:$B$160,0)),"16.706.064-1") -> 16.706.064-1 | C12: Victor Manuel Mondaca Vega | D12: AYUDANTE | E12: EDM-47K2 | F12: PQ | G12: 500-1000 | H12: 7,05 | J12: =IF($B12="","",IF(COUNTIFS('Ayuda Workera'!$C$5:$C$3004,UPPER(SUBSTITUTE($B12,".","")),'Ayuda Workera'!$B$5:$B$3004,DATE($H$1,$G$1,$F$1),'Marcación Workera'!$H$5:$H$3004,"Entrada")>0,"SI","NO")) -> SI | K12: =IF($B12="","",IF(COUNTIFS('Ayuda Workera'!$C$5:$C$3004,UPPER(SUBSTITUTE($B12,".","")),'Ayuda Workera'!$B$5:$B$3004,DATE($H$1,$G$1,$F$1),'Marcación Workera'!$H$5:$H$3004,"Salida")>0,"SI","NO")) -> NO
A13: 8 | B13: =IFERROR(INDEX(Dotación!$A$5:$A$160,MATCH($C13,Dotación!$B$5:$B$160,0)),"11508866-1") -> 11508866-1 | C13: William Hernan Alvares Trujillo | D13: SOLDADOR | E13: EDM-47K2 | F13: PQ | G13: 500-1000 | H13: 7,05 | J13: =IF($B13="","",IF(COUNTIFS('Ayuda Workera'!$C$5:$C$3004,UPPER(SUBSTITUTE($B13,".","")),'Ayuda Workera'!$B$5:$B$3004,DATE($H$1,$G$1,$F$1),'Marcación Workera'!$H$5:$H$3004,"Entrada")>0,"SI","NO")) -> SI | K13: =IF($B13="","",IF(COUNTIFS('Ayuda Workera'!$C$5:$C$3004,UPPER(SUBSTITUTE($B13,".","")),'Ayuda Workera'!$B$5:$B$3004,DATE($H$1,$G$1,$F$1),'Marcación Workera'!$H$5:$H$3004,"Salida")>0,"SI","NO")) -> SI
A14: 9 | B14: =IFERROR(INDEX(Dotación!$A$5:$A$160,MATCH($C14,Dotación!$B$5:$B$160,0)),"13855440-6") -> 13855440-6 | C14: Paolo Alejandro Manriquez Silva | D14: BODEGUERO | E14: EDM-47K2 | F14: PQ | G14: 500-1000 | H14: 7,05 | J14: =IF($B14="","",IF(COUNTIFS('Ayuda Workera'!$C$5:$C$3004,UPPER(SUBSTITUTE($B14,".","")),'Ayuda Workera'!$B$5:$B$3004,DATE($H$1,$G$1,$F$1),'Marcación Workera'!$H$5:$H$3004,"Entrada")>0,"SI","NO")) -> SI | K14: =IF($B14="","",IF(COUNTIFS('Ayuda Workera'!$C$5:$C$3004,UPPER(SUBSTITUTE($B14,".","")),'Ayuda Workera'!$B$5:$B$3004,DATE($H$1,$G$1,$F$1),'Marcación Workera'!$H$5:$H$3004,"Salida")>0,"SI","NO")) -> NO
A15: 10 | B15: =IFERROR(INDEX(Dotación!$A$5:$A$160,MATCH($C15,Dotación!$B$5:$B$160,0)),"12814487-0") -> 12814487-0 | C15: Walter del Carmen Pizarro Alvarez | D15: CHOFER | E15: EDM-47K2 | F15: PQ | G15: 500-1000 | H15: 7,05 | J15: =IF($B15="","",IF(COUNTIFS('Ayuda Workera'!$C$5:$C$3004,UPPER(SUBSTITUTE($B15,".","")),'Ayuda Workera'!$B$5:$B$3004,DATE($H$1,$G$1,$F$1),'Marcación Workera'!$H$5:$H$3004,"Entrada")>0,"SI","NO")) -> NO | K15: =IF($B15="","",IF(COUNTIFS('Ayuda Workera'!$C$5:$C$3004,UPPER(SUBSTITUTE($B15,".","")),'Ayuda Workera'!$B$5:$B$3004,DATE($H$1,$G$1,$F$1),'Marcación Workera'!$H$5:$H$3004,"Salida")>0,"SI","NO")) -> NO
A16: 11 | B16: =IFERROR(INDEX(Dotación!$A$5:$A$160,MATCH($C16,Dotación!$B$5:$B$160,0)),"21254681-K") -> 21254681-K | C16: Jorge Erikson Durand Ruiz | D16: MECÁNICO | E16: EDM-47K2 | F16: PQ | G16: 500-1000 | H16: 7,05 | J16: =IF($B16="","",IF(COUNTIFS('Ayuda Workera'!$C$5:$C$3004,UPPER(SUBSTITUTE($B16,".","")),'Ayuda Workera'!$B$5:$B$3004,DATE($H$1,$G$1,$F$1),'Marcación Workera'!$H$5:$H$3004,"Entrada")>0,"SI","NO")) -> NO | K16: =IF($B16="","",IF(COUNTIFS('Ayuda Workera'!$C$5:$C$3004,UPPER(SUBSTITUTE($B16,".","")),'Ayuda Workera'!$B$5:$B$3004,DATE($H$1,$G$1,$F$1),'Marcación Workera'!$H$5:$H$3004,"Salida")>0,"SI","NO")) -> NO
A17: 12 | B17: =IFERROR(INDEX(Dotación!$A$5:$A$160,MATCH($C17,Dotación!$B$5:$B$160,0)),"17805184-9") -> 17805184-9 | C17: Benjamin Josafatt Espinoza Uribe | D17: CHOFER | E17: EDM-47K2 | F17: PQ | G17: 500-1000 | H17: 7,05 | J17: =IF($B17="","",IF(COUNTIFS('Ayuda Workera'!$C$5:$C$3004,UPPER(SUBSTITUTE($B17,".","")),'Ayuda Workera'!$B$5:$B$3004,DATE($H$1,$G$1,$F$1),'Marcación Workera'!$H$5:$H$3004,"Entrada")>0,"SI","NO")) -> NO | K17: =IF($B17="","",IF(COUNTIFS('Ayuda Workera'!$C$5:$C$3004,UPPER(SUBSTITUTE($B17,".","")),'Ayuda Workera'!$B$5:$B$3004,DATE($H$1,$G$1,$F$1),'Marcación Workera'!$H$5:$H$3004,"Salida")>0,"SI","NO")) -> NO
A18: 13 | B18: =IFERROR(INDEX(Dotación!$A$5:$A$160,MATCH($C18,Dotación!$B$5:$B$160,0)),"23868099-9") -> 23868099-9 | C18: Jorge Armando Tinoco Ospino | D18: CHOFER TRADUCTOR | E18: EDM-47K2 | F18: PQ | G18: 500-1000 | H18: 7,05 | J18: =IF($B18="","",IF(COUNTIFS('Ayuda Workera'!$C$5:$C$3004,UPPER(SUBSTITUTE($B18,".","")),'Ayuda Workera'!$B$5:$B$3004,DATE($H$1,$G$1,$F$1),'Marcación Workera'!$H$5:$H$3004,"Entrada")>0,"SI","NO")) -> SI | K18: =IF($B18="","",IF(COUNTIFS('Ayuda Workera'!$C$5:$C$3004,UPPER(SUBSTITUTE($B18,".","")),'Ayuda Workera'!$B$5:$B$3004,DATE($H$1,$G$1,$F$1),'Marcación Workera'!$H$5:$H$3004,"Salida")>0,"SI","NO")) -> SI
A19: 14 | B19: =IFERROR(INDEX(Dotación!$A$5:$A$160,MATCH($C19,Dotación!$B$5:$B$160,0)),"4500989-0") -> 4500989-0 | C19: Jason Fletcher | D19: GERENTE TECNICO | E19: EDM-47K2 | F19: PQ | G19: 500-1000 | H19: 7,05 | J19: =IF($B19="","",IF(COUNTIFS('Ayuda Workera'!$C$5:$C$3004,UPPER(SUBSTITUTE($B19,".","")),'Ayuda Workera'!$B$5:$B$3004,DATE($H$1,$G$1,$F$1),'Marcación Workera'!$H$5:$H$3004,"Entrada")>0,"SI","NO")) -> NO | K19: =IF($B19="","",IF(COUNTIFS('Ayuda Workera'!$C$5:$C$3004,UPPER(SUBSTITUTE($B19,".","")),'Ayuda Workera'!$B$5:$B$3004,DATE($H$1,$G$1,$F$1),'Marcación Workera'!$H$5:$H$3004,"Salida")>0,"SI","NO")) -> NO
A20: 15 | B20: =IFERROR(INDEX(Dotación!$A$5:$A$160,MATCH($C20,Dotación!$B$5:$B$160,0)),"17626968-5") -> 17626968-5 | C20: Mauricio Enrique Tapia Carvajal | D20: PERFORISTA BU | E20: EDM-47K2 | F20: PQ | G20: 500-1000 | H20: 7,05 | J20: =IF($B20="","",IF(COUNTIFS('Ayuda Workera'!$C$5:$C$3004,UPPER(SUBSTITUTE($B20,".","")),'Ayuda Workera'!$B$5:$B$3004,DATE($H$1,$G$1,$F$1),'Marcación Workera'!$H$5:$H$3004,"Entrada")>0,"SI","NO")) -> NO | K20: =IF($B20="","",IF(COUNTIFS('Ayuda Workera'!$C$5:$C$3004,UPPER(SUBSTITUTE($B20,".","")),'Ayuda Workera'!$B$5:$B$3004,DATE($H$1,$G$1,$F$1),'Marcación Workera'!$H$5:$H$3004,"Salida")>0,"SI","NO")) -> NO
A21: 16 | B21: =IFERROR(INDEX(Dotación!$A$5:$A$160,MATCH($C21,Dotación!$B$5:$B$160,0)),"28683244-K") -> 28683244-K | C21: Ariunbold Tsogkhorkhoi | D21: PERFORISTA | E21: EDM 2000-8 | F21: PQ | G21: 500-1000 | H21: 7,05 | J21: =IF($B21="","",IF(COUNTIFS('Ayuda Workera'!$C$5:$C$3004,UPPER(SUBSTITUTE($B21,".","")),'Ayuda Workera'!$B$5:$B$3004,DATE($H$1,$G$1,$F$1),'Marcación Workera'!$H$5:$H$3004,"Entrada")>0,"SI","NO")) -> NO | K21: =IF($B21="","",IF(COUNTIFS('Ayuda Workera'!$C$5:$C$3004,UPPER(SUBSTITUTE($B21,".","")),'Ayuda Workera'!$B$5:$B$3004,DATE($H$1,$G$1,$F$1),'Marcación Workera'!$H$5:$H$3004,"Salida")>0,"SI","NO")) -> NO
A22: 17 | B22: =IFERROR(INDEX(Dotación!$A$5:$A$160,MATCH($C22,Dotación!$B$5:$B$160,0)),"19949787-1") -> 19949787-1 | C22: Fabian Patricio Cabrera Godoy | D22: AYUDANTE | E22: EDM-47K2 | F22: PQ | G22: 500-1000 | H22: 7,05 | J22: =IF($B22="","",IF(COUNTIFS('Ayuda Workera'!$C$5:$C$3004,UPPER(SUBSTITUTE($B22,".","")),'Ayuda Workera'!$B$5:$B$3004,DATE($H$1,$G$1,$F$1),'Marcación Workera'!$H$5:$H$3004,"Entrada")>0,"SI","NO")) -> NO | K22: =IF($B22="","",IF(COUNTIFS('Ayuda Workera'!$C$5:$C$3004,UPPER(SUBSTITUTE($B22,".","")),'Ayuda Workera'!$B$5:$B$3004,DATE($H$1,$G$1,$F$1),'Marcación Workera'!$H$5:$H$3004,"Salida")>0,"SI","NO")) -> NO
A24: TURNO NOCHE
A25: N° | B25: RUT | C25: NOMBRE COMPLETO | D25: CARGO | E25: MAQUINA | F25: DIAMETRO | G25: ESCALA | H25: METROS | I25: H. EXTRAS | J25: workera entrada | K25: workera salida | L25: MOTIVO HORAS EXTRAS
A26: 1 | B26: =IFERROR(INDEX(Dotación!$A$5:$A$160,MATCH($C26,Dotación!$B$5:$B$160,0)),"15.814.058-6") -> 15.814.058-6 | C26: Ulinson Diaz Cortes | D26: SUPERVISOR | E26: EDM-47K2 | F26: PQ | G26: 500-1000 | H26: 16,95 | J26: =IF($B26="","",IF(COUNTIFS('Ayuda Workera'!$C$5:$C$3004,UPPER(SUBSTITUTE($B26,".","")),'Ayuda Workera'!$B$5:$B$3004,DATE($H$1,$G$1,$F$1),'Marcación Workera'!$H$5:$H$3004,"Entrada")>0,"SI","NO")) -> NO | K26: =IF($B26="","",IF(COUNTIFS('Ayuda Workera'!$C$5:$C$3004,UPPER(SUBSTITUTE($B26,".","")),'Ayuda Workera'!$B$5:$B$3004,DATE($H$1,$G$1,$F$1),'Marcación Workera'!$H$5:$H$3004,"Salida")>0,"SI","NO")) -> NO
A27: 2 | B27: =IFERROR(INDEX(Dotación!$A$5:$A$160,MATCH($C27,Dotación!$B$5:$B$160,0)),"16188552-5") -> 16188552-5 | C27: Rodrigo Alejandro Flores Zepeda | D27: AYUDANTE | E27: EDM-47K2 | F27: PQ | G27: 500-1000 | H27: 16,95 | J27: =IF($B27="","",IF(COUNTIFS('Ayuda Workera'!$C$5:$C$3004,UPPER(SUBSTITUTE($B27,".","")),'Ayuda Workera'!$B$5:$B$3004,DATE($H$1,$G$1,$F$1),'Marcación Workera'!$H$5:$H$3004,"Entrada")>0,"SI","NO")) -> NO | K27: =IF($B27="","",IF(COUNTIFS('Ayuda Workera'!$C$5:$C$3004,UPPER(SUBSTITUTE($B27,".","")),'Ayuda Workera'!$B$5:$B$3004,DATE($H$1,$G$1,$F$1),'Marcación Workera'!$H$5:$H$3004,"Salida")>0,"SI","NO")) -> NO
A28: 3 | B28: =IFERROR(INDEX(Dotación!$A$5:$A$160,MATCH($C28,Dotación!$B$5:$B$160,0)),"20718093-9") -> 20718093-9 | C28: Ignacio Alejandro Robles Barrios | D28: AYUDANTE | E28: EDM-47K2 | F28: PQ | G28: 500-1000 | H28: 16,95 | J28: =IF($B28="","",IF(COUNTIFS('Ayuda Workera'!$C$5:$C$3004,UPPER(SUBSTITUTE($B28,".","")),'Ayuda Workera'!$B$5:$B$3004,DATE($H$1,$G$1,$F$1),'Marcación Workera'!$H$5:$H$3004,"Entrada")>0,"SI","NO")) -> NO | K28: =IF($B28="","",IF(COUNTIFS('Ayuda Workera'!$C$5:$C$3004,UPPER(SUBSTITUTE($B28,".","")),'Ayuda Workera'!$B$5:$B$3004,DATE($H$1,$G$1,$F$1),'Marcación Workera'!$H$5:$H$3004,"Salida")>0,"SI","NO")) -> NO
A29: 4 | B29: =IFERROR(INDEX(Dotación!$A$5:$A$160,MATCH($C29,Dotación!$B$5:$B$160,0)),"17643998-k") -> 17643998-k | C29: Benigno Eduardo Paez Meneses | D29: CHOFER | E29: EDM-47K2 | F29: PQ | G29: 500-1000 | H29: 16,95 | J29: =IF($B29="","",IF(COUNTIFS('Ayuda Workera'!$C$5:$C$3004,UPPER(SUBSTITUTE($B29,".","")),'Ayuda Workera'!$B$5:$B$3004,DATE($H$1,$G$1,$F$1),'Marcación Workera'!$H$5:$H$3004,"Entrada")>0,"SI","NO")) -> NO | K29: =IF($B29="","",IF(COUNTIFS('Ayuda Workera'!$C$5:$C$3004,UPPER(SUBSTITUTE($B29,".","")),'Ayuda Workera'!$B$5:$B$3004,DATE($H$1,$G$1,$F$1),'Marcación Workera'!$H$5:$H$3004,"Salida")>0,"SI","NO")) -> NO
A30: 5 | B30: =IFERROR(INDEX(Dotación!$A$5:$A$160,MATCH($C30,Dotación!$B$5:$B$160,0)),"15831074-0") -> 15831074-0 | C30: Estefania Constanza Naeter Quiroz | D30: CONDUCTOR TRADUCTOR | E30: EDM-47K2 | F30: PQ | G30: 500-1000 | H30: 16,95 | J30: =IF($B30="","",IF(COUNTIFS('Ayuda Workera'!$C$5:$C$3004,UPPER(SUBSTITUTE($B30,".","")),'Ayuda Workera'!$B$5:$B$3004,DATE($H$1,$G$1,$F$1),'Marcación Workera'!$H$5:$H$3004,"Entrada")>0,"SI","NO")) -> NO | K30: =IF($B30="","",IF(COUNTIFS('Ayuda Workera'!$C$5:$C$3004,UPPER(SUBSTITUTE($B30,".","")),'Ayuda Workera'!$B$5:$B$3004,DATE($H$1,$G$1,$F$1),'Marcación Workera'!$H$5:$H$3004,"Salida")>0,"SI","NO")) -> NO
A31: 6 | B31: =IFERROR(INDEX(Dotación!$A$5:$A$160,MATCH($C31,Dotación!$B$5:$B$160,0)),"14594999-8") -> 14594999-8 | C31: Roberto Mario Vargas Rodriguez | D31: MECANICO | E31: EDM-47K2 | F31: PQ | G31: 500-1000 | H31: 16,95 | J31: =IF($B31="","",IF(COUNTIFS('Ayuda Workera'!$C$5:$C$3004,UPPER(SUBSTITUTE($B31,".","")),'Ayuda Workera'!$B$5:$B$3004,DATE($H$1,$G$1,$F$1),'Marcación Workera'!$H$5:$H$3004,"Entrada")>0,"SI","NO")) -> NO | K31: =IF($B31="","",IF(COUNTIFS('Ayuda Workera'!$C$5:$C$3004,UPPER(SUBSTITUTE($B31,".","")),'Ayuda Workera'!$B$5:$B$3004,DATE($H$1,$G$1,$F$1),'Marcación Workera'!$H$5:$H$3004,"Salida")>0,"SI","NO")) -> NO
A32: 7 | B32: =IFERROR(INDEX(Dotación!$A$5:$A$160,MATCH($C32,Dotación!$B$5:$B$160,0)),"4.500.919-K") -> 4.500.919-K | C32: GANTSOOJ KHISHIGBAYAR | D32: PERFORISTA | E32: EDM-47K2 | F32: PQ | G32: 500-1000 | H32: 16,95 | J32: =IF($B32="","",IF(COUNTIFS('Ayuda Workera'!$C$5:$C$3004,UPPER(SUBSTITUTE($B32,".","")),'Ayuda Workera'!$B$5:$B$3004,DATE($H$1,$G$1,$F$1),'Marcación Workera'!$H$5:$H$3004,"Entrada")>0,"SI","NO")) -> NO | K32: =IF($B32="","",IF(COUNTIFS('Ayuda Workera'!$C$5:$C$3004,UPPER(SUBSTITUTE($B32,".","")),'Ayuda Workera'!$B$5:$B$3004,DATE($H$1,$G$1,$F$1),'Marcación Workera'!$H$5:$H$3004,"Salida")>0,"SI","NO")) -> NO

Sheet 04-08-2026
B1: PROYECTO: | C1: LA COIPA | F1: 4 | G1: 8 | H1: 2026 | J1: =IF($B1="","",IF(COUNTIFS('Ayuda Workera'!$C$5:$C$3004,UPPER(SUBSTITUTE($B1,".","")),'Ayuda Workera'!$B$5:$B$3004,DATE($H$1,$G$1,$F$1),'Marcación Workera'!$H$5:$H$3004,"Entrada")>0,"SI","NO")) -> NO | K1: =IF($B1="","",IF(COUNTIFS('Ayuda Workera'!$C$5:$C$3004,UPPER(SUBSTITUTE($B1,".","")),'Ayuda Workera'!$B$5:$B$3004,DATE($H$1,$G$1,$F$1),'Marcación Workera'!$H$5:$H$3004,"Salida")>0,"SI","NO")) -> NO
F2: DIA | G2: MES | H2: AÑO
A4: TURNO A DÍA
A5: N° | B5: RUT | C5: NOMBRE COMPLETO | D5: CARGO | E5: MAQUINA | F5: DIAMETRO | G5: ESCALA | H5: METROS | I5: H. EXTRAS | J5: workera entrada | K5: workera salida | L5: MOTIVO HORAS EXTRAS
A6: 1 | B6: =IFERROR(INDEX(Dotación!$A$5:$A$160,MATCH($C6,Dotación!$B$5:$B$160,0)),"11384027-7") -> 11384027-7 | C6: Alex Mario Morales Antiquera | D6: JEFE DE FAENA | E6: 47K-2 | F6: PQ | G6: 500-1000 | H6: 13,50 | J6: =IF($B6="","",IF(COUNTIFS('Ayuda Workera'!$C$5:$C$3004,UPPER(SUBSTITUTE($B6,".","")),'Ayuda Workera'!$B$5:$B$3004,DATE($H$1,$G$1,$F$1),'Marcación Workera'!$H$5:$H$3004,"Entrada")>0,"SI","NO")) -> NO | K6: =IF($B6="","",IF(COUNTIFS('Ayuda Workera'!$C$5:$C$3004,UPPER(SUBSTITUTE($B6,".","")),'Ayuda Workera'!$B$5:$B$3004,DATE($H$1,$G$1,$F$1),'Marcación Workera'!$H$5:$H$3004,"Salida")>0,"SI","NO")) -> NO
A7: 2 | B7: =IFERROR(INDEX(Dotación!$A$5:$A$160,MATCH($C7,Dotación!$B$5:$B$160,0)),"18352777-0") -> 18352777-0 | C7: Nora Alexandra Salas Rojas | D7: HSEC | E7: 47K-2 | F7: PQ | G7: 500-1000 | H7: 13,50 | J7: =IF($B7="","",IF(COUNTIFS('Ayuda Workera'!$C$5:$C$3004,UPPER(SUBSTITUTE($B7,".","")),'Ayuda Workera'!$B$5:$B$3004,DATE($H$1,$G$1,$F$1),'Marcación Workera'!$H$5:$H$3004,"Entrada")>0,"SI","NO")) -> NO | K7: =IF($B7="","",IF(COUNTIFS('Ayuda Workera'!$C$5:$C$3004,UPPER(SUBSTITUTE($B7,".","")),'Ayuda Workera'!$B$5:$B$3004,DATE($H$1,$G$1,$F$1),'Marcación Workera'!$H$5:$H$3004,"Salida")>0,"SI","NO")) -> NO
A8: 3 | B8: =IFERROR(INDEX(Dotación!$A$5:$A$160,MATCH($C8,Dotación!$B$5:$B$160,0)),"21516063-7") -> 21516063-7 | C8: Nataly Antonia Salas Escobar | D8: ADMINISTRATIVO | E8: 47K-2 | F8: PQ | G8: 500-1000 | H8: 13,50 | J8: =IF($B8="","",IF(COUNTIFS('Ayuda Workera'!$C$5:$C$3004,UPPER(SUBSTITUTE($B8,".","")),'Ayuda Workera'!$B$5:$B$3004,DATE($H$1,$G$1,$F$1),'Marcación Workera'!$H$5:$H$3004,"Entrada")>0,"SI","NO")) -> SI | K8: =IF($B8="","",IF(COUNTIFS('Ayuda Workera'!$C$5:$C$3004,UPPER(SUBSTITUTE($B8,".","")),'Ayuda Workera'!$B$5:$B$3004,DATE($H$1,$G$1,$F$1),'Marcación Workera'!$H$5:$H$3004,"Salida")>0,"SI","NO")) -> SI
A9: 4 | B9: =IFERROR(INDEX(Dotación!$A$5:$A$160,MATCH($C9,Dotación!$B$5:$B$160,0)),"15593625-8") -> 15593625-8 | C9: Carlos Rodrigez Hernandez | D9: ADC | E9: 47K-2 | F9: PQ | G9: 500-1000 | H9: 13,50 | J9: =IF($B9="","",IF(COUNTIFS('Ayuda Workera'!$C$5:$C$3004,UPPER(SUBSTITUTE($B9,".","")),'Ayuda Workera'!$B$5:$B$3004,DATE($H$1,$G$1,$F$1),'Marcación Workera'!$H$5:$H$3004,"Entrada")>0,"SI","NO")) -> SI | K9: =IF($B9="","",IF(COUNTIFS('Ayuda Workera'!$C$5:$C$3004,UPPER(SUBSTITUTE($B9,".","")),'Ayuda Workera'!$B$5:$B$3004,DATE($H$1,$G$1,$F$1),'Marcación Workera'!$H$5:$H$3004,"Salida")>0,"SI","NO")) -> SI
A10: 5 | B10: =IFERROR(INDEX(Dotación!$A$5:$A$160,MATCH($C10,Dotación!$B$5:$B$160,0)),"14043656-9") -> 14043656-9 | C10: Leonardo Andres Meneses Arredondo | D10: SUPERVISOR | E10: 47K-2 | F10: PQ | G10: 500-1000 | H10: 13,50 | J10: =IF($B10="","",IF(COUNTIFS('Ayuda Workera'!$C$5:$C$3004,UPPER(SUBSTITUTE($B10,".","")),'Ayuda Workera'!$B$5:$B$3004,DATE($H$1,$G$1,$F$1),'Marcación Workera'!$H$5:$H$3004,"Entrada")>0,"SI","NO")) -> SI | K10: =IF($B10="","",IF(COUNTIFS('Ayuda Workera'!$C$5:$C$3004,UPPER(SUBSTITUTE($B10,".","")),'Ayuda Workera'!$B$5:$B$3004,DATE($H$1,$G$1,$F$1),'Marcación Workera'!$H$5:$H$3004,"Salida")>0,"SI","NO")) -> NO
A11: 6 | B11: =IFERROR(INDEX(Dotación!$A$5:$A$160,MATCH($C11,Dotación!$B$5:$B$160,0)),"18889617-0") -> 18889617-0 | C11: Leonel Guillermo Campusano Dubo | D11: AYUDANTE | E11: 47K-2 | F11: PQ | G11: 500-1000 | H11: 13,50 | J11: =IF($B11="","",IF(COUNTIFS('Ayuda Workera'!$C$5:$C$3004,UPPER(SUBSTITUTE($B11,".","")),'Ayuda Workera'!$B$5:$B$3004,DATE($H$1,$G$1,$F$1),'Marcación Workera'!$H$5:$H$3004,"Entrada")>0,"SI","NO")) -> SI | K11: =IF($B11="","",IF(COUNTIFS('Ayuda Workera'!$C$5:$C$3004,UPPER(SUBSTITUTE($B11,".","")),'Ayuda Workera'!$B$5:$B$3004,DATE($H$1,$G$1,$F$1),'Marcación Workera'!$H$5:$H$3004,"Salida")>0,"SI","NO")) -> NO
A12: 7 | B12: =IFERROR(INDEX(Dotación!$A$5:$A$160,MATCH($C12,Dotación!$B$5:$B$160,0)),"16.706.064-1") -> 16.706.064-1 | C12: Victor Manuel Mondaca Vega | D12: AYUDANTE | E12: 47K-2 | F12: PQ | G12: 500-1000 | H12: 13,50 | J12: =IF($B12="","",IF(COUNTIFS('Ayuda Workera'!$C$5:$C$3004,UPPER(SUBSTITUTE($B12,".","")),'Ayuda Workera'!$B$5:$B$3004,DATE($H$1,$G$1,$F$1),'Marcación Workera'!$H$5:$H$3004,"Entrada")>0,"SI","NO")) -> SI | K12: =IF($B12="","",IF(COUNTIFS('Ayuda Workera'!$C$5:$C$3004,UPPER(SUBSTITUTE($B12,".","")),'Ayuda Workera'!$B$5:$B$3004,DATE($H$1,$G$1,$F$1),'Marcación Workera'!$H$5:$H$3004,"Salida")>0,"SI","NO")) -> NO
A13: 8 | B13: =IFERROR(INDEX(Dotación!$A$5:$A$160,MATCH($C13,Dotación!$B$5:$B$160,0)),"11508866-1") -> 11508866-1 | C13: William Hernan Alvares Trujillo | D13: SOLDADOR | E13: 47K-2 | F13: PQ | G13: 500-1000 | H13: 13,50 | J13: =IF($B13="","",IF(COUNTIFS('Ayuda Workera'!$C$5:$C$3004,UPPER(SUBSTITUTE($B13,".","")),'Ayuda Workera'!$B$5:$B$3004,DATE($H$1,$G$1,$F$1),'Marcación Workera'!$H$5:$H$3004,"Entrada")>0,"SI","NO")) -> SI | K13: =IF($B13="","",IF(COUNTIFS('Ayuda Workera'!$C$5:$C$3004,UPPER(SUBSTITUTE($B13,".","")),'Ayuda Workera'!$B$5:$B$3004,DATE($H$1,$G$1,$F$1),'Marcación Workera'!$H$5:$H$3004,"Salida")>0,"SI","NO")) -> SI
A14: 9 | B14: =IFERROR(INDEX(Dotación!$A$5:$A$160,MATCH($C14,Dotación!$B$5:$B$160,0)),"13855440-6") -> 13855440-6 | C14: Paolo Alejandro Manriquez Silva | D14: BODEGUERO | E14: 47K-2 | F14: PQ | G14: 500-1000 | H14: 13,50 | J14: =IF($B14="","",IF(COUNTIFS('Ayuda Workera'!$C$5:$C$3004,UPPER(SUBSTITUTE($B14,".","")),'Ayuda Workera'!$B$5:$B$3004,DATE($H$1,$G$1,$F$1),'Marcación Workera'!$H$5:$H$3004,"Entrada")>0,"SI","NO")) -> SI | K14: =IF($B14="","",IF(COUNTIFS('Ayuda Workera'!$C$5:$C$3004,UPPER(SUBSTITUTE($B14,".","")),'Ayuda Workera'!$B$5:$B$3004,DATE($H$1,$G$1,$F$1),'Marcación Workera'!$H$5:$H$3004,"Salida")>0,"SI","NO")) -> SI
A15: 10 | B15: =IFERROR(INDEX(Dotación!$A$5:$A$160,MATCH($C15,Dotación!$B$5:$B$160,0)),"12814487-0") -> 12814487-0 | C15: Walter del Carmen Pizarro Alvarez | D15: CHOFER | E15: 47K-2 | F15: PQ | G15: 500-1000 | H15: 13,50 | J15: =IF($B15="","",IF(COUNTIFS('Ayuda Workera'!$C$5:$C$3004,UPPER(SUBSTITUTE($B15,".","")),'Ayuda Workera'!$B$5:$B$3004,DATE($H$1,$G$1,$F$1),'Marcación Workera'!$H$5:$H$3004,"Entrada")>0,"SI","NO")) -> NO | K15: =IF($B15="","",IF(COUNTIFS('Ayuda Workera'!$C$5:$C$3004,UPPER(SUBSTITUTE($B15,".","")),'Ayuda Workera'!$B$5:$B$3004,DATE($H$1,$G$1,$F$1),'Marcación Workera'!$H$5:$H$3004,"Salida")>0,"SI","NO")) -> NO
A16: 11 | B16: =IFERROR(INDEX(Dotación!$A$5:$A$160,MATCH($C16,Dotación!$B$5:$B$160,0)),"21254681-K") -> 21254681-K | C16: Jorge Erikson Durand Ruiz | D16: MECÁNICO | E16: 47K-2 | F16: PQ | G16: 500-1000 | H16: 13,50 | J16: =IF($B16="","",IF(COUNTIFS('Ayuda Workera'!$C$5:$C$3004,UPPER(SUBSTITUTE($B16,".","")),'Ayuda Workera'!$B$5:$B$3004,DATE($H$1,$G$1,$F$1),'Marcación Workera'!$H$5:$H$3004,"Entrada")>0,"SI","NO")) -> NO | K16: =IF($B16="","",IF(COUNTIFS('Ayuda Workera'!$C$5:$C$3004,UPPER(SUBSTITUTE($B16,".","")),'Ayuda Workera'!$B$5:$B$3004,DATE($H$1,$G$1,$F$1),'Marcación Workera'!$H$5:$H$3004,"Salida")>0,"SI","NO")) -> NO
A17: 12 | B17: =IFERROR(INDEX(Dotación!$A$5:$A$160,MATCH($C17,Dotación!$B$5:$B$160,0)),"17805184-9") -> 17805184-9 | C17: Benjamin Josafatt Espinoza Uribe | D17: CHOFER | E17: 47K-2 | F17: PQ | G17: 500-1000 | H17: 13,50 | J17: =IF($B17="","",IF(COUNTIFS('Ayuda Workera'!$C$5:$C$3004,UPPER(SUBSTITUTE($B17,".","")),'Ayuda Workera'!$B$5:$B$3004,DATE($H$1,$G$1,$F$1),'Marcación Workera'!$H$5:$H$3004,"Entrada")>0,"SI","NO")) -> NO | K17: =IF($B17="","",IF(COUNTIFS('Ayuda Workera'!$C$5:$C$3004,UPPER(SUBSTITUTE($B17,".","")),'Ayuda Workera'!$B$5:$B$3004,DATE($H$1,$G$1,$F$1),'Marcación Workera'!$H$5:$H$3004,"Salida")>0,"SI","NO")) -> NO
A18: 13 | B18: =IFERROR(INDEX(Dotación!$A$5:$A$160,MATCH($C18,Dotación!$B$5:$B$160,0)),"23868099-9") -> 23868099-9 | C18: Jorge Armando Tinoco Ospino | D18: CHOFER TRADUCTOR | E18: 47K-2 | F18: PQ | G18: 500-1000 | H18: 13,50 | J18: =IF($B18="","",IF(COUNTIFS('Ayuda Workera'!$C$5:$C$3004,UPPER(SUBSTITUTE($B18,".","")),'Ayuda Workera'!$B$5:$B$3004,DATE($H$1,$G$1,$F$1),'Marcación Workera'!$H$5:$H$3004,"Entrada")>0,"SI","NO")) -> SI | K18: =IF($B18="","",IF(COUNTIFS('Ayuda Workera'!$C$5:$C$3004,UPPER(SUBSTITUTE($B18,".","")),'Ayuda Workera'!$B$5:$B$3004,DATE($H$1,$G$1,$F$1),'Marcación Workera'!$H$5:$H$3004,"Salida")>0,"SI","NO")) -> NO
A19: 14 | B19: =IFERROR(INDEX(Dotación!$A$5:$A$160,MATCH($C19,Dotación!$B$5:$B$160,0)),"4500989-0") -> 4500989-0 | C19: Jason Fletcher | D19: GERENTE TECNICO | E19: 47K-2 | F19: PQ | G19: 500-1000 | H19: 13,50 | J19: =IF($B19="","",IF(COUNTIFS('Ayuda Workera'!$C$5:$C$3004,UPPER(SUBSTITUTE($B19,".","")),'Ayuda Workera'!$B$5:$B$3004,DATE($H$1,$G$1,$F$1),'Marcación Workera'!$H$5:$H$3004,"Entrada")>0,"SI","NO")) -> NO | K19: =IF($B19="","",IF(COUNTIFS('Ayuda Workera'!$C$5:$C$3004,UPPER(SUBSTITUTE($B19,".","")),'Ayuda Workera'!$B$5:$B$3004,DATE($H$1,$G$1,$F$1),'Marcación Workera'!$H$5:$H$3004,"Salida")>0,"SI","NO")) -> NO
A20: 15 | B20: =IFERROR(INDEX(Dotación!$A$5:$A$160,MATCH($C20,Dotación!$B$5:$B$160,0)),"17626968-5") -> 17626968-5 | C20: Mauricio Enrique Tapia Carvajal | D20: PERFORISTA BU | E20: 47K-2 | F20: PQ | G20: 500-1000 | H20: 13,50 | J20: =IF($B20="","",IF(COUNTIFS('Ayuda Workera'!$C$5:$C$3004,UPPER(SUBSTITUTE($B20,".","")),'Ayuda Workera'!$B$5:$B$3004,DATE($H$1,$G$1,$F$1),'Marcación Workera'!$H$5:$H$3004,"Entrada")>0,"SI","NO")) -> NO | K20: =IF($B20="","",IF(COUNTIFS('Ayuda Workera'!$C$5:$C$3004,UPPER(SUBSTITUTE($B20,".","")),'Ayuda Workera'!$B$5:$B$3004,DATE($H$1,$G$1,$F$1),'Marcación Workera'!$H$5:$H$3004,"Salida")>0,"SI","NO")) -> NO
A21: 16 | B21: =IFERROR(INDEX(Dotación!$A$5:$A$160,MATCH($C21,Dotación!$B$5:$B$160,0)),"28683244-K") -> 28683244-K | C21: Ariunbold Tsogkhorkhoi | D21: PERFORISTA | E21: 47K-2 | F21: PQ | G21: 500-1000 | H21: 13,50 | J21: =IF($B21="","",IF(COUNTIFS('Ayuda Workera'!$C$5:$C$3004,UPPER(SUBSTITUTE($B21,".","")),'Ayuda Workera'!$B$5:$B$3004,DATE($H$1,$G$1,$F$1),'Marcación Workera'!$H$5:$H$3004,"Entrada")>0,"SI","NO")) -> NO | K21: =IF($B21="","",IF(COUNTIFS('Ayuda Workera'!$C$5:$C$3004,UPPER(SUBSTITUTE($B21,".","")),'Ayuda Workera'!$B$5:$B$3004,DATE($H$1,$G$1,$F$1),'Marcación Workera'!$H$5:$H$3004,"Salida")>0,"SI","NO")) -> NO
A22: 17 | B22: =IFERROR(INDEX(Dotación!$A$5:$A$160,MATCH($C22,Dotación!$B$5:$B$160,0)),"19949787-1") -> 19949787-1 | C22: Fabian Patricio Cabrera Godoy | D22: AYUDANTE | E22: 47K-2 | F22: PQ | G22: 500-1000 | H22: 13,50 | J22: =IF($B22="","",IF(COUNTIFS('Ayuda Workera'!$C$5:$C$3004,UPPER(SUBSTITUTE($B22,".","")),'Ayuda Workera'!$B$5:$B$3004,DATE($H$1,$G$1,$F$1),'Marcación Workera'!$H$5:$H$3004,"Entrada")>0,"SI","NO")) -> SI | K22: =IF($B22="","",IF(COUNTIFS('Ayuda Workera'!$C$5:$C$3004,UPPER(SUBSTITUTE($B22,".","")),'Ayuda Workera'!$B$5:$B$3004,DATE($H$1,$G$1,$F$1),'Marcación Workera'!$H$5:$H$3004,"Salida")>0,"SI","NO")) -> NO
A24: TURNO NOCHE
A25: N° | B25: RUT | C25: NOMBRE COMPLETO | D25: CARGO | E25: MAQUINA | F25: DIAMETRO | G25: ESCALA | H25: METROS | I25: H. EXTRAS | J25: workera entrada | K25: workera salida | L25: MOTIVO HORAS EXTRAS
A26: 1 | B26: =IFERROR(INDEX(Dotación!$A$5:$A$160,MATCH($C26,Dotación!$B$5:$B$160,0)),"15.814.058-6") -> 15.814.058-6 | C26: Ulinson Diaz Cortes | D26: SUPERVISOR | E26: EDM-47K2 | F26: PQ | G26: 500-1000 | H26: 16,50 | J26: =IF($B26="","",IF(COUNTIFS('Ayuda Workera'!$C$5:$C$3004,UPPER(SUBSTITUTE($B26,".","")),'Ayuda Workera'!$B$5:$B$3004,DATE($H$1,$G$1,$F$1),'Marcación Workera'!$H$5:$H$3004,"Entrada")>0,"SI","NO")) -> NO | K26: =IF($B26="","",IF(COUNTIFS('Ayuda Workera'!$C$5:$C$3004,UPPER(SUBSTITUTE($B26,".","")),'Ayuda Workera'!$B$5:$B$3004,DATE($H$1,$G$1,$F$1),'Marcación Workera'!$H$5:$H$3004,"Salida")>0,"SI","NO")) -> NO
