Workbook

Sheet 01
G2: DIA
D3: PROYECTO: | E3: LA COIPA | G3: 46266
C6: TURNO DIA - (A o B según fuera el caso)
B7: N° | C7: RUT | D7: NOMBRES Y APELLIDOS | E7: CARGO | F7: MAQUINA | G7: DIAMETRO | H7: ESCALA | I7: METROS | J7: ASISTENCIA | K7: WORKERA ENTRADA | L7: WORKERA SALIDA | M7: OBSERVACIONES
B8: 1 | C8: 14413231-9 | D8: =IFERROR(VLOOKUP(C8,'Lista desplegable'!B$1:C$436,2,FALSE),"") -> JOSE CRISTIAN BASTIAS PEREZ | E8: =IFERROR(VLOOKUP(D8,'Lista desplegable'!C$1:D$436,2,FALSE),"") -> SUPERVISOR DE OPERACIONES | F8: EDM47K-2 | G8: HQ | H8: 1000-1500 | I8: 1.15 | J8: PRESENTE | K8: SI | L8: SI | M8: Marca doble.
B9: 2 | C9: 44623904-K | D9: =IFERROR(VLOOKUP(C9,'Lista desplegable'!B$1:C$436,2,FALSE),"") -> DAYNE JEFFERY PASSMORE . | E9: =IFERROR(VLOOKUP(D9,'Lista desplegable'!C$1:D$436,2,FALSE),"") -> ADMINISTRADOR DE CONTRATO | F9: EDM47K-2 | G9: HQ | H9: 1000-1500 | I9: 1.15 | J9: PRESENTE
B10: 3 | C10: 18352777-0 | D10: =IFERROR(VLOOKUP(C10,'Lista desplegable'!B$1:C$436,2,FALSE),"") -> NORA ALEXANDRA SALAS ROJAS | E10: =IFERROR(VLOOKUP(D10,'Lista desplegable'!C$1:D$436,2,FALSE),"") -> PREVENCIONISTA DE RIESGOS | F10: EDM47K-2 | G10: HQ | H10: 1000-1500 | I10: 1.15 | J10: PRESENTE | K10: SI | L10: SI | M10: Trasladada a dos amigos,
B11: 4 | C11: 21516063-7 | D11: =IFERROR(VLOOKUP(C11,'Lista desplegable'!B$1:C$436,2,FALSE),"") -> NATALY ANTONIA SALAS ESCOBAR | E11: =IFERROR(VLOOKUP(D11,'Lista desplegable'!C$1:D$436,2,FALSE),"") -> ADMINISTRATIVO DE FAENA | F11: EDM47K-2 | G11: HQ | H11: 1000-1500 | I11: 1.15 | J11: PRESENTE | K11: SI | L11: SI
B12: 5 | C12: 13855440-6 | D12: =IFERROR(VLOOKUP(C12,'Lista desplegable'!B$1:C$436,2,FALSE),"") -> PAOLO ALEJANDRO MANRIQUEZ SILVA | E12: =IFERROR(VLOOKUP(D12,'Lista desplegable'!C$1:D$436,2,FALSE),"") -> BODEGUERO | F12: EDM47K-2 | G12: HQ | H12: 1000-1500 | I12: 1.15 | J12: PRESENTE | K12: SI | L12: SI
B13: 6 | C13: 15593625-8 | D13: =IFERROR(VLOOKUP(C13,'Lista desplegable'!B$1:C$436,2,FALSE),"") -> CARLOS EDUARDO RODRIGUEZ HERNANDEZ | E13: =IFERROR(VLOOKUP(D13,'Lista desplegable'!C$1:D$436,2,FALSE),"") -> ADMINISTRADOR DE CONTRATO | F13: EDM47K-2 | G13: HQ | H13: 1000-1500 | I13: 1.15 | J13: PRESENTE | K13: SI | L13: SI
B14: 7 | C14: 15831074-0 | D14: =IFERROR(VLOOKUP(C14,'Lista desplegable'!B$1:C$436,2,FALSE),"") -> ESTEFANIA CONSTANZA NAETER QUIROZ | E14: =IFERROR(VLOOKUP(D14,'Lista desplegable'!C$1:D$436,2,FALSE),"") -> CHOFER | F14: EDM47K-2 | G14: HQ | H14: 1000-1500 | I14: 1.15 | J14: PRESENTE | K14: SI | L14: SI
B15: 8 | C15: 12814487-0 | D15: =IFERROR(VLOOKUP(C15,'Lista desplegable'!B$1:C$436,2,FALSE),"") -> WALTER DEL CARMEN PIZARRO ALVAREZ | E15: =IFERROR(VLOOKUP(D15,'Lista desplegable'!C$1:D$436,2,FALSE),"") -> CHOFER | F15: EDM47K-2 | G15: HQ | H15: 1000-1500 | I15: 1.15 | J15: PRESENTE | K15: SI | L15: SI
B16: 9 | C16: 17643998-k | D16: =IFERROR(VLOOKUP(C16,'Lista desplegable'!B$1:C$436,2,FALSE),"") -> BENIGNO EDUARDO PAEZ MENESES | E16: =IFERROR(VLOOKUP(D16,'Lista desplegable'!C$1:D$436,2,FALSE),"") -> CHOFER | F16: EDM47K-2 | G16: HQ | H16: 1000-1500 | I16: 1.15 | J16: PRESENTE | K16: SI | L16: SI
B17: 10 | C17: 14594999-8 | D17: =IFERROR(VLOOKUP(C17,'Lista desplegable'!B$1:C$436,2,FALSE),"") -> ROBERTO MARIO VARGAS RODRIGUEZ | E17: =IFERROR(VLOOKUP(D17,'Lista desplegable'!C$1:D$436,2,FALSE),"") -> MECANICO | F17: EDM47K-2 | G17: HQ | H17: 1000-1500 | I17: 1.15 | J17: PRESENTE | K17: SI | L17: SI | M17: Se corrigue marcación, marca dos entradas.
B18: 11 | C18: 11508866-1 | D18: =IFERROR(VLOOKUP(C18,'Lista desplegable'!B$1:C$436,2,FALSE),"") -> WILLIAM HERNAN ALVAREZ TRUJILLO | E18: =IFERROR(VLOOKUP(D18,'Lista desplegable'!C$1:D$436,2,FALSE),"") -> SOLDADOR | F18: EDM47K-2 | G18: HQ | H18: 1000-1500 | I18: 1.15 | J18: PRESENTE | K18: SI | L18: SI
B19: 12 | C19: 44591746-K | D19: =IFERROR(VLOOKUP(C19,'Lista desplegable'!B$1:C$436,2,FALSE),"") -> GANTSOOJ KHISHIGBAYAR . | E19: =IFERROR(VLOOKUP(D19,'Lista desplegable'!C$1:D$436,2,FALSE),"") -> PERFORISTA | F19: EDM47K-2 | G19: HQ | H19: 1000-1500 | I19: 1.15 | J19: PRESENTE
B20: 13 | C20: 20718093-9 | D20: =IFERROR(VLOOKUP(C20,'Lista desplegable'!B$1:C$436,2,FALSE),"") -> IGNACIO ALEJANDRO ROBLES BARRIOS | E20: =IFERROR(VLOOKUP(D20,'Lista desplegable'!C$1:D$436,2,FALSE),"") -> AYUDANTE DE PERFORISTA | F20: EDM47K-2 | G20: HQ | H20: 1000-1500 | I20: 1.15 | J20: PRESENTE | K20: SI | L20: SI
B21: 14 | C21: 16188552-5 | D21: =IFERROR(VLOOKUP(C21,'Lista desplegable'!B$1:C$436,2,FALSE),"") -> RODRIGO ALEJANDRO FLORES ZEPEDA | E21: =IFERROR(VLOOKUP(D21,'Lista desplegable'!C$1:D$436,2,FALSE),"") -> AYUDANTE DE PERFORISTA | F21: EDM47K-2 | G21: HQ | H21: 1000-1500 | I21: 1.15 | J21: PRESENTE | K21: SI | L21: SI
B22: 15 | C22: 19949787-1 | D22: =IFERROR(VLOOKUP(C22,'Lista desplegable'!B$1:C$436,2,FALSE),"") -> FABIAN PATRICIO CABRERA GODOY | E22: =IFERROR(VLOOKUP(D22,'Lista desplegable'!C$1:D$436,2,FALSE),"") -> AYUDANTE DE PERFORISTA | F22: EDM47K-2 | G22: HQ | H22: 1000-1500 | I22: 1.15 | J22: PRESENTE | K22: SI | L22: SI
B23: 16 | C23: 15814058-6 | D23: =IFERROR(VLOOKUP(C23,'Lista desplegable'!B$1:C$436,2,FALSE),"") -> ULINSON DIAZ CORTES | E23: =IFERROR(VLOOKUP(D23,'Lista desplegable'!C$1:D$436,2,FALSE),"") -> SUPERVISOR DE OPERACIONES | F23: EDM47K-2 | G23: HQ | H23: 1000-1500 | I23: 1.15 | J23: PRESENTE | K23: SI | L23: SI
B24: 17 | D24: =IFERROR(VLOOKUP(C24,'Lista desplegable'!B$1:C$436,2,FALSE),"") | E24: =IFERROR(VLOOKUP(D24,'Lista desplegable'!C$1:D$436,2,FALSE),"")
B25: 18 | D25: =IFERROR(VLOOKUP(C25,'Lista desplegable'!B$1:C$436,2,FALSE),"") | E25: =IFERROR(VLOOKUP(D25,'Lista desplegable'!C$1:D$436,2,FALSE),"")
B26: 19 | D26: =IFERROR(VLOOKUP(C26,'Lista desplegable'!B$1:C$436,2,FALSE),"") | E26: =IFERROR(VLOOKUP(D26,'Lista desplegable'!C$1:D$436,2,FALSE),"")
B27: 20 | D27: =IFERROR(VLOOKUP(C27,'Lista desplegable'!B$1:C$436,2,FALSE),"") | E27: =IFERROR(VLOOKUP(D27,'Lista desplegable'!C$1:D$436,2,FALSE),"")
B28: 21 | D28: =IFERROR(VLOOKUP(C28,'Lista desplegable'!B$1:C$436,2,FALSE),"") | E28: =IFERROR(VLOOKUP(D28,'Lista desplegable'!C$1:D$436,2,FALSE),"")
B29: 22 | D29: =IFERROR(VLOOKUP(C29,'Lista desplegable'!B$1:C$436,2,FALSE),"") | E29: =IFERROR(VLOOKUP(D29,'Lista desplegable'!C$1:D$436,2,FALSE),"")
B30: 23 | D30: =IFERROR(VLOOKUP(C30,'Lista desplegable'!B$1:C$436,2,FALSE),"") | E30: =IFERROR(VLOOKUP(D30,'Lista desplegable'!C$1:D$436,2,FALSE),"")
B31: 24 | D31: =IFERROR(VLOOKUP(C31,'Lista desplegable'!B$1:C$436,2,FALSE),"") | E31: =IFERROR(VLOOKUP(D31,'Lista desplegable'!C$1:D$436,2,FALSE),"")
B32: 25 | D32: =IFERROR(VLOOKUP(C32,'Lista desplegable'!B$1:C$436,2,FALSE),"") | E32: =IFERROR(VLOOKUP(D32,'Lista desplegable'!C$1:D$436,2,FALSE),"")
B33: 26 | D33: =IFERROR(VLOOKUP(C33,'Lista desplegable'!B$1:C$436,2,FALSE),"") | E33: =IFERROR(VLOOKUP(D33,'Lista desplegable'!C$1:D$436,2,FALSE),"")
B34: 27 | D34: =IFERROR(VLOOKUP(C34,'Lista desplegable'!B$1:C$436,2,FALSE),"") | E34: =IFERROR(VLOOKUP(D34,'Lista desplegable'!C$1:D$436,2,FALSE),"")
B35: 28 | D35: =IFERROR(VLOOKUP(C35,'Lista desplegable'!B$1:C$436,2,FALSE),"") | E35: =IFERROR(VLOOKUP(D35,'Lista desplegable'!C$1:D$436,2,FALSE),"")
... B37: 30 | D37: =IFERROR(VLOOKUP(C37,'Lista desplegable'!B$1:C$436,2,FALSE),"") | E37: =IFERROR(VLOOKUP(D37,'Lista desplegable'!C$1:D$436,2,FALSE),"")
C40: TURNO NOCHE - (A o B según fuera el caso)
B41: N° | C41: RUT | D41: NOMBRES Y APELLIDOS | E41: CARGO | F41: MAQUINA | G41: DIAMETRO | H41: ESCALA | I41: METROS | J41: ASISTENCIA | K41: WORKERA ENTRADA | L41: WORKERA SALIDA | M41: OBSERVACIONES
B42: 1 | C42: 14043656-9 | D42: =IFERROR(VLOOKUP(C42,'Lista desplegable'!B$1:C$436,2,FALSE),"") -> LEONARDO ANDRES MENESES ARREDONDO | E42: =IFERROR(VLOOKUP(D42,'Lista desplegable'!C$1:D$436,2,FALSE),"") -> SUPERVISOR DE OPERACIONES | F42: EDM47K-2 | G42: HQ | H42: 1000-1500 | I42: 0 | J42: PRESENTE | K42: SI | L42: SI
B43: 2 | C43: 23868099-9 | D43: =IFERROR(VLOOKUP(C43,'Lista desplegable'!B$1:C$436,2,FALSE),"") -> JORGE ARMANDO TINOCO OSPINO | E43: =IFERROR(VLOOKUP(D43,'Lista desplegable'!C$1:D$436,2,FALSE),"") -> CHOFER | F43: EDM47K-2 | G43: HQ | H43: 1000-1500 | I43: 0 | J43: PRESENTE | K43: SI | L43: SI
B44: 3 | C44: 17805184-9 | D44: =IFERROR(VLOOKUP(C44,'Lista desplegable'!B$1:C$436,2,FALSE),"") -> BENJAMIN JOSEFATT ESPINOZA URIBE | E44: =IFERROR(VLOOKUP(D44,'Lista desplegable'!C$1:D$436,2,FALSE),"") -> CHOFER | F44: EDM47K-2 | G44: HQ | H44: 1000-1500 | I44: 0 | J44: PRESENTE | K44: SI | L44: SI
B45: 4 | C45: 17805184-9 | D45: =IFERROR(VLOOKUP(C45,'Lista desplegable'!B$1:C$436,2,FALSE),"") -> BENJAMIN JOSEFATT ESPINOZA URIBE | E45: =IFERROR(VLOOKUP(D45,'Lista desplegable'!C$1:D$436,2,FALSE),"") -> CHOFER | F45: EDM47K-2 | G45: HQ | H45: 1000-1500 | I45: 0 | J45: PRESENTE | K45: SI | L45: SI
B46: 5 | C46: 21254681-K | D46: =IFERROR(VLOOKUP(C46,'Lista desplegable'!B$1:C$436,2,FALSE),"") -> JORGE ERIKSON DURAND RUIZ | E46: =IFERROR(VLOOKUP(D46,'Lista desplegable'!C$1:D$436,2,FALSE),"") -> MECANICO | F46: EDM47K-2 | G46: HQ | H46: 1000-1500 | I46: 0 | J46: PRESENTE | K46: SI | L46: SI
...

Sheet 02
G2: DIA
D3: PROYECTO: | E3: LA COIPA | G3: 46267
C6: TURNO DIA - (A o B según fuera el caso)
B7: N° | C7: RUT | D7: NOMBRES Y APELLIDOS | E7: CARGO | F7: MAQUINA | G7: DIAMETRO | H7: ESCALA | I7: METROS | J7: ASISTENCIA | K7: WORKERA ENTRADA | L7: WORKERA SALIDA | M7: OBSERVACIONES
B8: 1 | C8: 14413231-9 | D8: =IFERROR(VLOOKUP(C8,'Lista desplegable'!B$1:C$436,2,FALSE),"") -> JOSE CRISTIAN BASTIAS PEREZ | E8: =IFERROR(VLOOKUP(D8,'Lista desplegable'!C$1:D$436,2,FALSE),"") -> SUPERVISOR DE OPERACIONES | F8: EDM47K-2 | G8: HQ | H8: 1000-1500 | I8: 10.3 | J8: PRESENTE | K8: SI | L8: SI | M8: Marca doble.
B9: 2 | C9: 44623904-K | D9: =IFERROR(VLOOKUP(C9,'Lista desplegable'!B$1:C$436,2,FALSE),"") -> DAYNE JEFFERY PASSMORE . | E9: =IFERROR(VLOOKUP(D9,'Lista desplegable'!C$1:D$436,2,FALSE),"") -> ADMINISTRADOR DE CONTRATO | F9: EDM47K-2 | G9: HQ | H9: 1000-1500 | I9: 10.3 | J9: PRESENTE
B10: 3 | C10: 18352777-0 | D10: =IFERROR(VLOOKUP(C10,'Lista desplegable'!B$1:C$436,2,FALSE),"") -> NORA ALEXANDRA SALAS ROJAS | E10: =IFERROR(VLOOKUP(D10,'Lista desplegable'!C$1:D$436,2,FALSE),"") -> PREVENCIONISTA DE RIESGOS | F10: EDM47K-2 | G10: HQ | H10: 1000-1500 | I10: 10.3 | J10: PRESENTE | K10: SI | L10: SI | M10: Trasladada a dos amigos.
B11: 4 | C11: 21516063-7 | D11: =IFERROR(VLOOKUP(C11,'Lista desplegable'!B$1:C$436,2,FALSE),"") -> NATALY ANTONIA SALAS ESCOBAR | E11: =IFERROR(VLOOKUP(D11,'Lista desplegable'!C$1:D$436,2,FALSE),"") -> ADMINISTRATIVO DE FAENA | F11: EDM47K-2 | G11: HQ | H11: 1000-1500 | I11: 10.3 | J11: PRESENTE | K11: SI | L11: SI
B12: 5 | C12: 13855440-6 | D12: =IFERROR(VLOOKUP(C12,'Lista desplegable'!B$1:C$436,2,FALSE),"") -> PAOLO ALEJANDRO MANRIQUEZ SILVA | E12: =IFERROR(VLOOKUP(D12,'Lista desplegable'!C$1:D$436,2,FALSE),"") -> BODEGUERO | F12: EDM47K-2 | G12: HQ | H12: 1000-1500 | I12: 10.3 | J12: PRESENTE | K12: SI | L12: SI | M12: Marca doble.
B13: 6 | C13: 15593625-8 | D13: =IFERROR(VLOOKUP(C13,'Lista desplegable'!B$1:C$436,2,FALSE),"") -> CARLOS EDUARDO RODRIGUEZ HERNANDEZ | E13: =IFERROR(VLOOKUP(D13,'Lista desplegable'!C$1:D$436,2,FALSE),"") -> ADMINISTRADOR DE CONTRATO | F13: EDM47K-2 | G13: HQ | H13: 1000-1500 | I13: 10.3 | J13: PRESENTE | K13: SI | L13: SI
B14: 7 | C14: 25832490-0 | D14: =IFERROR(VLOOKUP(C14,'Lista desplegable'!B$1:C$436,2,FALSE),"") -> JOSÉ LEONARDO RODRIGUEZ ROBLES | E14: =IFERROR(VLOOKUP(D14,'Lista desplegable'!C$1:D$436,2,FALSE),"") -> CHOFER | F14: EDM47K-2 | G14: HQ | H14: 1000-1500 | I14: 10.3 | J14: PRESENTE | K14: SI | L14: SI
B15: 8 | C15: 12152241-1 | D15: =IFERROR(VLOOKUP(C15,'Lista desplegable'!B$1:C$436,2,FALSE),"") -> JORGE ESTEBAN SAAVEDRA MENA | E15: =IFERROR(VLOOKUP(D15,'Lista desplegable'!C$1:D$436,2,FALSE),"") -> CHOFER | F15: EDM47K-2 | G15: HQ | H15: 1000-1500 | I15: 10.3 | J15: PRESENTE | K15: SI | L15: SI
B16: 9 | C16: 20173381-2 | D16: =IFERROR(VLOOKUP(C16,'Lista desplegable'!B$1:C$436,2,FALSE),"") -> ELIAS NICOLAS CORTEZ CORTEZ | E16: =IFERROR(VLOOKUP(D16,'Lista desplegable'!C$1:D$436,2,FALSE),"") -> CHOFER | F16: EDM47K-2 | G16: HQ | H16: 1000-1500 | I16: 10.3 | J16: PRESENTE | K16: SI | L16: SI
B17: 10 | C17: 13412582-9 | D17: =IFERROR(VLOOKUP(C17,'Lista desplegable'!B$1:C$436,2,FALSE),"") -> ALEJANDRO ALBERTO CAMPILLAY RUIZ | E17: =IFERROR(VLOOKUP(D17,'Lista desplegable'!C$1:D$436,2,FALSE),"") -> MECANICO | F17: EDM47K-2 | G17: HQ | H17: 1000-1500 | I17: 10.3 | J17: PRESENTE | K17: SI | L17: SI
B18: 11 | C18: 13744310-4 | D18: =IFERROR(VLOOKUP(C18,'Lista desplegable'!B$1:C$436,2,FALSE),"") -> WALDO RAFAEL CASTRO PASTENE | E18: =IFERROR(VLOOKUP(D18,'Lista desplegable'!C$1:D$436,2,FALSE),"") -> SOLDADOR | F18: EDM47K-2 | G18: HQ | H18: 1000-1500 | I18: 10.3 | J18: PRESENTE | K18: SI | L18: SI | M18: Marca doble.
B19: 12 | C19: 44591746-K | D19: =IFERROR(VLOOKUP(C19,'Lista desplegable'!B$1:C$436,2,FALSE),"") -> GANTSOOJ KHISHIGBAYAR . | E19: =IFERROR(VLOOKUP(D19,'Lista desplegable'!C$1:D$436,2,FALSE),"") -> PERFORISTA | F19: EDM47K-2 | G19: HQ | H19: 1000-1500 | I19: 10.3 | J19: PRESENTE
B20: 13 | C20: 21294612-5 | D20: =IFERROR(VLOOKUP(C20,'Lista desplegable'!B$1:C$436,2,FALSE),"") -> VICENTE ANDRES LOPEZ MARTINEZ | E20: =IFERROR(VLOOKUP(D20,'Lista desplegable'!C$1:D$436,2,FALSE),"") -> AYUDANTE DE PERFORISTA | F20: EDM47K-2 | G20: HQ | H20: 1000-1500 | I20: 10.3 | J20: PRESENTE | K20: SI | L20: SI
B21: 14 | C21: 17721340-3 | D21: =IFERROR(VLOOKUP(C21,'Lista desplegable'!B$1:C$436,2,FALSE),"") -> CARLOS ALBERTO PIZARRO PIZARRO | E21: =IFERROR(VLOOKUP(D21,'Lista desplegable'!C$1:D$436,2,FALSE),"") -> AYUDANTE DE PERFORISTA | F21: EDM47K-2 | G21: HQ | H21: 1000-1500 | I21: 10.3 | J21: PRESENTE | K21: SI | L21: SI
B22: 15 | C22: 18450168-6 | D22: =IFERROR(VLOOKUP(C22,'Lista desplegable'!B$1:C$436,2,FALSE),"") -> FELIPE DAVID SAAVEDRA CAMPOS | E22: =IFERROR(VLOOKUP(D22,'Lista desplegable'!C$1:D$436,2,FALSE),"") -> AYUDANTE DE PERFORISTA | F22: EDM47K-2 | G22: HQ | H22: 1000-1500 | I22: 10.3 | J22: PRESENTE | K22: SI | L22: SI
B23: 16 | C23: 8851229-4 | D23: =IFERROR(VLOOKUP(C23,'Lista desplegable'!B$1:C$436,2,FALSE),"") -> LUIS HUMBERTO PEÑA AHUMADA | E23: =IFERROR(VLOOKUP(D23,'Lista desplegable'!C$1:D$436,2,FALSE),"") -> CHOFER | F23: EDM47K-2 | G23: HQ | H23: 1000-1500 | I23: 10.3 | J23: PRESENTE | K23: SI | L23: SI
B24: 17 | D24: =IFERROR(VLOOKUP(C24,'Lista desplegable'!B$1:C$436,2,FALSE),"") | E24: =IFERROR(VLOOKUP(D24,'Lista desplegable'!C$1:D$436,2,FALSE),"")
B25: 18 | D25: =IFERROR(VLOOKUP(C25,'Lista desplegable'!B$1:C$436,2,FALSE),"") | E25: =IFERROR(VLOOKUP(D25,'Lista desplegable'!C$1:D$436,2,FALSE),"")
B26: 19 | D26: =IFERROR(VLOOKUP(C26,'Lista desplegable'!B$1:C$436,2,FALSE),"") | E26: =IFERROR(VLOOKUP(D26,'Lista desplegable'!C$1:D$436,2,FALSE),"")
B27: 20 | D27: =IFERROR(VLOOKUP(C27,'Lista desplegable'!B$1:C$436,2,FALSE),"") | E27: =IFERROR(VLOOKUP(D27,'Lista desplegable'!C$1:D$436,2,FALSE),"")
B28: 21 | D28: =IFERROR(VLOOKUP(C28,'Lista desplegable'!B$1:C$436,2,FALSE),"") | E28: =IFERROR(VLOOKUP(D28,'Lista desplegable'!C$1:D$436,2,FALSE),"")
B29: 22 | D29: =IFERROR(VLOOKUP(C29,'Lista desplegable'!B$1:C$436,2,FALSE),"") | E29: =IFERROR(VLOOKUP(D29,'Lista desplegable'!C$1:D$436,2,FALSE),"")
B30: 23 | D30: =IFERROR(VLOOKUP(C30,'Lista desplegable'!B$1:C$436,2,FALSE),"") | E30: =IFERROR(VLOOKUP(D30,'Lista desplegable'!C$1:D$436,2,FALSE),"")
B31: 24 | D31: =IFERROR(VLOOKUP(C31,'Lista desplegable'!B$1:C$436,2,FALSE),"") | E31: =IFERROR(VLOOKUP(D31,'Lista desplegable'!C$1:D$436,2,FALSE),"")
B32: 25 | D32: =IFERROR(VLOOKUP(C32,'Lista desplegable'!B$1:C$436,2,FALSE),"") | E32: =IFERROR(VLOOKUP(D32,'Lista desplegable'!C$1:D$436,2,FALSE),"")
B33: 26 | D33: =IFERROR(VLOOKUP(C33,'Lista desplegable'!B$1:C$436,2,FALSE),"") | E33: =IFERROR(VLOOKUP(D33,'Lista desplegable'!C$1:D$436,2,FALSE),"")
B34: 27 | D34: =IFERROR(VLOOKUP(C34,'Lista desplegable'!B$1:C$436,2,FALSE),"") | E34: =IFERROR(VLOOKUP(D34,'Lista desplegable'!C$1:D$436,2,FALSE),"")
B35: 28 | D35: =IFERROR(VLOOKUP(C35,'Lista desplegable'!B$1:C$436,2,FALSE),"") | E35: =IFERROR(VLOOKUP(D35,'Lista desplegable'!C$1:D$436,2,FALSE),"")
... B37: 30 | D37: =IFERROR(VLOOKUP(C37,'Lista desplegable'!B$1:C$436,2,FALSE),"") | E37: =IFERROR(VLOOKUP(D37,'Lista desplegable'!C$1:D$436,2,FALSE),"")
C40: TURNO NOCHE - (A o B según fuera el caso)
B41: N° | C41: RUT | D41: NOMBRES Y APELLIDOS | E41: CARGO | F41: MAQUINA | G41: DIAMETRO | H41: ESCALA | I41: METROS | J41: ASISTENCIA | K41: WORKERA ENTRADA | L41: WORKERA SALIDA | M41: OBSERVACIONES
B42: 1 | C42: 15613806-1 | D42: =IFERROR(VLOOKUP(C42,'Lista desplegable'!B$1:C$436,2,FALSE),"") -> ARIEL ANDRES SILVA RIQUELME | E42: =IFERROR(VLOOKUP(D42,'Lista desplegable'!C$1:D$436,2,FALSE),"") -> SUPERVISOR DE OPERACIONES | F42: EDM47K-2 | G42: HQ | H42: 1000-1500 | I42: 8.9 | J42: PRESENTE | K42: SI | L42: SI
B43: 2 | C43: 18919440-4 | D43: =IFERROR(VLOOKUP(C43,'Lista desplegable'!B$1:C$436,2,FALSE),"") -> ALISSON AYLEEN VILLAGRA CABALLERO | E43: =IFERROR(VLOOKUP(D43,'Lista desplegable'!C$1:D$436,2,FALSE),"") -> CHOFER | F43: EDM47K-2 | G43: HQ | H43: 1000-1500 | I43: 8.9 | J43: PRESENTE | K43: SI | L43: SI
B44: 3 | C44: 19804200-5 | D44: =IFERROR(VLOOKUP(C44,'Lista desplegable'!B$1:C$436,2,FALSE),"") -> MANUEL ALEJANDRO TILLERIA SAAVEDRA | E44: =IFERROR(VLOOKUP(D44,'Lista desplegable'!C$1:D$436,2,FALSE),"") -> MECANICO | F44: EDM47K-2 | G44: HQ | H44: 1000-1500 | I44: 8.9 | J44: PRESENTE | K44: SI | L44: SI
B45: 4 | C45: 28683244-K | D45: =IFERROR(VLOOKUP(C45,'Lista desplegable'!B$1:C$436,2,FALSE),"") -> ARIUNBOLD TSOGKHORKHOI . | E45: =IFERROR(VLOOKUP(D45,'Lista desplegable'!C$1:D$436,2,FALSE),"") -> PERFORISTA | F45: EDM47K-2 | G45: HQ | H45: 1000-1500 | I45: 8.9 | J45: PRESENTE
B46: 5 | C46: 11934921-4 | D46: =IFERROR(VLOOKUP(C46,'Lista desplegable'!B$1:C$436,2,FALSE),"") -> EDINSON RODRIGO GONZALEZ CORTINEZ | E46: =IFERROR(VLOOKUP(D46,'Lista desplegable'!C$1:D$436,2,FALSE),"") -> AYUDANTE DE PERFORISTA | F46: EDM47K-2 | G46: HQ | H46: 1000-1500 | I46: 8.9 | J46: PRESENTE | K46: SI | L46: SI | M46: Marcaciones en coipa 2.
...

Sheet 03
G2: DIA
D3: PROYECTO: | E3: LA COIPA | G3: 46268
C6: TURNO DIA - (A o B según fuera el caso)
B7: N° | C7: RUT | D7: NOMBRES Y APELLIDOS | E7: CARGO | F7: MAQUINA | G7: DIAMETRO | H7: ESCALA | I7: METROS | J7: ASISTENCIA | K7: WORKERA ENTRADA | L7: WORKERA SALIDA | M7: OBSERVACIONES
B8: 1 | C8: 14413231-9 | D8: =IFERROR(VLOOKUP(C8,'Lista desplegable'!B$1:C$436,2,FALSE),"") -> JOSE CRISTIAN BASTIAS PEREZ | E8: =IFERROR(VLOOKUP(D8,'Lista desplegable'!C$1:D$436,2,FALSE),"") -> SUPERVISOR DE OPERACIONES | F8: EDM47K-2 | G8: HQ | H8: 1000-1500 | I8: 12.1 | J8: PRESENTE | K8: SI | L8: SI
B9: 2 | C9: 44623904-K | D9: =IFERROR(VLOOKUP(C9,'Lista desplegable'!B$1:C$436,2,FALSE),"") -> DAYNE JEFFERY PASSMORE . | E9: =IFERROR(VLOOKUP(D9,'Lista desplegable'!C$1:D$436,2,FALSE),"") -> ADMINISTRADOR DE CONTRATO | F9: EDM47K-2 | G9: HQ | H9: 1000-1500 | I9: 12.1 | J9: PRESENTE | M9: Trasladada a dos amigos.
B10: 3 | C10: 18352777-0 | D10: =IFERROR(VLOOKUP(C10,'Lista desplegable'!B$1:C$436,2,FALSE),"") -> NORA ALEXANDRA SALAS ROJAS | E10: =IFERROR(VLOOKUP(D10,'Lista desplegable'!C$1:D$436,2,FALSE),"") -> PREVENCIONISTA DE RIESGOS | F10: EDM47K-2 | G10: HQ | H10: 1000-1500 | I10: 12.1 | J10: PRESENTE | K10: SI | L10: SI
B11: 4 | C11: 21516063-7 | D11: =IFERROR(VLOOKUP(C11,'Lista desplegable'!B$1:C$436,2,FALSE),"") -> NATALY ANTONIA SALAS ESCOBAR | E11: =IFERROR(VLOOKUP(D11,'Lista desplegable'!C$1:D$436,2,FALSE),"") -> ADMINISTRATIVO DE FAENA | F11: EDM47K-2 | G11: HQ | H11: 1000-1500 | I11: 12.1 | J11: PRESENTE | K11: SI | L11: SI
B12: 5 | C12: 13855440-6 | D12: =IFERROR(VLOOKUP(C12,'Lista desplegable'!B$1:C$436,2,FALSE),"") -> PAOLO ALEJANDRO MANRIQUEZ SILVA | E12: =IFERROR(VLOOKUP(D12,'Lista desplegable'!C$1:D$436,2,FALSE),"") -> BODEGUERO | F12: EDM47K-2 | G12: HQ | H12: 1000-1500 | I12: 12.1 | J12: PRESENTE | K12: SI | L12: SI
B13: 6 | C13: 15593625-8 | D13: =IFERROR(VLOOKUP(C13,'Lista desplegable'!B$1:C$436,2,FALSE),"") -> CARLOS EDUARDO RODRIGUEZ HERNANDEZ | E13: =IFERROR(VLOOKUP(D13,'Lista desplegable'!C$1:D$436,2,FALSE),"") -> ADMINISTRADOR DE CONTRATO | F13: EDM47K-2 | G13: HQ | H13: 1000-1500 | I13: 12.1 | J13: PRESENTE | K13: SI | L13: SI
B14: 7 | C14: 25832490-0 | D14: =IFERROR(VLOOKUP(C14,'Lista desplegable'!B$1:C$436,2,FALSE),"") -> JOSÉ LEONARDO RODRIGUEZ ROBLES | E14: =IFERROR(VLOOKUP(D14,'Lista desplegable'!C$1:D$436,2,FALSE),"") -> CHOFER | F14: EDM47K-2 | G14: HQ | H14: 1000-1500 | I14: 12.1 | J14: PRESENTE | K14: SI | L14: SI
B15: 8 | C15: 12152241-1 | D15: =IFERROR(VLOOKUP(C15,'Lista desplegable'!B$1:C$436,2,FALSE),"") -> JORGE ESTEBAN SAAVEDRA MENA | E15: =IFERROR(VLOOKUP(D15,'Lista desplegable'!C$1:D$436,2,FALSE),"") -> CHOFER | F15: EDM47K-2 | G15: HQ | H15: 1000-1500 | I15: 12.1 | J15: PRESENTE | K15: SI | L15: SI
B16: 9 | C16: 20173381-2 | D16: =IFERROR(VLOOKUP(C16,'Lista desplegable'!B$1:C$436,2,FALSE),"") -> ELIAS NICOLAS CORTEZ CORTEZ | E16: =IFERROR(VLOOKUP(D16,'Lista desplegable'!C$1:D$436,2,FALSE),"") -> CHOFER | F16: EDM47K-2 | G16: HQ | H16: 1000-1500 | I16: 12.1 | J16: PRESENTE | K16: SI | L16: SI
B17: 10 | C17: 13412582-9 | D17: =IFERROR(VLOOKUP(C17,'Lista desplegable'!B$1:C$436,2,FALSE),"") -> ALEJANDRO ALBERTO CAMPILLAY RUIZ | E17: =IFERROR(VLOOKUP(D17,'Lista desplegable'!C$1:D$436,2,FALSE),"") -> MECANICO | F17: EDM47K-2 | G17: HQ | H17: 1000-1500 | I17: 12.1 | J17: PRESENTE | K17: SI | L17: SI
B18: 11 | C18: 13744310-4 | D18: =IFERROR(VLOOKUP(C18,'Lista desplegable'!B$1:C$436,2,FALSE),"") -> WALDO RAFAEL CASTRO PASTENE | E18: =IFERROR(VLOOKUP(D18,'Lista desplegable'!C$1:D$436,2,FALSE),"") -> SOLDADOR | F18: EDM47K-2 | G18: HQ | H18: 1000-1500 | I18: 12.1 | J18: PRESENTE | K18: SI | L18: SI
B19: 12 | C19: 44591746-K | D19: =IFERROR(VLOOKUP(C19,'Lista desplegable'!B$1:C$436,2,FALSE),"") -> GANTSOOJ KHISHIGBAYAR . | E19: =IFERROR(VLOOKUP(D19,'Lista desplegable'!C$1:D$436,2,FALSE),"") -> PERFORISTA | F19: EDM47K-2 | G19: HQ | H19: 1000-1500 | I19: 12.1 | J19: PRESENTE
B20: 13 | C20: 21294612-5 | D20: =IFERROR(VLOOKUP(C20,'Lista desplegable'!B$1:C$436,2,FALSE),"") -> VICENTE ANDRES LOPEZ MARTINEZ | E20: =IFERROR(VLOOKUP(D20,'Lista desplegable'!C$1:D$436,2,FALSE),"") -> AYUDANTE DE PERFORISTA | F20: EDM47K-2 | G20: HQ | H20: 1000-1500 | I20: 12.1 | J20: PRESENTE | K20: SI | L20: SI
B21: 14 | C21: 17721340-3 | D21: =IFERROR(VLOOKUP(C21,'Lista desplegable'!B$1:C$436,2,FALSE),"") -> CARLOS ALBERTO PIZARRO PIZARRO | E21: =IFERROR(VLOOKUP(D21,'Lista desplegable'!C$1:D$436,2,FALSE),"") -> AYUDANTE DE PERFORISTA | F21: EDM47K-2 | G21: HQ | H21: 1000-1500 | I21: 12.1 | J21: PRESENTE | K21: SI | L21: SI
B22: 15 | C22: 18450168-6 | D22: =IFERROR(VLOOKUP(C22,'Lista desplegable'!B$1:C$436,2,FALSE),"") -> FELIPE DAVID SAAVEDRA CAMPOS | E22: =IFERROR(VLOOKUP(D22,'Lista desplegable'!C$1:D$436,2,FALSE),"") -> AYUDANTE DE PERFORISTA | F22: EDM47K-2 | G22: HQ | H22: 1000-1500 | I22: 12.1 | J22: PRESENTE | K22: SI | L22: SI
B23: 16 | C23: 8851229-4 | D23: =IFERROR(VLOOKUP(C23,'Lista desplegable'!B$1:C$436,2,FALSE),"") -> LUIS HUMBERTO PEÑA AHUMADA | E23: =IFERROR(VLOOKUP(D23,'Lista desplegable'!C$1:D$436,2,FALSE),"") -> CHOFER | F23: EDM47K-2 | G23: HQ | H23: 1000-1500 | I23: 12.1 | J23: PRESENTE | K23: SI | L23: SI
B24: 17 | D24: =IFERROR(VLOOKUP(C24,'Lista desplegable'!B$1:C$436,2,FALSE),"") | E24: =IFERROR(VLOOKUP(D24,'Lista desplegable'!C$1:D$436,2,FALSE),"")
B25: 18 | D25: =IFERROR(VLOOKUP(C25,'Lista desplegable'!B$1:C$436,2,FALSE),"") | E25: =IFERROR(VLOOKUP(D25,'Lista desplegable'!C$1:D$436,2,FALSE),"")
B26: 19 | D26: =IFERROR(VLOOKUP(C26,'Lista desplegable'!B$1:C$436,2,FALSE),"") | E26: =IFERROR(VLOOKUP(D26,'Lista desplegable'!C$1:D$436,2,FALSE),"")
B27: 20 | D27: =IFERROR(VLOOKUP(C27,'Lista desplegable'!B$1:C$436,2,FALSE),"") | E27: =IFERROR(VLOOKUP(D27,'Lista desplegable'!C$1:D$436,2,FALSE),"")
B28: 21 | D28: =IFERROR(VLOOKUP(C28,'Lista desplegable'!B$1:C$436,2,FALSE),"") | E28: =IFERROR(VLOOKUP(D28,'Lista desplegable'!C$1:D$436,2,FALSE),"")
B29: 22 | D29: =IFERROR(VLOOKUP(C29,'Lista desplegable'!B$1:C$436,2,FALSE),"") | E29: =IFERROR(VLOOKUP(D29,'Lista desplegable'!C$1:D$436,2,FALSE),"")
B30: 23 | D30: =IFERROR(VLOOKUP(C30,'Lista desplegable'!B$1:C$436,2,FALSE),"") | E30: =IFERROR(VLOOKUP(D30,'Lista desplegable'!C$1:D$436,2,FALSE),"")
B31: 24 | D31: =IFERROR(VLOOKUP(C31,'Lista desplegable'!B$1:C$436,2,FALSE),"") | E31: =IFERROR(VLOOKUP(D31,'Lista desplegable'!C$1:D$436,2,FALSE),"")
B32: 25 | D32: =IFERROR(VLOOKUP(C32,'Lista desplegable'!B$1:C$436,2,FALSE),"") | E32: =IFERROR(VLOOKUP(D32,'Lista desplegable'!C$1:D$436,2,FALSE),"")
B33: 26 | D33: =IFERROR(VLOOKUP(C33,'Lista desplegable'!B$1:C$436,2,FALSE),"") | E33: =IFERROR(VLOOKUP(D33,'Lista desplegable'!C$1:D$436,2,FALSE),"")
B34: 27 | D34: =IFERROR(VLOOKUP(C34,'Lista desplegable'!B$1:C$436,2,FALSE),"") | E34: =IFERROR(VLOOKUP(D34,'Lista desplegable'!C$1:D$436,2,FALSE),"")
B35: 28 | D35: =IFERROR(VLOOKUP(C35,'Lista desplegable'!B$1:C$436,2,FALSE),"") | E35: =IFERROR(VLOOKUP(D35,'Lista desplegable'!C$1:D$436,2,FALSE),"")
... B37: 30 | D37: =IFERROR(VLOOKUP(C37,'Lista desplegable'!B$1:C$436,2,FALSE),"") | E37: =IFERROR(VLOOKUP(D37,'Lista desplegable'!C$1:D$436,2,FALSE),"")
C40: TURNO NOCHE - (A o B según fuera el caso)
B41: N° | C41: RUT | D41: NOMBRES Y APELLIDOS | E41: CARGO | F41: MAQUINA | G41: DIAMETRO | H41: ESCALA | I41: METROS | J41: ASISTENCIA | K41: WORKERA ENTRADA | L41: WORKERA SALIDA | M41: OBSERVACIONES
B42: 1 | C42: 15613806-1 | D42: =IFERROR(VLOOKUP(C42,'Lista desplegable'!B$1:C$436,2,FALSE),"") -> ARIEL ANDRES SILVA RIQUELME | E42: =IFERROR(VLOOKUP(D42,'Lista desplegable'!C$1:D$436,2,FALSE),"") -> SUPERVISOR DE OPERACIONES | F42: EDM47K-2 | G42: HQ | H42: 1000-1500 | I42: 15 | J42: PRESENTE | K42: SI | L42: SI | M42: Marcó de día.
B43: 2 | C43: 18919440-4 | D43: =IFERROR(VLOOKUP(C43,'Lista desplegable'!B$1:C$436,2,FALSE),"") -> ALISSON AYLEEN VILLAGRA CABALLERO | E43: =IFERROR(VLOOKUP(D43,'Lista desplegable'!C$1:D$436,2,FALSE),"") -> CHOFER | F43: EDM47K-2 | G43: HQ | H43: 1000-1500 | I43: 15 | J43: PRESENTE | K43: SI | L43: SI
B44: 3 | C44: 19804200-5 | D44: =IFERROR(VLOOKUP(C44,'Lista desplegable'!B$1:C$436,2,FALSE),"") -> MANUEL ALEJANDRO TILLERIA SAAVEDRA | E44: =IFERROR(VLOOKUP(D44,'Lista desplegable'!C$1:D$436,2,FALSE),"") -> MECANICO | F44: EDM47K-2 | G44: HQ | H44: 1000-1500 | I44: 15 | J44: PRESENTE | K44: SI | L44: SI
B45: 4 | C45: 28683244-K | D45: =IFERROR(VLOOKUP(C45,'Lista desplegable'!B$1:C$436,2,FALSE),"") -> ARIUNBOLD TSOGKHORKHOI . | E45: =IFERROR(VLOOKUP(D45,'Lista desplegable'!C$1:D$436,2,FALSE),"") -> PERFORISTA | F45: EDM47K-2 | G45: HQ | H45: 1000-1500 | I45: 15 | J45: PRESENTE
B46: 5 | C46: 11934921-4 | D46: =IFERROR(VLOOKUP(C46,'Lista desplegable'!B$1:C$436,2,FALSE),"") -> EDINSON RODRIGO GONZALEZ CORTINEZ | E46: =IFERROR(VLOOKUP(D46,'Lista desplegable'!C$1:D$436,2,FALSE),"") -> AYUDANTE DE PERFORISTA | F46: EDM47K-2 | G46: HQ | H46: 1000-1500 | I46: 15 | J46: PRESENTE | K46: SI | L46: SI | M46: Marcaciones en coipa 2.
...

Sheet 04
G2: DIA
D3: PROYECTO: | E3: LA COIPA | G3: 46269
C6: TURNO DIA - (A o B según fuera el caso)
B7: N° | C7: RUT | D7: NOMBRES Y APELLIDOS | E7: CARGO | F7: MAQUINA | G7: DIAMETRO | H7: ESCALA | I7: METROS | J7: ASISTENCIA | K7: WORKERA ENTRADA | L7: WORKERA SALIDA | M7: OBSERVACIONES
B8: 1 | C8: 14413231-9 | D8: =IFERROR(VLOOKUP(C8,'Lista desplegable'!B$1:C$436,2,FALSE),"") -> JOSE CRISTIAN BASTIAS PEREZ | E8: =IFERROR(VLOOKUP(D8,'Lista desplegable'!C$1:D$436,2,FALSE),"") -> SUPERVISOR DE OPERACIONES | F8: EDM47K-2 | G8: HQ | H8: 1000-1500 | I8: 24 | J8: PRESENTE | K8: SI | L8: SI
B9: 2 | C9: 44623904-K | D9: =IFERROR(VLOOKUP(C9,'Lista desplegable'!B$1:C$436,2,FALSE),"") -> DAYNE JEFFERY PASSMORE . | E9: =IFERROR(VLOOKUP(D9,'Lista desplegable'!C$1:D$436,2,FALSE),"") -> ADMINISTRADOR DE CONTRATO | F9: EDM47K-2 | G9: HQ | H9: 1000-1500 | I9: 24 | J9: PRESENTE
B10: 3 | C10: 18352777-0 | D10: =IFERROR(VLOOKUP(C10,'Lista desplegable'!B$1:C$436,2,FALSE),"") -> NORA ALEXANDRA SALAS ROJAS | E10: =IFERROR(VLOOKUP(D10,'Lista desplegable'!C$1:D$436,2,FALSE),"") -> PREVENCIONISTA DE RIESGOS | F10: EDM47K-2 | G10: HQ | H10: 1000-1500 | I10: 24 | J10: PRESENTE | K10: SI | L10: SI | M10: Trasladada a dos amigos.
B11: 4 | C11: 21516063-7 | D11: =IFERROR(VLOOKUP(C11,'Lista desplegable'!B$1:C$436,2,FALSE),"") -> NATALY ANTONIA SALAS ESCOBAR | E11: =IFERROR(VLOOKUP(D11,'Lista desplegable'!C$1:D$436,2,FALSE),"") -> ADMINISTRATIVO DE FAENA | F11: EDM47K-2 | G11: HQ | H11: 1000-1500 | I11: 24 | J11: PRESENTE | K11: SI | L11: SI
B12: 5 | C12: 13855440-6 | D12: =IFERROR(VLOOKUP(C12,'Lista desplegable'!B$1:C$436,2,FALSE),"") -> PAOLO ALEJANDRO MANRIQUEZ SILVA | E12: =IFERROR(VLOOKUP(D12,'Lista desplegable'!C$1:D$436,2,FALSE),"") -> BODEGUERO | F12: EDM47K-2 | G12: HQ | H12: 1000-1500 | I12: 24 | J12: PRESENTE | K12: SI | L12: SI
B13: 6 | C13: 25832490-0 | D13: =IFERROR(VLOOKUP(C13,'Lista desplegable'!B$1:C$436,2,FALSE),"") -> JOSÉ LEONARDO RODRIGUEZ ROBLES | E13: =IFERROR(VLOOKUP(D13,'Lista desplegable'!C$1:D$436,2,FALSE),"") -> CHOFER | F13: EDM47K-2 | G13: HQ | H13: 1000-1500 | I13: 24 | J13: PRESENTE | K13: SI | L13: SI
B14: 7 | C14: 12152241-1 | D14: =IFERROR(VLOOKUP(C14,'Lista desplegable'!B$1:C$436,2,FALSE),"") -> JORGE ESTEBAN SAAVEDRA MENA | E14: =IFERROR(VLOOKUP(D14,'Lista desplegable'!C$1:D$436,2,FALSE),"") -> CHOFER | F14: EDM47K-2 | G14: HQ | H14: 1000-1500 | I14: 24 | J14: PRESENTE | K14: SI | L14: SI
B15: 8 | C15: 20173381-2 | D15: =IFERROR(VLOOKUP(C15,'Lista desplegable'!B$1:C$436,2,FALSE),"") -> ELIAS NICOLAS CORTEZ CORTEZ | E15: =IFERROR(VLOOKUP(D15,'Lista desplegable'!C$1:D$436,2,FALSE),"") -> CHOFER | F15: EDM47K-2 | G15: HQ | H15: 1000-1500 | I15: 24 | J15: PRESENTE | K15: SI | L15: SI
B16: 9 | C16: 13412582-9 | D16: =IFERROR(VLOOKUP(C16,'Lista desplegable'!B$1:C$436,2,FALSE),"") -> ALEJANDRO ALBERTO CAMPILLAY RUIZ | E16: =IFERROR(VLOOKUP(D16,'Lista desplegable'!C$1:D$436,2,FALSE),"") -> MECANICO | F16: EDM47K-2 | G16: HQ | H16: 1000-1500 | I16: 24 | J16: PRESENTE | K16: SI | L16: SI
B17: 10 | C17: 13744310-4 | D17: =IFERROR(VLOOKUP(C17,'Lista desplegable'!B$1:C$436,2,FALSE),"") -> WALDO RAFAEL CASTRO PASTENE | E17: =IFERROR(VLOOKUP(D17,'Lista desplegable'!C$1:D$436,2,FALSE),"") -> SOLDADOR | F17: EDM47K-2 | G17: HQ | H17: 1000-1500 | I17: 24 | J17: PRESENTE | K17: SI | L17: SI
B18: 11 | C18: 44601238-K | D18: =IFERROR(VLOOKUP(C18,'Lista desplegable'!B$1:C$436,2,FALSE),"") -> ENKHZAYA GANBAATAR . | E18: =IFERROR(VLOOKUP(D18,'Lista desplegable'!C$1:D$436,2,FALSE),"") -> PERFORISTA | F18: EDM47K-2 | G18: HQ | H18: 1000-1500 | I18: 24 | J18: PRESENTE
B19: 12 | C19: 21294612-5 | D19: =IFERROR(VLOOKUP(C19,'Lista desplegable'!B$1:C$436,2,FALSE),"") -> VICENTE ANDRES LOPEZ MARTINEZ | E19: =IFERROR(VLOOKUP(D19,'Lista desplegable'!C$1:D$436,2,FALSE),"") -> AYUDANTE DE PERFORISTA | F19: EDM47K-2 | G19: HQ | H19: 1000-1500 | I19: 24 | J19: PRESENTE | K19: SI | L19: SI
B20: 13 | C20: 17721340-3 | D20: =IFERROR(VLOOKUP(C20,'Lista desplegable'!B$1:C$436,2,FALSE),"") -> CARLOS ALBERTO PIZARRO PIZARRO | E20: =IFERROR(VLOOKUP(D20,'Lista desplegable'!C$1:D$436,2,FALSE),"") -> AYUDANTE DE PERFORISTA | F20: EDM47K-2 | G20: HQ | H20: 1000-1500 | I20: 24 | J20: PRESENTE | K20: SI | L20: SI
B21: 14 | C21: 18450168-6 | D21: =IFERROR(VLOOKUP(C21,'Lista desplegable'!B$1:C$436,2,FALSE),"") -> FELIPE DAVID SAAVEDRA CAMPOS | E21: =IFERROR(VLOOKUP(D21,'Lista desplegable'!C$1:D$436,2,FALSE),"") -> AYUDANTE DE PERFORISTA | F21: EDM47K-2 | G21: HQ | H21: 1000-1500 | I21: 24 | J21: PRESENTE | K21: SI | L21: SI
B22: 15 | C22: 8851229-4 | D22: =IFERROR(VLOOKUP(C22,'Lista desplegable'!B$1:C$436,2,FALSE),"") -> LUIS HUMBERTO PEÑA AHUMADA | E22: =IFERROR(VLOOKUP(D22,'Lista desplegable'!C$1:D$436,2,FALSE),"") -> CHOFER | F22: EDM47K-2 | G22: HQ | H22: 1000-1500 | I22: 24 | J22: PRESENTE | K22: SI | L22: SI
B23: 16 | D23: =IFERROR(VLOOKUP(C23,'Lista desplegable'!B$1:C$436,2,FALSE),"") | E23: =IFERROR(VLOOKUP(D23,'Lista desplegable'!C$1:D$436,2,FALSE),"")
B24: 17 | D24: =IFERROR(VLOOKUP(C24,'Lista desplegable'!B$1:C$436,2,FALSE),"") | E24: =IFERROR(VLOOKUP(D24,'Lista desplegable'!C$1:D$436,2,FALSE),"")
B25: 18 | D25: =IFERROR(VLOOKUP(C25,'Lista desplegable'!B$1:C$436,2,FALSE),"") | E25: =IFERROR(VLOOKUP(D25,'Lista desplegable'!C$1:D$436,2,FALSE),"")
B26: 19 | D26: =IFERROR(VLOOKUP(C26,'Lista desplegable'!B$1:C$436,2,FALSE),"") | E26: =IFERROR(VLOOKUP(D26,'Lista desplegable'!C$1:D$436,2,FALSE),"")
B27: 20 | D27: =IFERROR(VLOOKUP(C27,'Lista desplegable'!B$1:C$436,2,FALSE),"") | E27: =IFERROR(VLOOKUP(D27,'Lista desplegable'!C$1:D$436,2,FALSE),"")
B28: 21 | D28: =IFERROR(VLOOKUP(C28,'Lista desplegable'!B$1:C$436,2,FALSE),"") | E28: =IFERROR(VLOOKUP(D28,'Lista desplegable'!C$1:D$436,2,FALSE),"")
B29: 22 | D29: =IFERROR(VLOOKUP(C29,'Lista desplegable'!B$1:C$436,2,FALSE),"") | E29: =IFERROR(VLOOKUP(D29,'Lista desplegable'!C$1:D$436,2,FALSE),"")
B30: 23 | D30: =IFERROR(VLOOKUP(C30,'Lista desplegable'!B$1:C$436,2,FALSE),"") | E30: =IFERROR(VLOOKUP(D30,'Lista desplegable'!C$1:D$436,2,FALSE),"")
B31: 24 | D31: =IFERROR(VLOOKUP(C31,'Lista desplegable'!B$1:C$436,2,FALSE),"") | E31: =IFERROR(VLOOKUP(D31,'Lista desplegable'!C$1:D$436,2,FALSE),"")
B32: 25 | D32: =IFERROR(VLOOKUP(C32,'Lista desplegable'!B$1:C$436,2,FALSE),"") | E32: =IFERROR(VLOOKUP(D32,'Lista desplegable'!C$1:D$436,2,FALSE),"")
B33: 26 | D33: =IFERROR(VLOOKUP(C33,'Lista desplegable'!B$1:C$436,2,FALSE),"") | E33: =IFERROR(VLOOKUP(D33,'Lista desplegable'!C$1:D$436,2,FALSE),"")
B34: 27 | D34: =IFERROR(VLOOKUP(C34,'Lista desplegable'!B$1:C$436,2,FALSE),"") | E34: =IFERROR(VLOOKUP(D34,'Lista desplegable'!C$1:D$436,2,FALSE),"")
... B37: 30 | D37: =IFERROR(VLOOKUP(C37,'Lista desplegable'!B$1:C$436,2,FALSE),"") | E37: =IFERROR(VLOOKUP(D37,'Lista desplegable'!C$1:D$436,2,FALSE),"")
C40: TURNO NOCHE - (A o B según fuera el caso)
B41: N° | C41: RUT | D41: NOMBRES Y APELLIDOS | E41: CARGO | F41: MAQUINA | G41: DIAMETRO | H41: ESCALA | I41: METROS | J41: ASISTENCIA | K41: WORKERA ENTRADA | L41: WORKERA SALIDA | M41: OBSERVACIONES
B42: 1 | C42: 15613806-1 | D42: =IFERROR(VLOOKUP(C42,'Lista desplegable'!B$1:C$436,2,FALSE),"") -> ARIEL ANDRES SILVA RIQUELME | E42: =IFERROR(VLOOKUP(D42,'Lista desplegable'!C$1:D$436,2,FALSE),"") -> SUPERVISOR DE OPERACIONES | F42: EDM47K-2 | G42: HQ | H42: 1000-1500 | I42: 24 | J42: PRESENTE | K42: SI | L42: SI | M42: Marcó de día.
B43: 2 | C43: 18919440-4 | D43: =IFERROR(VLOOKUP(C43,'Lista desplegable'!B$1:C$436,2,FALSE),"") -> ALISSON AYLEEN VILLAGRA CABALLERO | E43: =IFERROR(VLOOKUP(D43,'Lista desplegable'!C$1:D$436,2,FALSE),"") -> CHOFER | F43: EDM47K-2 | G43: HQ | H43: 1000-1500 | I43: 24 | J43: PRESENTE | K43: SI | L43: SI
B44: 3 | C44: 19804200-5 | D44: =IFERROR(VLOOKUP(C44,'Lista desplegable'!B$1:C$436,2,FALSE),"") -> MANUEL ALEJANDRO TILLERIA SAAVEDRA | E44: =IFERROR(VLOOKUP(D44,'Lista desplegable'!C$1:D$436,2,FALSE),"") -> MECANICO | F44: EDM47K-2 | G44: HQ | H44: 1000-1500 | I44: 24 | J44: PRESENTE | K44: SI | L44: SI
B45: 4 | C45: 28683244-K | D45: =IFERROR(VLOOKUP(C45,'Lista desplegable'!B$1:C$436,2,FALSE),"") -> ARIUNBOLD TSOGKHORKHOI . | E45: =IFERROR(VLOOKUP(D45,'Lista desplegable'!C$1:D$436,2,FALSE),"") -> PERFORISTA | F45: EDM47K-2 | G45: HQ | H45: 1000-1500 | I45: 24 | J45: PRESENTE
B46: 5 | C46: 44601231-2 | D46: =IFERROR(VLOOKUP(C46,'Lista desplegable'!B$1:C$436,2,FALSE),"") -> ULZIIBADRAKH BAYANMUNKH . | E46: =IFERROR(VLOOKUP(D46,'Lista desplegable'!C$1:D$436,2,FALSE),"") -> PERFORISTA | F46: EDM47K-2 | G46: HQ | H46: 1000-1500 | I46: 24 | J46: PRESENTE
B47: 6 | C47: 11934921-4 | D47: =IFERROR(VLOOKUP(C47,'Lista desplegable'!B$1:C$436,2,FALSE),"") -> EDINSON RODRIGO GONZALEZ CORTINEZ | E47: =IFERROR(VLOOKUP(D47,'Lista desplegable'!C$1:D$436,2,FALSE),"") -> AYUDANTE DE PERFORISTA | F47: EDM47K-2 | G47: HQ | H47: 1000-1500 | I47: 24 | J47: PRESENTE | K47: SI | L47: SI | M47: Marcaciones en coipa 2.
...

Sheet 05
G2: DIA
D3: PROYECTO: | E3: LA COIPA | G3: 46270
C6: TURNO DIA - (A o B según fuera el caso)
B7: N° | C7: RUT | D7: NOMBRES Y APELLIDOS | E7: CARGO | F7: MAQUINA | G7: DIAMETRO | H7: ESCALA | I7: METROS | J7: ASISTENCIA | K7: WORKERA ENTRADA | L7: WORKERA SALIDA | M7: OBSERVACIONES
B8: 1 | C8: 14413231-9 | D8: =IFERROR(VLOOKUP(C8,'Lista desplegable'!B$1:C$436,2,FALSE),"") -> JOSE CRISTIAN BASTIAS PEREZ | E8: =IFERROR(VLOOKUP(D8,'Lista desplegable'!C$1:D$436,2,FALSE),"") -> SUPERVISOR DE OPERACIONES | F8: EDM47K-2 | G8: HQ | H8: 1000-1500 | I8: 24 | J8: PRESENTE | K8: SI | L8: SI
B9: 2 | C9: 44623904-K | D9: =IFERROR(VLOOKUP(C9,'Lista desplegable'!B$1:C$436,2,FALSE),"") -> DAYNE JEFFERY PASSMORE . | E9: =IFERROR(VLOOKUP(D9,'Lista desplegable'!C$1:D$436,2,FALSE),"") -> ADMINISTRADOR DE CONTRATO | F9: EDM47K-2 | G9: HQ | H9: 1000-1500 | I9: 24 | J9: PRESENTE
B10: 3 | C10: 18352777-0 | D10: =IFERROR(VLOOKUP(C10,'Lista desplegable'!B$1:C$436,2,FALSE),"") -> NORA ALEXANDRA SALAS ROJAS | E10: =IFERROR(VLOOKUP(D10,'Lista desplegable'!C$1:D$436,2,FALSE),"") -> PREVENCIONISTA DE RIESGOS | F10: EDM47K-2 | G10: HQ | H10: 1000-1500 | I10: 24 | J10: PRESENTE | K10: SI | L10: SI | M10: Trasladada a dos amigos.
B11: 4 | C11: 21516063-7 | D11: =IFERROR(VLOOKUP(C11,'Lista desplegable'!B$1:C$436,2,FALSE),"") -> NATALY ANTONIA SALAS ESCOBAR | E11: =IFERROR(VLOOKUP(D11,'Lista desplegable'!C$1:D$436,2,FALSE),"") -> ADMINISTRATIVO DE FAENA | F11: EDM47K-2 | G11: HQ | H11: 1000-1500 | I11: 24 | J11: PRESENTE | K11: SI | L11: SI
B12: 5 | C12: 13855440-6 | D12: =IFERROR(VLOOKUP(C12,'Lista desplegable'!B$1:C$436,2,FALSE),"") -> PAOLO ALEJANDRO MANRIQUEZ SILVA | E12: =IFERROR(VLOOKUP(D12,'Lista desplegable'!C$1:D$436,2,FALSE),"") -> BODEGUERO | F12: EDM47K-2 | G12: HQ | H12: 1000-1500 | I12: 24 | J12: PRESENTE | K12: SI | L12: SI
B13: 6 | C13: 25832490-0 | D13: =IFERROR(VLOOKUP(C13,'Lista desplegable'!B$1:C$436,2,FALSE),"") -> JOSÉ LEONARDO RODRIGUEZ ROBLES | E13: =IFERROR(VLOOKUP(D13,'Lista desplegable'!C$1:D$436,2,FALSE),"") -> CHOFER | F13: EDM47K-2 | G13: HQ | H13: 1000-1500 | I13: 24 | J13: PRESENTE | K13: SI | L13: SI
B14: 7 | C14: 12152241-1 | D14: =IFERROR(VLOOKUP(C14,'Lista desplegable'!B$1:C$436,2,FALSE),"") -> JORGE ESTEBAN SAAVEDRA MENA | E14: =IFERROR(VLOOKUP(D14,'Lista desplegable'!C$1:D$436,2,FALSE),"") -> CHOFER | F14: EDM47K-2 | G14: HQ | H14: 1000-1500 | I14: 24 | J14: PRESENTE | K14: SI | L14: SI
B15: 8 | C15: 20173381-2 | D15: =IFERROR(VLOOKUP(C15,'Lista desplegable'!B$1:C$436,2,FALSE),"") -> ELIAS NICOLAS CORTEZ CORTEZ | E15: =IFERROR(VLOOKUP(D15,'Lista desplegable'!C$1:D$436,2,FALSE),"") -> CHOFER | F15: EDM47K-2 | G15: HQ | H15: 1000-1500 | I15: 24 | J15: PRESENTE | K15: SI | L15: SI
B16: 9 | C16: 13412582-9 | D16: =IFERROR(VLOOKUP(C16,'Lista desplegable'!B$1:C$436,2,FALSE),"") -> ALEJANDRO ALBERTO CAMPILLAY RUIZ | E16: =IFERROR(VLOOKUP(D16,'Lista desplegable'!C$1:D$436,2,FALSE),"") -> MECANICO | F16: EDM47K-2 | G16: HQ | H16: 1000-1500 | I16: 24 | J16: PRESENTE | K16: SI | L16: SI
B17: 10 | C17: 13744310-4 | D17: =IFERROR(VLOOKUP(C17,'Lista desplegable'!B$1:C$436,2,FALSE),"") -> WALDO RAFAEL CASTRO PASTENE | E17: =IFERROR(VLOOKUP(D17,'Lista desplegable'!C$1:D$436,2,FALSE),"") -> SOLDADOR | F17: EDM47K-2 | G17: HQ | H17: 1000-1500 | I17: 24 | J17: PRESENTE | K17: SI | L17: SI
B18: 11 | C18: 44601238-K | D18: =IFERROR(VLOOKUP(C18,'Lista desplegable'!B$1:C$436,2,FALSE),"") -> ENKHZAYA GANBAATAR . | E18: =IFERROR(VLOOKUP(D18,'Lista desplegable'!C$1:D$436,2,FALSE),"") -> PERFORISTA | F18: EDM47K-2 | G18: HQ | H18: 1000-1500 | I18: 24 | J18: PRESENTE
B19: 12 | C19: 21294612-5 | D19: =IFERROR(VLOOKUP(C19,'Lista desplegable'!B$1:C$436,2,FALSE),"") -> VICENTE ANDRES LOPEZ MARTINEZ | E19: =IFERROR(VLOOKUP(D19,'Lista desplegable'!C$1:D$436,2,FALSE),"") -> AYUDANTE DE PERFORISTA | F19: EDM47K-2 | G19: HQ | H19: 1000-1500 | I19: 24 | J19: PRESENTE | K19: SI | L19: SI
B20: 13 | C20: 17721340-3 | D20: =IFERROR(VLOOKUP(C20,'Lista desplegable'!B$1:C$436,2,FALSE),"") -> CARLOS ALBERTO PIZARRO PIZARRO | E20: =IFERROR(VLOOKUP(D20,'Lista desplegable'!C$1:D$436,2,FALSE),"") -> AYUDANTE DE PERFORISTA | F20: EDM47K-2 | G20: HQ | H20: 1000-1500 | I20: 24 | J20: PRESENTE | K20: SI | L20: SI
B21: 14 | C21: 18450168-6 | D21: =IFERROR(VLOOKUP(C21,'Lista desplegable'!B$1:C$436,2,FALSE),"") -> FELIPE DAVID SAAVEDRA CAMPOS | E21: =IFERROR(VLOOKUP(D21,'Lista desplegable'!C$1:D$436,2,FALSE),"") -> AYUDANTE DE PERFORISTA | F21: EDM47K-2 | G21: HQ | H21: 1000-1500 | I21: 24 | J21: PRESENTE | K21: SI | L21: SI
B22: 15 | D22: =IFERROR(VLOOKUP(C22,'Lista desplegable'!B$1:C$436,2,FALSE),"") | E22: =IFERROR(VLOOKUP(D22,'Lista desplegable'!C$1:D$436,2,FALSE),"")
B23: 16 | D23: =IFERROR(VLOOKUP(C23,'Lista desplegable'!B$1:C$436,2,FALSE),"") | E23: =IFERROR(VLOOKUP(D23,'Lista desplegable'!C$1:D$436,2,FALSE),"")
B24: 17 | D24: =IFERROR(VLOOKUP(C24,'Lista desplegable'!B$1:C$436,2,FALSE),"") | E24: =IFERROR(VLOOKUP(D24,'Lista desplegable'!C$1:D$436,2,FALSE),"")
B25: 18 | D25: =IFERROR(VLOOKUP(C25,'Lista desplegable'!B$1:C$436,2,FALSE),"") | E25: =IFERROR(VLOOKUP(D25,'Lista desplegable'!C$1:D$436,2,FALSE),"")
B26: 19 | D26: =IFERROR(VLOOKUP(C26,'Lista desplegable'!B$1:C$436,2,FALSE),"") | E26: =IFERROR(VLOOKUP(D26,'Lista desplegable'!C$1:D$436,2,FALSE),"")
B27: 20 | D27: =IFERROR(VLOOKUP(C27,'Lista desplegable'!B$1:C$436,2,FALSE),"") | E27: =IFERROR(VLOOKUP(D27,'Lista desplegable'!C$1:D$436,2,FALSE),"")
B28: 21 | D28: =IFERROR(VLOOKUP(C28,'Lista desplegable'!B$1:C$436,2,FALSE),"") | E28: =IFERROR(VLOOKUP(D28,'Lista desplegable'!C$1:D$436,2,FALSE),"")
B29: 22 | D29: =IFERROR(VLOOKUP(C29,'Lista desplegable'!B$1:C$436,2,FALSE),"") | E29: =IFERROR(VLOOKUP(D29,'Lista desplegable'!C$1:D$436,2,FALSE),"")
B30: 23 | D30: =IFERROR(VLOOKUP(C30,'Lista desplegable'!B$1:C$436,2,FALSE),"") | E30: =IFERROR(VLOOKUP(D30,'Lista desplegable'!C$1:D$436,2,FALSE),"")
B31: 24 | D31: =IFERROR(VLOOKUP(C31,'Lista desplegable'!B$1:C$436,2,FALSE),"") | E31: =IFERROR(VLOOKUP(D31,'Lista desplegable'!C$1:D$436,2,FALSE),"")
B32: 25 | D32: =IFERROR(VLOOKUP(C32,'Lista desplegable'!B$1:C$436,2,FALSE),"") | E32: =IFERROR(VLOOKUP(D32,'Lista desplegable'!C$1:D$436,2,FALSE),"")
B33: 26 | D33: =IFERROR(VLOOKUP(C33,'Lista desplegable'!B$1:C$436,2,FALSE),"") | E33: =IFERROR(VLOOKUP(D33,'Lista desplegable'!C$1:D$436,2,FALSE),"")
... B37: 30 | D37: =IFERROR(VLOOKUP(C37,'Lista desplegable'!B$1:C$436,2,FALSE),"") | E37: =IFERROR(VLOOKUP(D37,'Lista desplegable'!C$1:D$436,2,FALSE),"")
C40: TURNO NOCHE - (A o B según fuera el caso)
B41: N° | C41: RUT | D41: NOMBRES Y APELLIDOS | E41: CARGO | F41: MAQUINA | G41: DIAMETRO | H41: ESCALA | I41: METROS | J41: ASISTENCIA | K41: WORKERA ENTRADA | L41: WORKERA SALIDA | M41: OBSERVACIONES
B42: 1 | C42: 15613806-1 | D42: =IFERROR(VLOOKUP(C42,'Lista desplegable'!B$1:C$436,2,FALSE),"") -> ARIEL ANDRES SILVA RIQUELME | E42: =IFERROR(VLOOKUP(D42,'Lista desplegable'!C$1:D$436,2,FALSE),"") -> SUPERVISOR DE OPERACIONES | F42: EDM47K-2 | G42: HQ | H42: 1000-1500 | I42: 24 | J42: PRESENTE | K42: SI | L42: SI | M42: Marca de día
B43: 2 | C43: 18919440-4 | D43: =IFERROR(VLOOKUP(C43,'Lista desplegable'!B$1:C$436,2,FALSE),"") -> ALISSON AYLEEN VILLAGRA CABALLERO | E43: =IFERROR(VLOOKUP(D43,'Lista desplegable'!C$1:D$436,2,FALSE),"") -> CHOFER | F43: EDM47K-2 | G43: HQ | H43: 1000-1500 | I43: 24 | J43: PRESENTE | K43: SI | L43: SI
B44: 3 | C44: 8851229-4 | D44: =IFERROR(VLOOKUP(C44,'Lista desplegable'!B$1:C$436,2,FALSE),"") -> LUIS HUMBERTO PEÑA AHUMADA | E44: =IFERROR(VLOOKUP(D44,'Lista desplegable'!C$1:D$436,2,FALSE),"") -> CHOFER | F44: EDM47K-2 | G44: HQ | H44: 1000-1500 | I44: 24 | J44: PRESENTE | K44: SI | L44: SI | M44: Marca de día
B45: 4 | C45: 19804200-5 | D45: =IFERROR(VLOOKUP(C45,'Lista desplegable'!B$1:C$436,2,FALSE),"") -> MANUEL ALEJANDRO TILLERIA SAAVEDRA | E45: =IFERROR(VLOOKUP(D45,'Lista desplegable'!C$1:D$436,2,FALSE),"") -> MECANICO | F45: EDM47K-2 | G45: HQ | H45: 1000-1500 | I45: 24 | J45: PRESENTE | K45: SI | L45: SI
B46: 5 | C46: 28683244-K | D46: =IFERROR(VLOOKUP(C46,'Lista desplegable'!B$1:C$436,2,FALSE),"") -> ARIUNBOLD TSOGKHORKHOI . | E46: =IFERROR(VLOOKUP(D46,'Lista desplegable'!C$1:D$436,2,FALSE),"") -> PERFORISTA | F46: EDM47K-2 | G46: HQ | H46: 1000-1500 | I46: 24 | J46: PRESENTE
B47: 6 | C47: 44601231-2 | D47: =IFERROR(VLOOKUP(C47,'Lista desplegable'!B$1:C$436,2,FALSE),"") -> ULZIIBADRAKH BAYANMUNKH . | E47: =IFERROR(VLOOKUP(D47,'Lista desplegable'!C$1:D$436,2,FALSE),"") -> PERFORISTA | F47: EDM47K-2 | G47: HQ | H47: 1000-1500 | I47: 24 | J47: PRESENTE
B48: 7 | C48: 11934921-4 | D48: =IFERROR(VLOOKUP(C48,'Lista desplegable'!B$1:C$436,2,FALSE),"") -> EDINSON RODRIGO GONZALEZ CORTINEZ | E48: =IFERROR(VLOOKUP(D48,'Lista desplegable'!C$1:D$436,2,FALSE),"") -> AYUDANTE DE PERFORISTA | F48: EDM47K-2 | G48: HQ | H48: 1000-1500 | I48: 24 | J48: PRESENTE | K48: SI | L48: SI | M48: Marcas en coipa 2.
...

Sheet 06
G2: DIA
D3: PROYECTO: | E3: LA COIPA | G3: 46271
C6: TURNO DIA - (A o B según fuera el caso)
B7: N° | C7: RUT | D7: NOMBRES Y APELLIDOS | E7: CARGO | F7: MAQUINA | G7: DIAMETRO | H7: ESCALA | I7: METROS | J7: ASISTENCIA | K7: WORKERA ENTRADA | L7: WORKERA SALIDA | M7: OBSERVACIONES
B8: 1 | C8: 14413231-9 | D8: =IFERROR(VLOOKUP(C8,'Lista desplegable'!B$1:C$436,2,FALSE),"") -> JOSE CRISTIAN BASTIAS PEREZ | E8: =IFERROR(VLOOKUP(D8,'Lista desplegable'!C$1:D$436,2,FALSE),"") -> SUPERVISOR DE OPERACIONES | F8: EDM47K-2 | G8: HQ | H8: 1000-1500 | I8: 24 | J8: PRESENTE | K8: SI | L8: SI
B9: 2 | C9: 44623904-K | D9: =IFERROR(VLOOKUP(C9,'Lista desplegable'!B$1:C$436,2,FALSE),"") -> DAYNE JEFFERY PASSMORE . | E9: =IFERROR(VLOOKUP(D9,'Lista desplegable'!C$1:D$436,2,FALSE),"") -> ADMINISTRADOR DE CONTRATO | F9: EDM47K-2 | G9: HQ | H9: 1000-1500 | I9: 24 | J9: PRESENTE
B10: 3 | C10: 18352777-0 | D10: =IFERROR(VLOOKUP(C10,'Lista desplegable'!B$1:C$436,2,FALSE),"") -> NORA ALEXANDRA SALAS ROJAS | E10: =IFERROR(VLOOKUP(D10,'Lista desplegable'!C$1:D$436,2,FALSE),"") -> PREVENCIONISTA DE RIESGOS | F10: EDM47K-2 | G10: HQ | H10: 1000-1500 | I10: 24 | J10: PRESENTE | K10: SI | L10: SI | M10: Trasladada a dos amigos.
B11: 4 | C11: 21516063-7 | D11: =IFERROR(VLOOKUP(C11,'Lista desplegable'!B$1:C$436,2,FALSE),"") -> NATALY ANTONIA SALAS ESCOBAR | E11: =IFERROR(VLOOKUP(D11,'Lista desplegable'!C$1:D$436,2,FALSE),"") -> ADMINISTRATIVO DE FAENA | F11: EDM47K-2 | G11: HQ | H11: 1000-1500 | I11: 24 | J11: PRESENTE | K11: SI | L11: SI
B12: 5 | C12: 13855440-6 | D12: =IFERROR(VLOOKUP(C12,'Lista desplegable'!B$1:C$436,2,FALSE),"") -> PAOLO ALEJANDRO MANRIQUEZ SILVA | E12: =IFERROR(VLOOKUP(D12,'Lista desplegable'!C$1:D$436,2,FALSE),"") -> BODEGUERO | F12: EDM47K-2 | G12: HQ | H12: 1000-1500 | I12: 24 | J12: PRESENTE | K12: SI | L12: SI
B13: 6 | C13: 25832490-0 | D13: =IFERROR(VLOOKUP(C13,'Lista desplegable'!B$1:C$436,2,FALSE),"") -> JOSÉ LEONARDO RODRIGUEZ ROBLES | E13: =IFERROR(VLOOKUP(D13,'Lista desplegable'!C$1:D$436,2,FALSE),"") -> CHOFER | F13: EDM47K-2 | G13: HQ | H13: 1000-1500 | I13: 24 | J13: PRESENTE | K13: SI | L13: SI
B14: 7 | C14: 12152241-1 | D14: =IFERROR(VLOOKUP(C14,'Lista desplegable'!B$1:C$436,2,FALSE),"") -> JORGE ESTEBAN SAAVEDRA MENA | E14: =IFERROR(VLOOKUP(D14,'Lista desplegable'!C$1:D$436,2,FALSE),"") -> CHOFER | F14: EDM47K-2 | G14: HQ | H14: 1000-1500 | I14: 24 | J14: PRESENTE | K14: SI | L14: SI
B15: 8 | C15: 20173381-2 | D15: =IFERROR(VLOOKUP(C15,'Lista desplegable'!B$1:C$436,2,FALSE),"") -> ELIAS NICOLAS CORTEZ CORTEZ | E15: =IFERROR(VLOOKUP(D15,'Lista desplegable'!C$1:D$436,2,FALSE),"") -> CHOFER | F15: EDM47K-2 | G15: HQ | H15: 1000-1500 | I15: 24 | J15: PRESENTE | K15: SI | L15: SI
B16: 9 | C16: 13412582-9 | D16: =IFERROR(VLOOKUP(C16,'Lista desplegable'!B$1:C$436,2,FALSE),"") -> ALEJANDRO ALBERTO CAMPILLAY RUIZ | E16: =IFERROR(VLOOKUP(D16,'Lista desplegable'!C$1:D$436,2,FALSE),"") -> MECANICO | F16: EDM47K-2 | G16: HQ | H16: 1000-1500 | I16: 24 | J16: PRESENTE | K16: SI | L16: SI
B17: 10 | C17: 13744310-4 | D17: =IFERROR(VLOOKUP(C17,'Lista desplegable'!B$1:C$436,2,FALSE),"") -> WALDO RAFAEL CASTRO PASTENE | E17: =IFERROR(VLOOKUP(D17,'Lista desplegable'!C$1:D$436,2,FALSE),"") -> SOLDADOR | F17: EDM47K-2 | G17: HQ | H17: 1000-1500 | I17: 24 | J17: PRESENTE | K17: SI | L17: SI
B18: 11 | C18: 44601238-K | D18: =IFERROR(VLOOKUP(C18,'Lista desplegable'!B$1:C$436,2,FALSE),"") -> ENKHZAYA GANBAATAR . | E18: =IFERROR(VLOOKUP(D18,'Lista desplegable'!C$1:D$436,2,FALSE),"") -> PERFORISTA | F18: EDM47K-2 | G18: HQ | H18: 1000-1500 | I18: 24 | J18: PRESENTE
B19: 12 | C19: 21294612-5 | D19: =IFERROR(VLOOKUP(C19,'Lista desplegable'!B$1:C$436,2,FALSE),"") -> VICENTE ANDRES LOPEZ MARTINEZ | E19: =IFERROR(VLOOKUP(D19,'Lista desplegable'!C$1:D$436,2,FALSE),"") -> AYUDANTE DE PERFORISTA | F19: EDM47K-2 | G19: HQ | H19: 1000-1500 | I19: 24 | J19: PRESENTE | K19: SI | L19: SI
B20: 13 | C20: 17721340-3 | D20: =IFERROR(VLOOKUP(C20,'Lista desplegable'!B$1:C$436,2,FALSE),"") -> CARLOS ALBERTO PIZARRO PIZARRO | E20: =IFERROR(VLOOKUP(D20,'Lista desplegable'!C$1:D$436,2,FALSE),"") -> AYUDANTE DE PERFORISTA | F20: EDM47K-2 | G20: HQ | H20: 1000-1500 | I20: 24 | J20: PRESENTE | K20: SI | L20: SI
B21: 14 | C21: 18450168-6 | D21: =IFERROR(VLOOKUP(C21,'Lista desplegable'!B$1:C$436,2,FALSE),"") -> FELIPE DAVID SAAVEDRA CAMPOS | E21: =IFERROR(VLOOKUP(D21,'Lista desplegable'!C$1:D$436,2,FALSE),"") -> AYUDANTE DE PERFORISTA | F21: EDM47K-2 | G21: HQ | H21: 1000-1500 | I21: 24 | J21: PRESENTE | K21: SI | L21: SI
B22: 15 | D22: =IFERROR(VLOOKUP(C22,'Lista desplegable'!B$1:C$436,2,FALSE),"") | E22: =IFERROR(VLOOKUP(D22,'Lista desplegable'!C$1:D$436,2,FALSE),"")
B23: 16 | D23: =IFERROR(VLOOKUP(C23,'Lista desplegable'!B$1:C$436,2,FALSE),"") | E23: =IFERROR(VLOOKUP(D23,'Lista desplegable'!C$1:D$436,2,FALSE),"")
B24: 17 | D24: =IFERROR(VLOOKUP(C24,'Lista desplegable'!B$1:C$436,2,FALSE),"") | E24: =IFERROR(VLOOKUP(D24,'Lista desplegable'!C$1:D$436,2,FALSE),"")
B25: 18 | D25: =IFERROR(VLOOKUP(C25,'Lista desplegable'!B$1:C$436,2,FALSE),"") | E25: =IFERROR(VLOOKUP(D25,'Lista desplegable'!C$1:D$436,2,FALSE),"")
B26: 19 | D26: =IFERROR(VLOOKUP(C26,'Lista desplegable'!B$1:C$436,2,FALSE),"") | E26: =IFERROR(VLOOKUP(D26,'Lista desplegable'!C$1:D$436,2,FALSE),"")
B27: 20 | D27: =IFERROR(VLOOKUP(C27,'Lista desplegable'!B$1:C$436,2,FALSE),"") | E27: =IFERROR(VLOOKUP(D27,'Lista desplegable'!C$1:D$436,2,FALSE),"")
B28: 21 | D28: =IFERROR(VLOOKUP(C28,'Lista desplegable'!B$1:C$436,2,FALSE),"") | E28: =IFERROR(VLOOKUP(D28,'Lista desplegable'!C$1:D$436,2,FALSE),"")
B29: 22 | D29: =IFERROR(VLOOKUP(C29,'Lista desplegable'!B$1:C$436,2,FALSE),"") | E29: =IFERROR(VLOOKUP(D29,'Lista desplegable'!C$1:D$436,2,FALSE),"")
B30: 23 | D30: =IFERROR(VLOOKUP(C30,'Lista desplegable'!B$1:C$436,2,FALSE),"") | E30: =IFERROR(VLOOKUP(D30,'Lista desplegable'!C$1:D$436,2,FALSE),"")
B31: 24 | D31: =IFERROR(VLOOKUP(C31,'Lista desplegable'!B$1:C$436,2,FALSE),"") | E31: =IFERROR(VLOOKUP(D31,'Lista desplegable'!C$1:D$436,2,FALSE),"")
B32: 25 | D32: =IFERROR(VLOOKUP(C32,'Lista desplegable'!B$1:C$436,2,FALSE),"") | E32: =IFERROR(VLOOKUP(D32,'Lista desplegable'!C$1:D$436,2,FALSE),"")
B33: 26 | D33: =IFERROR(VLOOKUP(C33,'Lista desplegable'!B$1:C$436,2,FALSE),"") | E33: =IFERROR(VLOOKUP(D33,'Lista desplegable'!C$1:D$436,2,FALSE),"")
... B37: 30 | D37: =IFERROR(VLOOKUP(C37,'Lista desplegable'!B$1:C$436,2,FALSE),"") | E37: =IFERROR(VLOOKUP(D37,'Lista desplegable'!C$1:D$436,2,FALSE),"")
C40: TURNO NOCHE - (A o B según fuera el caso)
B41: N° | C41: RUT | D41: NOMBRES Y APELLIDOS | E41: CARGO | F41: MAQUINA | G41: DIAMETRO | H41: ESCALA | I41: METROS | J41: ASISTENCIA | K41: WORKERA ENTRADA | L41: WORKERA SALIDA | M41: OBSERVACIONES
B42: 1 | C42: 15613806-1 | D42: =IFERROR(VLOOKUP(C42,'Lista desplegable'!B$1:C$436,2,FALSE),"") -> ARIEL ANDRES SILVA RIQUELME | E42: =IFERROR(VLOOKUP(D42,'Lista desplegable'!C$1:D$436,2,FALSE),"") -> SUPERVISOR DE OPERACIONES | F42: EDM47K-2 | G42: HQ | H42: 1000-1500 | I42: 24 | J42: PRESENTE | K42: SI | L42: SI | M42: Marca de día.
B43: 2 | C43: 18919440-4 | D43: =IFERROR(VLOOKUP(C43,'Lista desplegable'!B$1:C$436,2,FALSE),"") -> ALISSON AYLEEN VILLAGRA CABALLERO | E43: =IFERROR(VLOOKUP(D43,'Lista desplegable'!C$1:D$436,2,FALSE),"") -> CHOFER | F43: EDM47K-2 | G43: HQ | H43: 1000-1500 | I43: 24 | J43: PRESENTE | K43: SI | L43: SI
B44: 3 | C44: 8851229-4 | D44: =IFERROR(VLOOKUP(C44,'Lista desplegable'!B$1:C$436,2,FALSE),"") -> LUIS HUMBERTO PEÑA AHUMADA | E44: =IFERROR(VLOOKUP(D44,'Lista desplegable'!C$1:D$436,2,FALSE),"") -> CHOFER | F44: EDM47K-2 | G44: HQ | H44: 1000-1500 | I44: 24 | J44: PRESENTE | K44: SI | L44: SI | M44: Marca de día.
B45: 4 | C45: 19804200-5 | D45: =IFERROR(VLOOKUP(C45,'Lista desplegable'!B$1:C$436,2,FALSE),"") -> MANUEL ALEJANDRO TILLERIA SAAVEDRA | E45: =IFERROR(VLOOKUP(D45,'Lista desplegable'!C$1:D$436,2,FALSE),"") -> MECANICO | F45: EDM47K-2 | G45: HQ | H45: 1000-1500 | I45: 24 | J45: PRESENTE | K45: SI | L45: SI
B46: 5 | C46: 28683244-K | D46: =IFERROR(VLOOKUP(C46,'Lista desplegable'!B$1:C$436,2,FALSE),"") -> ARIUNBOLD TSOGKHORKHOI . | E46: =IFERROR(VLOOKUP(D46,'Lista desplegable'!C$1:D$436,2,FALSE),"") -> PERFORISTA | F46: EDM47K-2 | G46: HQ | H46: 1000-1500 | I46: 24 | J46: PRESENTE
B47: 6 | C47: 44601231-2 | D47: =IFERROR(VLOOKUP(C47,'Lista desplegable'!B$1:C$436,2,FALSE),"") -> ULZIIBADRAKH BAYANMUNKH . | E47: =IFERROR(VLOOKUP(D47,'Lista desplegable'!C$1:D$436,2,FALSE),"") -> PERFORISTA | F47: EDM47K-2 | G47: HQ | H47: 1000-1500 | I47: 24 | J47: PRESENTE
B48: 7 | C48: 11934921-4 | D48: =IFERROR(VLOOKUP(C48,'Lista desplegable'!B$1:C$436,2,FALSE),"") -> EDINSON RODRIGO GONZALEZ CORTINEZ | E48: =IFERROR(VLOOKUP(D48,'Lista desplegable'!C$1:D$436,2,FALSE),"") -> AYUDANTE DE PERFORISTA | F48: EDM47K-2 | G48: HQ | H48: 1000-1500 | I48: 24 | J48: PRESENTE | K48: SI | L48: SI | M48: Marcas en coipa 2.
...

Sheet 07
G2: DIA
D3: PROYECTO: | E3: LA COIPA | G3: 46272
C6: TURNO DIA - (A o B según fuera el caso)
B7: N° | C7: RUT | D7: NOMBRES Y APELLIDOS | E7: CARGO | F7: MAQUINA | G7: DIAMETRO | H7: ESCALA | I7: METROS | J7: ASISTENCIA | K7: WORKERA ENTRADA | L7: WORKERA SALIDA | M7: OBSERVACIONES
B8: 1 | C8: 14413231-9 | D8: =IFERROR(VLOOKUP(C8,'Lista desplegable'!B$1:C$436,2,FALSE),"") -> JOSE CRISTIAN BASTIAS PEREZ | E8: =IFERROR(VLOOKUP(D8,'Lista desplegable'!C$1:D$436,2,FALSE),"") -> SUPERVISOR DE OPERACIONES | F8: EDM47K-2 | G8: HQ | H8: 1000-1500 | I8: 18 | J8: PRESENTE | K8: SI | L8: SI
B9: 2 | C9: 44623904-K | D9: =IFERROR(VLOOKUP(C9,'Lista desplegable'!B$1:C$436,2,FALSE),"") -> DAYNE JEFFERY PASSMORE . | E9: =IFERROR(VLOOKUP(D9,'Lista desplegable'!C$1:D$436,2,FALSE),"") -> ADMINISTRADOR DE CONTRATO | F9: EDM47K-2 | G9: HQ | H9: 1000-1500 | I9: 18 | J9: PRESENTE
B10: 3 | C10: 18352777-0 | D10: =IFERROR(VLOOKUP(C10,'Lista desplegable'!B$1:C$436,2,FALSE),"") -> NORA ALEXANDRA SALAS ROJAS | E10: =IFERROR(VLOOKUP(D10,'Lista desplegable'!C$1:D$436,2,FALSE),"") -> PREVENCIONISTA DE RIESGOS | F10: EDM47K-2 | G10: HQ | H10: 1000-1500 | I10: 18 | J10: PRESENTE | K10: SI | L10: SI | M10: Trasladada a dos amigos.
B11: 4 | C11: 21516063-7 | D11: =IFERROR(VLOOKUP(C11,'Lista desplegable'!B$1:C$436,2,FALSE),"") -> NATALY ANTONIA SALAS ESCOBAR | E11: =IFERROR(VLOOKUP(D11,'Lista desplegable'!C$1:D$436,2,FALSE),"") -> ADMINISTRATIVO DE FAENA | F11: EDM47K-2 | G11: HQ | H11: 1000-1500 | I11: 18 | J11: PRESENTE | K11: SI | L11: SI
B12: 5 | C12: 13855440-6 | D12: =IFERROR(VLOOKUP(C12,'Lista desplegable'!B$1:C$436,2,FALSE),"") -> PAOLO ALEJANDRO MANRIQUEZ SILVA | E12: =IFERROR(VLOOKUP(D12,'Lista desplegable'!C$1:D$436,2,FALSE),"") -> BODEGUERO | F12: EDM47K-2 | G12: HQ | H12: 1000-1500 | I12: 18 | J12: PRESENTE | K12: SI | L12: SI
B13: 6 | C13: 15593625-8 | D13: =IFERROR(VLOOKUP(C13,'Lista desplegable'!B$1:C$436,2,FALSE),"") -> CARLOS EDUARDO RODRIGUEZ HERNANDEZ | E13: =IFERROR(VLOOKUP(D13,'Lista desplegable'!C$1:D$436,2,FALSE),"") -> ADMINISTRADOR DE CONTRATO | F13: EDM47K-2 | G13: HQ | H13: 1000-1500 | I13: 18 | J13: PRESENTE | K13: SI | L13: SI
B14: 7 | C14: 25832490-0 | D14: =IFERROR(VLOOKUP(C14,'Lista desplegable'!B$1:C$436,2,FALSE),"") -> JOSÉ LEONARDO RODRIGUEZ ROBLES | E14: =IFERROR(VLOOKUP(D14,'Lista desplegable'!C$1:D$436,2,FALSE),"") -> CHOFER | F14: EDM47K-2 | G14: HQ | H14: 1000-1500 | I14: 18 | J14: PRESENTE | K14: SI | L14: SI
B15: 8 | C15: 12152241-1 | D15: =IFERROR(VLOOKUP(C15,'Lista desplegable'!B$1:C$436,2,FALSE),"") -> JORGE ESTEBAN SAAVEDRA MENA | E15: =IFERROR(VLOOKUP(D15,'Lista desplegable'!C$1:D$436,2,FALSE),"") -> CHOFER | F15: EDM47K-2 | G15: HQ | H15: 1000-1500 | I15: 18 | J15: PRESENTE | K15: SI | L15: SI
B16: 9 | C16: 20173381-2 | D16: =IFERROR(VLOOKUP(C16,'Lista desplegable'!B$1:C$436,2,FALSE),"") -> ELIAS NICOLAS CORTEZ CORTEZ | E16: =IFERROR(VLOOKUP(D16,'Lista desplegable'!C$1:D$436,2,FALSE),"") -> CHOFER | F16: EDM47K-2 | G16: HQ | H16: 1000-1500 | I16: 18 | J16: PRESENTE | K16: SI | L16: SI
B17: 10 | C17: 13412582-9 | D17: =IFERROR(VLOOKUP(C17,'Lista desplegable'!B$1:C$436,2,FALSE),"") -> ALEJANDRO ALBERTO CAMPILLAY RUIZ | E17: =IFERROR(VLOOKUP(D17,'Lista desplegable'!C$1:D$436,2,FALSE),"") -> MECANICO | F17: EDM47K-2 | G17: HQ | H17: 1000-1500 | I17: 18 | J17: PRESENTE | K17: SI | L17: SI
B18: 11 | C18: 13744310-4 | D18: =IFERROR(VLOOKUP(C18,'Lista desplegable'!B$1:C$436,2,FALSE),"") -> WALDO RAFAEL CASTRO PASTENE | E18: =IFERROR(VLOOKUP(D18,'Lista desplegable'!C$1:D$436,2,FALSE),"") -> SOLDADOR | F18: EDM47K-2 | G18: HQ | H18: 1000-1500 | I18: 18 | J18: PRESENTE | K18: SI | L18: SI
B19: 12 | C19: 44601238-K | D19: =IFERROR(VLOOKUP(C19,'Lista desplegable'!B$1:C$436,2,FALSE),"") -> ENKHZAYA GANBAATAR . | E19: =IFERROR(VLOOKUP(D19,'Lista desplegable'!C$1:D$436,2,FALSE),"") -> PERFORISTA | F19: EDM47K-2 | G19: HQ | H19: 1000-1500 | I19: 18 | J19: PRESENTE
B20: 13 | C20: 21294612-5 | D20: =IFERROR(VLOOKUP(C20,'Lista desplegable'!B$1:C$436,2,FALSE),"") -> VICENTE ANDRES LOPEZ MARTINEZ | E20: =IFERROR(VLOOKUP(D20,'Lista desplegable'!C$1:D$436,2,FALSE),"") -> AYUDANTE DE PERFORISTA | F20: EDM47K-2 | G20: HQ | H20: 1000-1500 | I20: 18 | J20: PRESENTE | K20: SI | L20: SI
B21: 14 | C21: 17721340-3 | D21: =IFERROR(VLOOKUP(C21,'Lista desplegable'!B$1:C$436,2,FALSE),"") -> CARLOS ALBERTO PIZARRO PIZARRO | E21: =IFERROR(VLOOKUP(D21,'Lista desplegable'!C$1:D$436,2,FALSE),"") -> AYUDANTE DE PERFORISTA | F21: EDM47K-2 | G21: HQ | H21: 1000-1500 | I21: 18 | J21: PRESENTE | K21: SI | L21: SI
B22: 15 | C22: 18450168-6 | D22: =IFERROR(VLOOKUP(C22,'Lista desplegable'!B$1:C$436,2,FALSE),"") -> FELIPE DAVID SAAVEDRA CAMPOS | E22: =IFERROR(VLOOKUP(D22,'Lista desplegable'!C$1:D$436,2,FALSE),"") -> AYUDANTE DE PERFORISTA | F22: EDM47K-2 | G22: HQ | H22: 1000-1500 | I22: 18 | J22: PRESENTE | K22: SI | L22: SI
B23: 16 | D23: =IFERROR(VLOOKUP(C23,'Lista desplegable'!B$1:C$436,2,FALSE),"") | E23: =IFERROR(VLOOKUP(D23,'Lista desplegable'!C$1:D$436,2,FALSE),"")
B24: 17 | D24: =IFERROR(VLOOKUP(C24,'Lista desplegable'!B$1:C$436,2,FALSE),"") | E24: =IFERROR(VLOOKUP(D24,'Lista desplegable'!C$1:D$436,2,FALSE),"")
B25: 18 | D25: =IFERROR(VLOOKUP(C25,'Lista desplegable'!B$1:C$436,2,FALSE),"") | E25: =IFERROR(VLOOKUP(D25,'Lista desplegable'!C$1:D$436,2,FALSE),"")
B26: 19 | D26: =IFERROR(VLOOKUP(C26,'Lista desplegable'!B$1:C$436,2,FALSE),"") | E26: =IFERROR(VLOOKUP(D26,'Lista desplegable'!C$1:D$436,2,FALSE),"")
B27: 20 | D27: =IFERROR(VLOOKUP(C27,'Lista desplegable'!B$1:C$436,2,FALSE),"") | E27: =IFERROR(VLOOKUP(D27,'Lista desplegable'!C$1:D$436,2,FALSE),"")
B28: 21 | D28: =IFERROR(VLOOKUP(C28,'Lista desplegable'!B$1:C$436,2,FALSE),"") | E28: =IFERROR(VLOOKUP(D28,'Lista desplegable'!C$1:D$436,2,FALSE),"")
B29: 22 | D29: =IFERROR(VLOOKUP(C29,'Lista desplegable'!B$1:C$436,2,FALSE),"") | E29: =IFERROR(VLOOKUP(D29,'Lista desplegable'!C$1:D$436,2,FALSE),"")
B30: 23 | D30: =IFERROR(VLOOKUP(C30,'Lista desplegable'!B$1:C$436,2,FALSE),"") | E30: =IFERROR(VLOOKUP(D30,'Lista desplegable'!C$1:D$436,2,FALSE),"")
